<mujoco model="planar walker">
  <include file="./common/visual.xml" />
  <include file="./common/skybox.xml" />
  <include file="./common/materials.xml" />

  <option timestep="0.0025" />

  <statistic center="0 0 1" extent="2" />

  <default>
    <joint armature="0.01" damping=".1" limited="true" solimplimit="0 .99 .01" />
    <geom conaffinity="0" contype="1" friction=".7 .1 .1" />
    <motor ctrllimited="true" ctrlrange="-1 1" />
    <site size="0.01" />
    <default class="walker">
      <geom material="self" type="capsule" />
      <joint axis="0 -1 0" />
    </default>
  </default>

  <worldbody>
    <geom conaffinity="1" material="grid" name="floor" pos="248 0 0" size="250 .8 .2" type="plane" zaxis="-0.13525263401298893 0.0 0.9908111449678735" />
    <body childclass="walker" name="torso" pos="2.251785521164777 0.0 -32.244491006227676">
      <light mode="trackcom" name="light" pos="0 0 2" />
      <camera euler="60 0 0" mode="trackcom" name="side" pos="0 -2 .7" />
      <camera mode="trackcom" name="back" pos="-2 0 .5" xyaxes="0 -1 0 1 0 3" />
      <joint armature="0" axis="0 0 1" damping="0.1575462280036249" limited="false" name="rootz" type="slide" />
      <joint armature="0" axis="1 0 0" damping="0.061219091011039" limited="false" name="rootx" type="slide" />
      <joint armature="0" axis="0 1 0" damping="0.08313134070571351" limited="false" name="rooty" type="hinge" />
      <geom density="679.7015086375151" friction="0.8158278565863523 0.20231974027947597 0.164894792056382" name="torso" size="0.07 0.3" />
      <body name="right_thigh" pos="0 -.05 -0.3">
        <joint damping="0.21669176704936455" name="right_hip" range="-20 100" />
        <geom density="2137.4018678070784" friction="1.306755518966464 0.18783999038535237 0.09216101553596619" name="right_thigh" pos="0 0 -0.225" size="0.05 0.225" />
        <body name="right_leg" pos="0 0 -0.7">
          <joint damping="0.2014894439325929" name="right_knee" pos="0 0 0.25" range="-150 0" />
          <geom density="485.5192571583077" friction="0.40782788119113134 0.1315542426009892 0.07146468874698268" name="right_leg" size="0.04 0.25" />
          <body name="right_foot" pos="0.06 0 -0.25">
            <joint damping="0.13757672471503193" name="right_ankle" pos="-0.06 0 0" range="-45 45" />
            <geom density="1471.273504727157" friction="0.8289032622122504 0.17166174763115075 0.10168391151884165" name="right_foot" size="0.05 0.19338385964597588" zaxis="1 0 0" />
          </body>
        </body>
      </body>
      <body name="left_thigh" pos="0 .05 -0.3">
        <joint damping="0.18501150273884362" name="left_hip" range="-20 100" />
        <geom density="1823.9530289477837" friction="0.6170821126636632 0.07755171922717924 0.16247860712506115" name="left_thigh" pos="0 0 -0.225" size="0.05 0.225" />
        <body name="left_leg" pos="0 0 -0.7">
          <joint damping="0.13132857797818215" name="left_knee" pos="0 0 0.25" range="-150 0" />
          <geom density="1042.3373363576807" friction="0.891432434963774 0.09650962787836122 0.0697297026974575" name="left_leg" size="0.04 0.25" />
          <body name="left_foot" pos="0.06 0 -0.25">
            <joint damping="0.09112422344462144" name="left_ankle" pos="-0.06 0 0" range="-45 45" />
            <geom density="669.9994207052486" friction="1.3351968867766566 0.07280722791323205 0.060319414894031476" name="left_foot" size="0.05 0.06117756095236515" zaxis="1 0 0" />
          </body>
        </body>
      </body>
    </body>
  </worldbody>

  <sensor>
    <subtreelinvel body="torso" name="torso_subtreelinvel" />
  </sensor>

  <actuator>
    <motor gear="100" joint="right_hip" name="right_hip" />
    <motor gear="50" joint="right_knee" name="right_knee" />
    <motor gear="20" joint="right_ankle" name="right_ankle" />
    <motor gear="100" joint="left_hip" name="left_hip" />
    <motor gear="50" joint="left_knee" name="left_knee" />
    <motor gear="20" joint="left_ankle" name="left_ankle" />
  </actuator>
</mujoco>