<mujoco model="planar walker">
  <include file="./common/visual.xml" />
  <include file="./common/skybox.xml" />
  <include file="./common/materials.xml" />

  <option timestep="0.0025" />

  <statistic center="0 0 1" extent="2" />

  <default>
    <joint armature="0.01" damping=".1" limited="true" solimplimit="0 .99 .01" />
    <geom conaffinity="0" contype="1" friction=".7 .1 .1" />
    <motor ctrllimited="true" ctrlrange="-1 1" />
    <site size="0.01" />
    <default class="walker">
      <geom material="self" type="capsule" />
      <joint axis="0 -1 0" />
    </default>
  </default>

  <worldbody>
    <geom conaffinity="1" material="grid" name="floor" pos="248 0 0" size="250 .8 .2" type="plane" zaxis="0.13518556551648417 0.0 0.9908202979733451" />
    <body childclass="walker" name="torso" pos="2.303603215713707 0.0 34.82418430768274">
      <light mode="trackcom" name="light" pos="0 0 2" />
      <camera euler="60 0 0" mode="trackcom" name="side" pos="0 -2 .7" />
      <camera mode="trackcom" name="back" pos="-2 0 .5" xyaxes="0 -1 0 1 0 3" />
      <joint armature="0" axis="0 0 1" damping="0.10414758077596818" limited="false" name="rootz" type="slide" />
      <joint armature="0" axis="1 0 0" damping="0.19670426908976002" limited="false" name="rootx" type="slide" />
      <joint armature="0" axis="0 1 0" damping="0.18518006947648463" limited="false" name="rooty" type="hinge" />
      <geom density="871.7274152397322" friction="0.8666773323306796 0.0722146685510121 0.04669463748818594" name="torso" size="0.07 0.3" />
      <body name="right_thigh" pos="0 -.05 -0.3">
        <joint damping="0.08193895612572327" name="right_hip" range="-20 100" />
        <geom density="837.3477107242672" friction="0.39988453388509737 0.12854891527767134 0.1557999032613239" name="right_thigh" pos="0 0 -0.225" size="0.05 0.225" />
        <body name="right_leg" pos="0 0 -0.7">
          <joint damping="0.10230451298843744" name="right_knee" pos="0 0 0.25" range="-150 0" />
          <geom density="483.9186753416215" friction="0.4682446893028686 0.1019264864950693 0.15612851111863946" name="right_leg" size="0.04 0.25" />
          <body name="right_foot" pos="0.06 0 -0.25">
            <joint damping="0.08696624224027096" name="right_ankle" pos="-0.06 0 0" range="-45 45" />
            <geom density="1334.1005509420131" friction="0.6118447405238557 0.05504507222121843 0.13120920818050338" name="right_foot" size="0.05 0.09853718716205682" zaxis="1 0 0" />
          </body>
        </body>
      </body>
      <body name="left_thigh" pos="0 .05 -0.3">
        <joint damping="0.17167732902648203" name="left_hip" range="-20 100" />
        <geom density="560.7979360114246" friction="0.37166109448535084 0.1978474703855299 0.11545881126760654" name="left_thigh" pos="0 0 -0.225" size="0.05 0.225" />
        <body name="left_leg" pos="0 0 -0.7">
          <joint damping="0.09461187821620909" name="left_knee" pos="0 0 0.25" range="-150 0" />
          <geom density="789.643157176938" friction="0.4578183388506647 0.14025574585529565 0.09673373597979533" name="left_leg" size="0.04 0.25" />
          <body name="left_foot" pos="0.06 0 -0.25">
            <joint damping="0.05009314936911287" name="left_ankle" pos="-0.06 0 0" range="-45 45" />
            <geom density="744.9668609173137" friction="0.7368172063186101 0.05399844838458188 0.1672708805977441" name="left_foot" size="0.05 0.06551553562427002" zaxis="1 0 0" />
          </body>
        </body>
      </body>
    </body>
  </worldbody>

  <sensor>
    <subtreelinvel body="torso" name="torso_subtreelinvel" />
  </sensor>

  <actuator>
    <motor gear="100" joint="right_hip" name="right_hip" />
    <motor gear="50" joint="right_knee" name="right_knee" />
    <motor gear="20" joint="right_ankle" name="right_ankle" />
    <motor gear="100" joint="left_hip" name="left_hip" />
    <motor gear="50" joint="left_knee" name="left_knee" />
    <motor gear="20" joint="left_ankle" name="left_ankle" />
  </actuator>
</mujoco>