<mujoco model="planar walker">
  <include file="./common/visual.xml" />
  <include file="./common/skybox.xml" />
  <include file="./common/materials.xml" />

  <option timestep="0.0025" />

  <statistic center="0 0 1" extent="2" />

  <default>
    <joint armature="0.01" damping=".1" limited="true" solimplimit="0 .99 .01" />
    <geom conaffinity="0" contype="1" friction=".7 .1 .1" />
    <motor ctrllimited="true" ctrlrange="-1 1" />
    <site size="0.01" />
    <default class="walker">
      <geom material="self" type="capsule" />
      <joint axis="0 -1 0" />
    </default>
  </default>

  <worldbody>
    <geom conaffinity="1" material="grid" name="floor" pos="248 0 0" size="250 .8 .2" type="plane" zaxis="-0.14988631652851792 0.0 0.9887032376388342" />
    <body childclass="walker" name="torso" pos="2.771619802263416 0.0 -35.87406585154468">
      <light mode="trackcom" name="light" pos="0 0 2" />
      <camera euler="60 0 0" mode="trackcom" name="side" pos="0 -2 .7" />
      <camera mode="trackcom" name="back" pos="-2 0 .5" xyaxes="0 -1 0 1 0 3" />
      <joint armature="0" axis="0 0 1" damping="0.09148424754321788" limited="false" name="rootz" type="slide" />
      <joint armature="0" axis="1 0 0" damping="0.04576778454661691" limited="false" name="rootx" type="slide" />
      <joint armature="0" axis="0 1 0" damping="0.14879820700399732" limited="false" name="rooty" type="hinge" />
      <geom density="1361.6061396458108" friction="0.40893779212526765 0.11517522932012236 0.08427736043027395" name="torso" size="0.07 0.3" />
      <body name="right_thigh" pos="0 -.05 -0.3">
        <joint damping="0.16860052142155035" name="right_hip" range="-20 100" />
        <geom density="1107.6776589371877" friction="0.8888359290942834 0.06992512643934697 0.21528754938185837" name="right_thigh" pos="0 0 -0.225" size="0.05 0.225" />
        <body name="right_leg" pos="0 0 -0.7">
          <joint damping="0.04789689703820281" name="right_knee" pos="0 0 0.25" range="-150 0" />
          <geom density="1044.7650259459285" friction="0.45905799015535 0.19507061389352545 0.15988414480120572" name="right_leg" size="0.04 0.25" />
          <body name="right_foot" pos="0.06 0 -0.25">
            <joint damping="0.05713022986546419" name="right_ankle" pos="-0.06 0 0" range="-45 45" />
            <geom density="749.6980925036816" friction="1.4173673650886682 0.1084298752624552 0.04826657279070674" name="right_foot" size="0.05 0.08108559141547708" zaxis="1 0 0" />
          </body>
        </body>
      </body>
      <body name="left_thigh" pos="0 .05 -0.3">
        <joint damping="0.06792828124798243" name="left_hip" range="-20 100" />
        <geom density="558.0065867404728" friction="1.5024069463591603 0.09254970014001879 0.15081641977079596" name="left_thigh" pos="0 0 -0.225" size="0.05 0.225" />
        <body name="left_leg" pos="0 0 -0.7">
          <joint damping="0.13850599743135478" name="left_knee" pos="0 0 0.25" range="-150 0" />
          <geom density="1149.918496224983" friction="0.8581631175946004 0.19935772318492825 0.04858499248084111" name="left_leg" size="0.04 0.25" />
          <body name="left_foot" pos="0.06 0 -0.25">
            <joint damping="0.1942007612061074" name="left_ankle" pos="-0.06 0 0" range="-45 45" />
            <geom density="712.5756431896858" friction="0.7957710506087085 0.13778812897672618 0.16403702283264485" name="left_foot" size="0.05 0.07816160927197349" zaxis="1 0 0" />
          </body>
        </body>
      </body>
    </body>
  </worldbody>

  <sensor>
    <subtreelinvel body="torso" name="torso_subtreelinvel" />
  </sensor>

  <actuator>
    <motor gear="100" joint="right_hip" name="right_hip" />
    <motor gear="50" joint="right_knee" name="right_knee" />
    <motor gear="20" joint="right_ankle" name="right_ankle" />
    <motor gear="100" joint="left_hip" name="left_hip" />
    <motor gear="50" joint="left_knee" name="left_knee" />
    <motor gear="20" joint="left_ankle" name="left_ankle" />
  </actuator>
</mujoco>