<mujoco model="planar walker">
  <include file="./common/visual.xml" />
  <include file="./common/skybox.xml" />
  <include file="./common/materials.xml" />

  <option timestep="0.0025" />

  <statistic center="0 0 1" extent="2" />

  <default>
    <joint armature="0.01" damping=".1" limited="true" solimplimit="0 .99 .01" />
    <geom conaffinity="0" contype="1" friction=".7 .1 .1" />
    <motor ctrllimited="true" ctrlrange="-1 1" />
    <site size="0.01" />
    <default class="walker">
      <geom material="self" type="capsule" />
      <joint axis="0 -1 0" />
    </default>
  </default>

  <worldbody>
    <geom conaffinity="1" material="grid" name="floor" pos="248 0 0" size="250 .8 .2" type="plane" zaxis="0.07633085306930622 0.0 0.9970825446620315" />
    <body childclass="walker" name="torso" pos="0.7387950944300599 0.0 20.229468070120348">
      <light mode="trackcom" name="light" pos="0 0 2" />
      <camera euler="60 0 0" mode="trackcom" name="side" pos="0 -2 .7" />
      <camera mode="trackcom" name="back" pos="-2 0 .5" xyaxes="0 -1 0 1 0 3" />
      <joint armature="0" axis="0 0 1" damping="0.06437972298328391" limited="false" name="rootz" type="slide" />
      <joint armature="0" axis="1 0 0" damping="0.18198483221130238" limited="false" name="rootx" type="slide" />
      <joint armature="0" axis="0 1 0" damping="0.05747848918528356" limited="false" name="rooty" type="hinge" />
      <geom density="458.0020634097232" friction="0.8738559227376572 0.08057210459517888 0.19089100643814302" name="torso" size="0.07 0.3" />
      <body name="right_thigh" pos="0 -.05 -0.3">
        <joint damping="0.07916159753865032" name="right_hip" range="-20 100" />
        <geom density="1008.8579112981402" friction="1.4618473876683327 0.13303947097652902 0.10135789990883842" name="right_thigh" pos="0 0 -0.225" size="0.05 0.225" />
        <body name="right_leg" pos="0 0 -0.7">
          <joint damping="0.07069565643239718" name="right_knee" pos="0 0 0.25" range="-150 0" />
          <geom density="1419.7866572725043" friction="0.39214952237559414 0.13654841561059358 0.15470289625836142" name="right_leg" size="0.04 0.25" />
          <body name="right_foot" pos="0.06 0 -0.25">
            <joint damping="0.19376595366953706" name="right_ankle" pos="-0.06 0 0" range="-45 45" />
            <geom density="577.7542053796661" friction="1.0370120365504703 0.1712857471478855 0.04761839976450541" name="right_foot" size="0.05 0.1284089848748445" zaxis="1 0 0" />
          </body>
        </body>
      </body>
      <body name="left_thigh" pos="0 .05 -0.3">
        <joint damping="0.15224605044460213" name="left_hip" range="-20 100" />
        <geom density="1023.4785360738157" friction="0.6996704401289676 0.054754937637043304 0.06717673954076163" name="left_thigh" pos="0 0 -0.225" size="0.05 0.225" />
        <body name="left_leg" pos="0 0 -0.7">
          <joint damping="0.09268659463160397" name="left_knee" pos="0 0 0.25" range="-150 0" />
          <geom density="487.87225212985896" friction="0.7756269184347085 0.09255899141786296 0.0673561282705319" name="left_leg" size="0.04 0.25" />
          <body name="left_foot" pos="0.06 0 -0.25">
            <joint damping="0.06822227676523236" name="left_ankle" pos="-0.06 0 0" range="-45 45" />
            <geom density="778.5931970023487" friction="0.33766403027393965 0.10290132450911088 0.1255224895996003" name="left_foot" size="0.05 0.04711931766044999" zaxis="1 0 0" />
          </body>
        </body>
      </body>
    </body>
  </worldbody>

  <sensor>
    <subtreelinvel body="torso" name="torso_subtreelinvel" />
  </sensor>

  <actuator>
    <motor gear="100" joint="right_hip" name="right_hip" />
    <motor gear="50" joint="right_knee" name="right_knee" />
    <motor gear="20" joint="right_ankle" name="right_ankle" />
    <motor gear="100" joint="left_hip" name="left_hip" />
    <motor gear="50" joint="left_knee" name="left_knee" />
    <motor gear="20" joint="left_ankle" name="left_ankle" />
  </actuator>
</mujoco>