<mujoco model="planar walker">
  <include file="./common/visual.xml" />
  <include file="./common/skybox.xml" />
  <include file="./common/materials.xml" />

  <option timestep="0.0025" />

  <statistic center="0 0 1" extent="2" />

  <default>
    <joint armature="0.01" damping=".1" limited="true" solimplimit="0 .99 .01" />
    <geom conaffinity="0" contype="1" friction=".7 .1 .1" />
    <motor ctrllimited="true" ctrlrange="-1 1" />
    <site size="0.01" />
    <default class="walker">
      <geom material="self" type="capsule" />
      <joint axis="0 -1 0" />
    </default>
  </default>

  <worldbody>
    <geom conaffinity="1" material="grid" name="floor" pos="248 0 0" size="250 .8 .2" type="plane" zaxis="-0.1394705174044413 0.0 0.9902262240392028" />
    <body childclass="walker" name="torso" pos="2.3960023347968047 0.0 -33.2906430714936">
      <light mode="trackcom" name="light" pos="0 0 2" />
      <camera euler="60 0 0" mode="trackcom" name="side" pos="0 -2 .7" />
      <camera mode="trackcom" name="back" pos="-2 0 .5" xyaxes="0 -1 0 1 0 3" />
      <joint armature="0" axis="0 0 1" damping="0.13700993895461908" limited="false" name="rootz" type="slide" />
      <joint armature="0" axis="1 0 0" damping="0.04878806330751924" limited="false" name="rootx" type="slide" />
      <joint armature="0" axis="0 1 0" damping="0.05132653618423795" limited="false" name="rooty" type="hinge" />
      <geom density="1949.2763316097803" friction="1.065677974029827 0.0812034426578006 0.08659740628889387" name="torso" size="0.07 0.3" />
      <body name="right_thigh" pos="0 -.05 -0.3">
        <joint damping="0.09651514493321178" name="right_hip" range="-20 100" />
        <geom density="599.7860636210388" friction="0.4648941197070739 0.11128566970930674 0.06122342273140288" name="right_thigh" pos="0 0 -0.225" size="0.05 0.225" />
        <body name="right_leg" pos="0 0 -0.7">
          <joint damping="0.06850833884812244" name="right_knee" pos="0 0 0.25" range="-150 0" />
          <geom density="2127.345876243739" friction="0.6383101742877275 0.06184091108596175 0.05969218285939326" name="right_leg" size="0.04 0.25" />
          <body name="right_foot" pos="0.06 0 -0.25">
            <joint damping="0.20830524707623882" name="right_ankle" pos="-0.06 0 0" range="-45 45" />
            <geom density="1475.7292887016085" friction="0.6773921653314416 0.10568682252952617 0.18846057947138675" name="right_foot" size="0.05 0.06327263996091113" zaxis="1 0 0" />
          </body>
        </body>
      </body>
      <body name="left_thigh" pos="0 .05 -0.3">
        <joint damping="0.0825962770970135" name="left_hip" range="-20 100" />
        <geom density="1082.354892468021" friction="0.3613384775421358 0.05131458635681527 0.20311370588428593" name="left_thigh" pos="0 0 -0.225" size="0.05 0.225" />
        <body name="left_leg" pos="0 0 -0.7">
          <joint damping="0.06168166733522093" name="left_knee" pos="0 0 0.25" range="-150 0" />
          <geom density="873.192417836278" friction="0.4562944596345055 0.10350216421957614 0.1286527700833888" name="left_leg" size="0.04 0.25" />
          <body name="left_foot" pos="0.06 0 -0.25">
            <joint damping="0.10242118243501377" name="left_ankle" pos="-0.06 0 0" range="-45 45" />
            <geom density="825.6144711598704" friction="0.37625406696546765 0.1271871494496634 0.15323490579985255" name="left_foot" size="0.05 0.08192601703549224" zaxis="1 0 0" />
          </body>
        </body>
      </body>
    </body>
  </worldbody>

  <sensor>
    <subtreelinvel body="torso" name="torso_subtreelinvel" />
  </sensor>

  <actuator>
    <motor gear="100" joint="right_hip" name="right_hip" />
    <motor gear="50" joint="right_knee" name="right_knee" />
    <motor gear="20" joint="right_ankle" name="right_ankle" />
    <motor gear="100" joint="left_hip" name="left_hip" />
    <motor gear="50" joint="left_knee" name="left_knee" />
    <motor gear="20" joint="left_ankle" name="left_ankle" />
  </actuator>
</mujoco>