<mujoco model="planar walker">
  <include file="./common/visual.xml" />
  <include file="./common/skybox.xml" />
  <include file="./common/materials.xml" />

  <option timestep="0.0025" />

  <statistic center="0 0 1" extent="2" />

  <default>
    <joint armature="0.01" damping=".1" limited="true" solimplimit="0 .99 .01" />
    <geom conaffinity="0" contype="1" friction=".7 .1 .1" />
    <motor ctrllimited="true" ctrlrange="-1 1" />
    <site size="0.01" />
    <default class="walker">
      <geom material="self" type="capsule" />
      <joint axis="0 -1 0" />
    </default>
  </default>

  <worldbody>
    <geom conaffinity="1" material="grid" name="floor" pos="248 0 0" size="250 .8 .2" type="plane" zaxis="-0.0516567126637348 0.0 0.9986649007734157" />
    <body childclass="walker" name="torso" pos="0.32077326566016495 0.0 -11.511131760451546">
      <light mode="trackcom" name="light" pos="0 0 2" />
      <camera euler="60 0 0" mode="trackcom" name="side" pos="0 -2 .7" />
      <camera mode="trackcom" name="back" pos="-2 0 .5" xyaxes="0 -1 0 1 0 3" />
      <joint armature="0" axis="0 0 1" damping="0.11959214939591656" limited="false" name="rootz" type="slide" />
      <joint armature="0" axis="1 0 0" damping="0.20516472677196773" limited="false" name="rootx" type="slide" />
      <joint armature="0" axis="0 1 0" damping="0.11527840363399872" limited="false" name="rooty" type="hinge" />
      <geom density="525.3234022352109" friction="0.8756287254211357 0.13060810666647135 0.17670263174590803" name="torso" size="0.07 0.3" />
      <body name="right_thigh" pos="0 -.05 -0.3">
        <joint damping="0.18023732529197498" name="right_hip" range="-20 100" />
        <geom density="874.2061541729961" friction="0.4522925350733827 0.0849991313493676 0.10768092622370413" name="right_thigh" pos="0 0 -0.225" size="0.05 0.225" />
        <body name="right_leg" pos="0 0 -0.7">
          <joint damping="0.0890229021533443" name="right_knee" pos="0 0 0.25" range="-150 0" />
          <geom density="484.80638597045146" friction="0.875702063207025 0.08075123473214933 0.21856983955823492" name="right_leg" size="0.04 0.25" />
          <body name="right_foot" pos="0.06 0 -0.25">
            <joint damping="0.15310827299333862" name="right_ankle" pos="-0.06 0 0" range="-45 45" />
            <geom density="2097.0892106577207" friction="0.6725701567464789 0.10551563078878985 0.1490219941648753" name="right_foot" size="0.05 0.05371404304099941" zaxis="1 0 0" />
          </body>
        </body>
      </body>
      <body name="left_thigh" pos="0 .05 -0.3">
        <joint damping="0.045755798425831835" name="left_hip" range="-20 100" />
        <geom density="552.6303050336368" friction="0.6136782926831855 0.07096972294765584 0.13773268824666174" name="left_thigh" pos="0 0 -0.225" size="0.05 0.225" />
        <body name="left_leg" pos="0 0 -0.7">
          <joint damping="0.09051617965387208" name="left_knee" pos="0 0 0.25" range="-150 0" />
          <geom density="1372.3382678622304" friction="1.3782162582996533 0.08188686055498912 0.0858727126208641" name="left_leg" size="0.04 0.25" />
          <body name="left_foot" pos="0.06 0 -0.25">
            <joint damping="0.11174570162520406" name="left_ankle" pos="-0.06 0 0" range="-45 45" />
            <geom density="1716.238030484365" friction="0.4775641785955006 0.056519976047459786 0.14295015936502106" name="left_foot" size="0.05 0.18395887568102964" zaxis="1 0 0" />
          </body>
        </body>
      </body>
    </body>
  </worldbody>

  <sensor>
    <subtreelinvel body="torso" name="torso_subtreelinvel" />
  </sensor>

  <actuator>
    <motor gear="100" joint="right_hip" name="right_hip" />
    <motor gear="50" joint="right_knee" name="right_knee" />
    <motor gear="20" joint="right_ankle" name="right_ankle" />
    <motor gear="100" joint="left_hip" name="left_hip" />
    <motor gear="50" joint="left_knee" name="left_knee" />
    <motor gear="20" joint="left_ankle" name="left_ankle" />
  </actuator>
</mujoco>