<mujoco model="planar walker">
  <include file="./common/visual.xml" />
  <include file="./common/skybox.xml" />
  <include file="./common/materials.xml" />

  <option timestep="0.0025" />

  <statistic center="0 0 1" extent="2" />

  <default>
    <joint armature="0.01" damping=".1" limited="true" solimplimit="0 .99 .01" />
    <geom conaffinity="0" contype="1" friction=".7 .1 .1" />
    <motor ctrllimited="true" ctrlrange="-1 1" />
    <site size="0.01" />
    <default class="walker">
      <geom material="self" type="capsule" />
      <joint axis="0 -1 0" />
    </default>
  </default>

  <worldbody>
    <geom conaffinity="1" material="grid" name="floor" pos="248 0 0" size="250 .8 .2" type="plane" zaxis="0.18304740492819144 0.0 0.9831040878508515" />
    <body childclass="walker" name="torso" pos="4.226795693974481 0.0 46.69237723976165">
      <light mode="trackcom" name="light" pos="0 0 2" />
      <camera euler="60 0 0" mode="trackcom" name="side" pos="0 -2 .7" />
      <camera mode="trackcom" name="back" pos="-2 0 .5" xyaxes="0 -1 0 1 0 3" />
      <joint armature="0" axis="0 0 1" damping="0.0882954913315705" limited="false" name="rootz" type="slide" />
      <joint armature="0" axis="1 0 0" damping="0.2171241267240118" limited="false" name="rootx" type="slide" />
      <joint armature="0" axis="0 1 0" damping="0.0665120912657227" limited="false" name="rooty" type="hinge" />
      <geom density="932.1145911650158" friction="0.44943032391020393 0.17518353710386225 0.10231415707570475" name="torso" size="0.07 0.3" />
      <body name="right_thigh" pos="0 -.05 -0.3">
        <joint damping="0.13710498182553268" name="right_hip" range="-20 100" />
        <geom density="851.8564074227259" friction="1.4242165840438443 0.18323396683916898 0.12413883915691837" name="right_thigh" pos="0 0 -0.225" size="0.05 0.225" />
        <body name="right_leg" pos="0 0 -0.7">
          <joint damping="0.05028620304516123" name="right_knee" pos="0 0 0.25" range="-150 0" />
          <geom density="691.930628480257" friction="0.4520755518306846 0.17804204322305814 0.2164314154830157" name="right_leg" size="0.04 0.25" />
          <body name="right_foot" pos="0.06 0 -0.25">
            <joint damping="0.20009002083008168" name="right_ankle" pos="-0.06 0 0" range="-45 45" />
            <geom density="2131.320694500596" friction="0.5490568575346456 0.1044458137480498 0.16255407988880158" name="right_foot" size="0.05 0.056681622892139565" zaxis="1 0 0" />
          </body>
        </body>
      </body>
      <body name="left_thigh" pos="0 .05 -0.3">
        <joint damping="0.08636352406547965" name="left_hip" range="-20 100" />
        <geom density="493.49028186435703" friction="0.3222495875611514 0.1825532757142184 0.19237980931264287" name="left_thigh" pos="0 0 -0.225" size="0.05 0.225" />
        <body name="left_leg" pos="0 0 -0.7">
          <joint damping="0.18314433150762158" name="left_knee" pos="0 0 0.25" range="-150 0" />
          <geom density="518.2445196825186" friction="1.243883155374259 0.2056889999676184 0.09345094830394422" name="left_leg" size="0.04 0.25" />
          <body name="left_foot" pos="0.06 0 -0.25">
            <joint damping="0.21235435326646088" name="left_ankle" pos="-0.06 0 0" range="-45 45" />
            <geom density="1569.5925712104872" friction="1.1663821911659258 0.05710540457701368 0.1249600337691989" name="left_foot" size="0.05 0.06259750211911913" zaxis="1 0 0" />
          </body>
        </body>
      </body>
    </body>
  </worldbody>

  <sensor>
    <subtreelinvel body="torso" name="torso_subtreelinvel" />
  </sensor>

  <actuator>
    <motor gear="100" joint="right_hip" name="right_hip" />
    <motor gear="50" joint="right_knee" name="right_knee" />
    <motor gear="20" joint="right_ankle" name="right_ankle" />
    <motor gear="100" joint="left_hip" name="left_hip" />
    <motor gear="50" joint="left_knee" name="left_knee" />
    <motor gear="20" joint="left_ankle" name="left_ankle" />
  </actuator>
</mujoco>