<mujoco model="planar walker">
  <include file="./common/visual.xml" />
  <include file="./common/skybox.xml" />
  <include file="./common/materials.xml" />

  <option timestep="0.0025" />

  <statistic center="0 0 1" extent="2" />

  <default>
    <joint armature="0.01" damping=".1" limited="true" solimplimit="0 .99 .01" />
    <geom conaffinity="0" contype="1" friction=".7 .1 .1" />
    <motor ctrllimited="true" ctrlrange="-1 1" />
    <site size="0.01" />
    <default class="walker">
      <geom material="self" type="capsule" />
      <joint axis="0 -1 0" />
    </default>
  </default>

  <worldbody>
    <geom conaffinity="1" material="grid" name="floor" pos="248 0 0" size="250 .8 .2" type="plane" zaxis="-0.1890387931912663 0.0 0.9819696200335272" />
    <body childclass="walker" name="torso" pos="4.433726473047017 0.0 -45.58522678742733">
      <light mode="trackcom" name="light" pos="0 0 2" />
      <camera euler="60 0 0" mode="trackcom" name="side" pos="0 -2 .7" />
      <camera mode="trackcom" name="back" pos="-2 0 .5" xyaxes="0 -1 0 1 0 3" />
      <joint armature="0" axis="0 0 1" damping="0.048994191379600094" limited="false" name="rootz" type="slide" />
      <joint armature="0" axis="1 0 0" damping="0.07388181085448832" limited="false" name="rootx" type="slide" />
      <joint armature="0" axis="0 1 0" damping="0.09874302184144781" limited="false" name="rooty" type="hinge" />
      <geom density="1039.4457183199756" friction="0.3199128398166208 0.19660356171046828 0.09237765413726762" name="torso" size="0.07 0.3" />
      <body name="right_thigh" pos="0 -.05 -0.3">
        <joint damping="0.21342541972293924" name="right_hip" range="-20 100" />
        <geom density="863.8717203183598" friction="0.45535387964377355 0.16661443314199978 0.07852060714731765" name="right_thigh" pos="0 0 -0.225" size="0.05 0.225" />
        <body name="right_leg" pos="0 0 -0.7">
          <joint damping="0.15461660813415565" name="right_knee" pos="0 0 0.25" range="-150 0" />
          <geom density="1573.6492311083534" friction="0.7068796844883244 0.10446622343248474 0.06066271348108992" name="right_leg" size="0.04 0.25" />
          <body name="right_foot" pos="0.06 0 -0.25">
            <joint damping="0.05999390536342745" name="right_ankle" pos="-0.06 0 0" range="-45 45" />
            <geom density="997.6694391491218" friction="1.4933059456052031 0.11744981120327638 0.08078897732983281" name="right_foot" size="0.05 0.14991500050657852" zaxis="1 0 0" />
          </body>
        </body>
      </body>
      <body name="left_thigh" pos="0 .05 -0.3">
        <joint damping="0.18013520984088344" name="left_hip" range="-20 100" />
        <geom density="455.8652710095843" friction="0.45463906572339763 0.18666885034972527 0.07605617274413509" name="left_thigh" pos="0 0 -0.225" size="0.05 0.225" />
        <body name="left_leg" pos="0 0 -0.7">
          <joint damping="0.20198282222394087" name="left_knee" pos="0 0 0.25" range="-150 0" />
          <geom density="1440.1061508174262" friction="0.55635033805031 0.12757503224245292 0.04577141915790699" name="left_leg" size="0.04 0.25" />
          <body name="left_foot" pos="0.06 0 -0.25">
            <joint damping="0.08223801037406565" name="left_ankle" pos="-0.06 0 0" range="-45 45" />
            <geom density="520.6116708440917" friction="1.2927685383388057 0.054495484769503034 0.06762461918131872" name="left_foot" size="0.05 0.06381119914403369" zaxis="1 0 0" />
          </body>
        </body>
      </body>
    </body>
  </worldbody>

  <sensor>
    <subtreelinvel body="torso" name="torso_subtreelinvel" />
  </sensor>

  <actuator>
    <motor gear="100" joint="right_hip" name="right_hip" />
    <motor gear="50" joint="right_knee" name="right_knee" />
    <motor gear="20" joint="right_ankle" name="right_ankle" />
    <motor gear="100" joint="left_hip" name="left_hip" />
    <motor gear="50" joint="left_knee" name="left_knee" />
    <motor gear="20" joint="left_ankle" name="left_ankle" />
  </actuator>
</mujoco>