<mujoco model="planar walker">
  <include file="./common/visual.xml" />
  <include file="./common/skybox.xml" />
  <include file="./common/materials.xml" />

  <option timestep="0.0025" />

  <statistic center="0 0 1" extent="2" />

  <default>
    <joint armature="0.01" damping=".1" limited="true" solimplimit="0 .99 .01" />
    <geom conaffinity="0" contype="1" friction=".7 .1 .1" />
    <motor ctrllimited="true" ctrlrange="-1 1" />
    <site size="0.01" />
    <default class="walker">
      <geom material="self" type="capsule" />
      <joint axis="0 -1 0" />
    </default>
  </default>

  <worldbody>
    <geom conaffinity="1" material="grid" name="floor" pos="248 0 0" size="250 .8 .2" type="plane" zaxis="-0.15463975372991456 0.0 0.9879709239478414" />
    <body childclass="walker" name="torso" pos="2.9522829101893535 0.0 -37.053064740229246">
      <light mode="trackcom" name="light" pos="0 0 2" />
      <camera euler="60 0 0" mode="trackcom" name="side" pos="0 -2 .7" />
      <camera mode="trackcom" name="back" pos="-2 0 .5" xyaxes="0 -1 0 1 0 3" />
      <joint armature="0" axis="0 0 1" damping="0.06668943335725407" limited="false" name="rootz" type="slide" />
      <joint armature="0" axis="1 0 0" damping="0.053893297908289145" limited="false" name="rootx" type="slide" />
      <joint armature="0" axis="0 1 0" damping="0.061650139795986714" limited="false" name="rooty" type="hinge" />
      <geom density="558.5924407746638" friction="0.4271701008165118 0.16140859266744803 0.0828042450223838" name="torso" size="0.07 0.3" />
      <body name="right_thigh" pos="0 -.05 -0.3">
        <joint damping="0.18749303211711568" name="right_hip" range="-20 100" />
        <geom density="1250.4352145128894" friction="1.1653807614558256 0.08419854017911281 0.12755289601216854" name="right_thigh" pos="0 0 -0.225" size="0.05 0.225" />
        <body name="right_leg" pos="0 0 -0.7">
          <joint damping="0.1082230805964716" name="right_knee" pos="0 0 0.25" range="-150 0" />
          <geom density="1314.486765165662" friction="0.3276484557661836 0.05174084178315749 0.06693789381245752" name="right_leg" size="0.04 0.25" />
          <body name="right_foot" pos="0.06 0 -0.25">
            <joint damping="0.1518759829207341" name="right_ankle" pos="-0.06 0 0" range="-45 45" />
            <geom density="2074.203911988079" friction="0.3901359293130544 0.08290755056192366 0.21605668615931287" name="right_foot" size="0.05 0.05365012641066526" zaxis="1 0 0" />
          </body>
        </body>
      </body>
      <body name="left_thigh" pos="0 .05 -0.3">
        <joint damping="0.1326159175791278" name="left_hip" range="-20 100" />
        <geom density="712.8120290788462" friction="1.3995305926354242 0.2071503159889869 0.04767557016489246" name="left_thigh" pos="0 0 -0.225" size="0.05 0.225" />
        <body name="left_leg" pos="0 0 -0.7">
          <joint damping="0.19336104240061938" name="left_knee" pos="0 0 0.25" range="-150 0" />
          <geom density="1027.5765722089156" friction="0.5173376398177902 0.09818662841439274 0.1965618457709941" name="left_leg" size="0.04 0.25" />
          <body name="left_foot" pos="0.06 0 -0.25">
            <joint damping="0.10798711895502788" name="left_ankle" pos="-0.06 0 0" range="-45 45" />
            <geom density="504.6862613943068" friction="0.7213221077278484 0.19004217166677329 0.19771089636907513" name="left_foot" size="0.05 0.1982661968686998" zaxis="1 0 0" />
          </body>
        </body>
      </body>
    </body>
  </worldbody>

  <sensor>
    <subtreelinvel body="torso" name="torso_subtreelinvel" />
  </sensor>

  <actuator>
    <motor gear="100" joint="right_hip" name="right_hip" />
    <motor gear="50" joint="right_knee" name="right_knee" />
    <motor gear="20" joint="right_ankle" name="right_ankle" />
    <motor gear="100" joint="left_hip" name="left_hip" />
    <motor gear="50" joint="left_knee" name="left_knee" />
    <motor gear="20" joint="left_ankle" name="left_ankle" />
  </actuator>
</mujoco>