<mujoco model="planar walker">
  <include file="./common/visual.xml" />
  <include file="./common/skybox.xml" />
  <include file="./common/materials.xml" />

  <option timestep="0.0025" />

  <statistic center="0 0 1" extent="2" />

  <default>
    <joint armature="0.01" damping=".1" limited="true" solimplimit="0 .99 .01" />
    <geom conaffinity="0" contype="1" friction=".7 .1 .1" />
    <motor ctrllimited="true" ctrlrange="-1 1" />
    <site size="0.01" />
    <default class="walker">
      <geom material="self" type="capsule" />
      <joint axis="0 -1 0" />
    </default>
  </default>

  <worldbody>
    <geom conaffinity="1" material="grid" name="floor" pos="248 0 0" size="250 .8 .2" type="plane" zaxis="-0.11291586685519261 0.0 0.993604552632656" />
    <body childclass="walker" name="torso" pos="1.5634877737302872 0.0 -26.704414069561235">
      <light mode="trackcom" name="light" pos="0 0 2" />
      <camera euler="60 0 0" mode="trackcom" name="side" pos="0 -2 .7" />
      <camera mode="trackcom" name="back" pos="-2 0 .5" xyaxes="0 -1 0 1 0 3" />
      <joint armature="0" axis="0 0 1" damping="0.05795602718801457" limited="false" name="rootz" type="slide" />
      <joint armature="0" axis="1 0 0" damping="0.07777630497534808" limited="false" name="rootx" type="slide" />
      <joint armature="0" axis="0 1 0" damping="0.12946163738590555" limited="false" name="rooty" type="hinge" />
      <geom density="1599.556581238739" friction="0.7411063330867668 0.055442468292361304 0.18162750953121642" name="torso" size="0.07 0.3" />
      <body name="right_thigh" pos="0 -.05 -0.3">
        <joint damping="0.12437738128515921" name="right_hip" range="-20 100" />
        <geom density="1243.9502936713445" friction="0.6272111005221872 0.11090906530675537 0.0898810862413946" name="right_thigh" pos="0 0 -0.225" size="0.05 0.225" />
        <body name="right_leg" pos="0 0 -0.7">
          <joint damping="0.07621328535971755" name="right_knee" pos="0 0 0.25" range="-150 0" />
          <geom density="696.7359589392067" friction="0.6292958899383403 0.17871004220177344 0.06870035255745255" name="right_leg" size="0.04 0.25" />
          <body name="right_foot" pos="0.06 0 -0.25">
            <joint damping="0.08817698097082488" name="right_ankle" pos="-0.06 0 0" range="-45 45" />
            <geom density="1266.8686949239295" friction="1.5013354955120122 0.089323697779423 0.20427029570766975" name="right_foot" size="0.05 0.08971561440412482" zaxis="1 0 0" />
          </body>
        </body>
      </body>
      <body name="left_thigh" pos="0 .05 -0.3">
        <joint damping="0.09845111610022295" name="left_hip" range="-20 100" />
        <geom density="1551.1931702225172" friction="1.3618140180792273 0.15857424087659228 0.17685782436204522" name="left_thigh" pos="0 0 -0.225" size="0.05 0.225" />
        <body name="left_leg" pos="0 0 -0.7">
          <joint damping="0.1396865680135805" name="left_knee" pos="0 0 0.25" range="-150 0" />
          <geom density="1520.8804063949628" friction="0.36352370379787186 0.05162643102383446 0.05520324747036215" name="left_leg" size="0.04 0.25" />
          <body name="left_foot" pos="0.06 0 -0.25">
            <joint damping="0.13165110583653816" name="left_ankle" pos="-0.06 0 0" range="-45 45" />
            <geom density="1122.9704043736647" friction="0.5746680024686713 0.06196033405597426 0.06111632471769793" name="left_foot" size="0.05 0.050667485196733524" zaxis="1 0 0" />
          </body>
        </body>
      </body>
    </body>
  </worldbody>

  <sensor>
    <subtreelinvel body="torso" name="torso_subtreelinvel" />
  </sensor>

  <actuator>
    <motor gear="100" joint="right_hip" name="right_hip" />
    <motor gear="50" joint="right_knee" name="right_knee" />
    <motor gear="20" joint="right_ankle" name="right_ankle" />
    <motor gear="100" joint="left_hip" name="left_hip" />
    <motor gear="50" joint="left_knee" name="left_knee" />
    <motor gear="20" joint="left_ankle" name="left_ankle" />
  </actuator>
</mujoco>