<mujoco model="planar walker">
  <include file="./common/visual.xml" />
  <include file="./common/skybox.xml" />
  <include file="./common/materials.xml" />

  <option timestep="0.0025" />

  <statistic center="0 0 1" extent="2" />

  <default>
    <joint armature="0.01" damping=".1" limited="true" solimplimit="0 .99 .01" />
    <geom conaffinity="0" contype="1" friction=".7 .1 .1" />
    <motor ctrllimited="true" ctrlrange="-1 1" />
    <site size="0.01" />
    <default class="walker">
      <geom material="self" type="capsule" />
      <joint axis="0 -1 0" />
    </default>
  </default>

  <worldbody>
    <geom conaffinity="1" material="grid" name="floor" pos="248 0 0" size="250 .8 .2" type="plane" zaxis="-0.09882606832233927 0.0 0.9951047222377896" />
    <body childclass="walker" name="torso" pos="1.1942636713637285 0.0 -23.20984399949258">
      <light mode="trackcom" name="light" pos="0 0 2" />
      <camera euler="60 0 0" mode="trackcom" name="side" pos="0 -2 .7" />
      <camera mode="trackcom" name="back" pos="-2 0 .5" xyaxes="0 -1 0 1 0 3" />
      <joint armature="0" axis="0 0 1" damping="0.060566267004675094" limited="false" name="rootz" type="slide" />
      <joint armature="0" axis="1 0 0" damping="0.08955970828511711" limited="false" name="rootx" type="slide" />
      <joint armature="0" axis="0 1 0" damping="0.05092266802259199" limited="false" name="rooty" type="hinge" />
      <geom density="824.5751627304558" friction="0.8343680003126387 0.11761939381708182 0.14953807156431909" name="torso" size="0.07 0.3" />
      <body name="right_thigh" pos="0 -.05 -0.3">
        <joint damping="0.17189829995476635" name="right_hip" range="-20 100" />
        <geom density="1513.95215118096" friction="0.41362587913979715 0.10014327957865372 0.07736781843391452" name="right_thigh" pos="0 0 -0.225" size="0.05 0.225" />
        <body name="right_leg" pos="0 0 -0.7">
          <joint damping="0.05253236467654959" name="right_knee" pos="0 0 0.25" range="-150 0" />
          <geom density="464.1291288285148" friction="0.7764551605127451 0.05927952603115484 0.07662454721152395" name="right_leg" size="0.04 0.25" />
          <body name="right_foot" pos="0.06 0 -0.25">
            <joint damping="0.07660390672790746" name="right_ankle" pos="-0.06 0 0" range="-45 45" />
            <geom density="834.5481832865664" friction="0.9985928089327335 0.2172475154824567 0.058859032141164364" name="right_foot" size="0.05 0.07007237577777324" zaxis="1 0 0" />
          </body>
        </body>
      </body>
      <body name="left_thigh" pos="0 .05 -0.3">
        <joint damping="0.12589892602973293" name="left_hip" range="-20 100" />
        <geom density="1020.4844085677671" friction="0.45128032145181457 0.048595910710134485 0.16824653394855216" name="left_thigh" pos="0 0 -0.225" size="0.05 0.225" />
        <body name="left_leg" pos="0 0 -0.7">
          <joint damping="0.04619226569799016" name="left_knee" pos="0 0 0.25" range="-150 0" />
          <geom density="646.368430414122" friction="0.8644175015395085 0.05512484462758384 0.0501217788586612" name="left_leg" size="0.04 0.25" />
          <body name="left_foot" pos="0.06 0 -0.25">
            <joint damping="0.07266484722050663" name="left_ankle" pos="-0.06 0 0" range="-45 45" />
            <geom density="1158.7982708164704" friction="1.1502522754813238 0.08440445698384182 0.09995512909268457" name="left_foot" size="0.05 0.16872861452678303" zaxis="1 0 0" />
          </body>
        </body>
      </body>
    </body>
  </worldbody>

  <sensor>
    <subtreelinvel body="torso" name="torso_subtreelinvel" />
  </sensor>

  <actuator>
    <motor gear="100" joint="right_hip" name="right_hip" />
    <motor gear="50" joint="right_knee" name="right_knee" />
    <motor gear="20" joint="right_ankle" name="right_ankle" />
    <motor gear="100" joint="left_hip" name="left_hip" />
    <motor gear="50" joint="left_knee" name="left_knee" />
    <motor gear="20" joint="left_ankle" name="left_ankle" />
  </actuator>
</mujoco>