<mujoco model="planar walker">
  <include file="./common/visual.xml" />
  <include file="./common/skybox.xml" />
  <include file="./common/materials.xml" />

  <option timestep="0.0025" />

  <statistic center="0 0 1" extent="2" />

  <default>
    <joint armature="0.01" damping=".1" limited="true" solimplimit="0 .99 .01" />
    <geom conaffinity="0" contype="1" friction=".7 .1 .1" />
    <motor ctrllimited="true" ctrlrange="-1 1" />
    <site size="0.01" />
    <default class="walker">
      <geom material="self" type="capsule" />
      <joint axis="0 -1 0" />
    </default>
  </default>

  <worldbody>
    <geom conaffinity="1" material="grid" name="floor" pos="248 0 0" size="250 .8 .2" type="plane" zaxis="-0.09039835156305455 0.0 0.9959056873191771" />
    <body childclass="walker" name="torso" pos="0.9973098745314815 0.0 -21.11961005017369">
      <light mode="trackcom" name="light" pos="0 0 2" />
      <camera euler="60 0 0" mode="trackcom" name="side" pos="0 -2 .7" />
      <camera mode="trackcom" name="back" pos="-2 0 .5" xyaxes="0 -1 0 1 0 3" />
      <joint armature="0" axis="0 0 1" damping="0.08552327210344099" limited="false" name="rootz" type="slide" />
      <joint armature="0" axis="1 0 0" damping="0.058970434759158856" limited="false" name="rootx" type="slide" />
      <joint armature="0" axis="0 1 0" damping="0.21857644388501846" limited="false" name="rooty" type="hinge" />
      <geom density="715.3938382221801" friction="0.4882999598926913 0.06480390888479777 0.1473749135456058" name="torso" size="0.07 0.3" />
      <body name="right_thigh" pos="0 -.05 -0.3">
        <joint damping="0.10672717677796656" name="right_hip" range="-20 100" />
        <geom density="459.48245830924907" friction="0.60913467762777 0.13229649040395053 0.12358438274795132" name="right_thigh" pos="0 0 -0.225" size="0.05 0.225" />
        <body name="right_leg" pos="0 0 -0.7">
          <joint damping="0.12918887794010542" name="right_knee" pos="0 0 0.25" range="-150 0" />
          <geom density="1535.8721829963604" friction="0.9687853927791932 0.2179608669919146 0.04623314933882106" name="right_leg" size="0.04 0.25" />
          <body name="right_foot" pos="0.06 0 -0.25">
            <joint damping="0.1983127955566184" name="right_ankle" pos="-0.06 0 0" range="-45 45" />
            <geom density="1677.9167513235905" friction="0.6694084804550816 0.18046188000944563 0.1841729035960877" name="right_foot" size="0.05 0.05823357931307889" zaxis="1 0 0" />
          </body>
        </body>
      </body>
      <body name="left_thigh" pos="0 .05 -0.3">
        <joint damping="0.08359831155294244" name="left_hip" range="-20 100" />
        <geom density="712.063053991603" friction="0.6956044154637315 0.21814647798388906 0.161171685823149" name="left_thigh" pos="0 0 -0.225" size="0.05 0.225" />
        <body name="left_leg" pos="0 0 -0.7">
          <joint damping="0.08004509634418652" name="left_knee" pos="0 0 0.25" range="-150 0" />
          <geom density="1710.5066487385407" friction="1.1006507001825143 0.08942066626408968 0.14935111503392545" name="left_leg" size="0.04 0.25" />
          <body name="left_foot" pos="0.06 0 -0.25">
            <joint damping="0.1095583011718885" name="left_ankle" pos="-0.06 0 0" range="-45 45" />
            <geom density="1420.9770554024208" friction="1.138411125063891 0.0583684889883941 0.13800320604381822" name="left_foot" size="0.05 0.10967684971451681" zaxis="1 0 0" />
          </body>
        </body>
      </body>
    </body>
  </worldbody>

  <sensor>
    <subtreelinvel body="torso" name="torso_subtreelinvel" />
  </sensor>

  <actuator>
    <motor gear="100" joint="right_hip" name="right_hip" />
    <motor gear="50" joint="right_knee" name="right_knee" />
    <motor gear="20" joint="right_ankle" name="right_ankle" />
    <motor gear="100" joint="left_hip" name="left_hip" />
    <motor gear="50" joint="left_knee" name="left_knee" />
    <motor gear="20" joint="left_ankle" name="left_ankle" />
  </actuator>
</mujoco>