<mujoco model="planar walker">
  <include file="./common/visual.xml" />
  <include file="./common/skybox.xml" />
  <include file="./common/materials.xml" />

  <option timestep="0.0025" />

  <statistic center="0 0 1" extent="2" />

  <default>
    <joint armature="0.01" damping=".1" limited="true" solimplimit="0 .99 .01" />
    <geom conaffinity="0" contype="1" friction=".7 .1 .1" />
    <motor ctrllimited="true" ctrlrange="-1 1" />
    <site size="0.01" />
    <default class="walker">
      <geom material="self" type="capsule" />
      <joint axis="0 -1 0" />
    </default>
  </default>

  <worldbody>
    <geom conaffinity="1" material="grid" name="floor" pos="248 0 0" size="250 .8 .2" type="plane" zaxis="-0.06922678946293054 0.0 0.9976009480852828" />
    <body childclass="walker" name="torso" pos="0.5811195169572727 0.0 -15.868723597189716">
      <light mode="trackcom" name="light" pos="0 0 2" />
      <camera euler="60 0 0" mode="trackcom" name="side" pos="0 -2 .7" />
      <camera mode="trackcom" name="back" pos="-2 0 .5" xyaxes="0 -1 0 1 0 3" />
      <joint armature="0" axis="0 0 1" damping="0.07944945907626036" limited="false" name="rootz" type="slide" />
      <joint armature="0" axis="1 0 0" damping="0.13558659054402628" limited="false" name="rootx" type="slide" />
      <joint armature="0" axis="0 1 0" damping="0.12162082073390215" limited="false" name="rooty" type="hinge" />
      <geom density="476.7845292274395" friction="0.33211135606771497 0.18410077015919502 0.07259927643143702" name="torso" size="0.07 0.3" />
      <body name="right_thigh" pos="0 -.05 -0.3">
        <joint damping="0.20678063400215885" name="right_hip" range="-20 100" />
        <geom density="612.594252000429" friction="0.6107797174231424 0.0983860002127547 0.11640882256630392" name="right_thigh" pos="0 0 -0.225" size="0.05 0.225" />
        <body name="right_leg" pos="0 0 -0.7">
          <joint damping="0.08799489009171789" name="right_knee" pos="0 0 0.25" range="-150 0" />
          <geom density="1377.3065959911555" friction="0.38434579872022506 0.08260384102971093 0.21884104853136666" name="right_leg" size="0.04 0.25" />
          <body name="right_foot" pos="0.06 0 -0.25">
            <joint damping="0.19375529951593842" name="right_ankle" pos="-0.06 0 0" range="-45 45" />
            <geom density="1633.3784909963013" friction="1.2364682865124177 0.16641169142103346 0.06349497376268959" name="right_foot" size="0.05 0.11612821550676218" zaxis="1 0 0" />
          </body>
        </body>
      </body>
      <body name="left_thigh" pos="0 .05 -0.3">
        <joint damping="0.21800726308581583" name="left_hip" range="-20 100" />
        <geom density="1580.890479738008" friction="0.8621792699083473 0.060776375753928115 0.15013111429209525" name="left_thigh" pos="0 0 -0.225" size="0.05 0.225" />
        <body name="left_leg" pos="0 0 -0.7">
          <joint damping="0.10836140517261168" name="left_knee" pos="0 0 0.25" range="-150 0" />
          <geom density="520.9319323704963" friction="0.6273444604523546 0.09985024106909533 0.11453499271905006" name="left_leg" size="0.04 0.25" />
          <body name="left_foot" pos="0.06 0 -0.25">
            <joint damping="0.07765785935734683" name="left_ankle" pos="-0.06 0 0" range="-45 45" />
            <geom density="1871.2451931128055" friction="0.6949504879749884 0.1424007955768806 0.1388618541296128" name="left_foot" size="0.05 0.15774210643268227" zaxis="1 0 0" />
          </body>
        </body>
      </body>
    </body>
  </worldbody>

  <sensor>
    <subtreelinvel body="torso" name="torso_subtreelinvel" />
  </sensor>

  <actuator>
    <motor gear="100" joint="right_hip" name="right_hip" />
    <motor gear="50" joint="right_knee" name="right_knee" />
    <motor gear="20" joint="right_ankle" name="right_ankle" />
    <motor gear="100" joint="left_hip" name="left_hip" />
    <motor gear="50" joint="left_knee" name="left_knee" />
    <motor gear="20" joint="left_ankle" name="left_ankle" />
  </actuator>
</mujoco>