<mujoco model="planar walker">
  <include file="./common/visual.xml" />
  <include file="./common/skybox.xml" />
  <include file="./common/materials.xml" />

  <option timestep="0.0025" />

  <statistic center="0 0 1" extent="2" />

  <default>
    <joint armature="0.01" damping=".1" limited="true" solimplimit="0 .99 .01" />
    <geom conaffinity="0" contype="1" friction=".7 .1 .1" />
    <motor ctrllimited="true" ctrlrange="-1 1" />
    <site size="0.01" />
    <default class="walker">
      <geom material="self" type="capsule" />
      <joint axis="0 -1 0" />
    </default>
  </default>

  <worldbody>
    <geom conaffinity="1" material="grid" name="floor" pos="248 0 0" size="250 .8 .2" type="plane" zaxis="0.18497172747205087 0.0 0.9827438425327352" />
    <body childclass="walker" name="torso" pos="4.3165213973760785 0.0 47.169537181575166">
      <light mode="trackcom" name="light" pos="0 0 2" />
      <camera euler="60 0 0" mode="trackcom" name="side" pos="0 -2 .7" />
      <camera mode="trackcom" name="back" pos="-2 0 .5" xyaxes="0 -1 0 1 0 3" />
      <joint armature="0" axis="0 0 1" damping="0.08542442871710686" limited="false" name="rootz" type="slide" />
      <joint armature="0" axis="1 0 0" damping="0.09864058494310582" limited="false" name="rootx" type="slide" />
      <joint armature="0" axis="0 1 0" damping="0.1812403825172983" limited="false" name="rooty" type="hinge" />
      <geom density="681.0009129839805" friction="0.7949999502019217 0.10559518592973774 0.1768187596418725" name="torso" size="0.07 0.3" />
      <body name="right_thigh" pos="0 -.05 -0.3">
        <joint damping="0.06688491560498198" name="right_hip" range="-20 100" />
        <geom density="1515.6179205093983" friction="1.4099886739368872 0.0660167214860928 0.1336114262957585" name="right_thigh" pos="0 0 -0.225" size="0.05 0.225" />
        <body name="right_leg" pos="0 0 -0.7">
          <joint damping="0.20703043695271048" name="right_knee" pos="0 0 0.25" range="-150 0" />
          <geom density="665.7156573776507" friction="0.3405803922391764 0.17993246654767095 0.04747268717389684" name="right_leg" size="0.04 0.25" />
          <body name="right_foot" pos="0.06 0 -0.25">
            <joint damping="0.16000534693740118" name="right_ankle" pos="-0.06 0 0" range="-45 45" />
            <geom density="1680.1308638232179" friction="0.7855596841819514 0.06981334919685077 0.04801084057664859" name="right_foot" size="0.05 0.05439736618724174" zaxis="1 0 0" />
          </body>
        </body>
      </body>
      <body name="left_thigh" pos="0 .05 -0.3">
        <joint damping="0.1973737839421791" name="left_hip" range="-20 100" />
        <geom density="2073.980034581196" friction="0.7663169333016495 0.10087078018747529 0.13933170658273586" name="left_thigh" pos="0 0 -0.225" size="0.05 0.225" />
        <body name="left_leg" pos="0 0 -0.7">
          <joint damping="0.16285437567417338" name="left_knee" pos="0 0 0.25" range="-150 0" />
          <geom density="1554.1369807687652" friction="0.5242042717830812 0.2022991428500156 0.13225854893789732" name="left_leg" size="0.04 0.25" />
          <body name="left_foot" pos="0.06 0 -0.25">
            <joint damping="0.05338484554915898" name="left_ankle" pos="-0.06 0 0" range="-45 45" />
            <geom density="489.0419849494143" friction="0.9885625494060514 0.1598489209261199 0.12155428502353538" name="left_foot" size="0.05 0.11867117970139303" zaxis="1 0 0" />
          </body>
        </body>
      </body>
    </body>
  </worldbody>

  <sensor>
    <subtreelinvel body="torso" name="torso_subtreelinvel" />
  </sensor>

  <actuator>
    <motor gear="100" joint="right_hip" name="right_hip" />
    <motor gear="50" joint="right_knee" name="right_knee" />
    <motor gear="20" joint="right_ankle" name="right_ankle" />
    <motor gear="100" joint="left_hip" name="left_hip" />
    <motor gear="50" joint="left_knee" name="left_knee" />
    <motor gear="20" joint="left_ankle" name="left_ankle" />
  </actuator>
</mujoco>