<mujoco model="planar walker">
  <include file="./common/visual.xml" />
  <include file="./common/skybox.xml" />
  <include file="./common/materials.xml" />

  <option timestep="0.0025" />

  <statistic center="0 0 1" extent="2" />

  <default>
    <joint armature="0.01" damping=".1" limited="true" solimplimit="0 .99 .01" />
    <geom conaffinity="0" contype="1" friction=".7 .1 .1" />
    <motor ctrllimited="true" ctrlrange="-1 1" />
    <site size="0.01" />
    <default class="walker">
      <geom material="self" type="capsule" />
      <joint axis="0 -1 0" />
    </default>
  </default>

  <worldbody>
    <geom conaffinity="1" material="grid" name="floor" pos="248 0 0" size="250 .8 .2" type="plane" zaxis="-0.0923257391659672 0.0 0.9957288576150928" />
    <body childclass="walker" name="torso" pos="1.0407781636237985 0.0 -21.597637541636846">
      <light mode="trackcom" name="light" pos="0 0 2" />
      <camera euler="60 0 0" mode="trackcom" name="side" pos="0 -2 .7" />
      <camera mode="trackcom" name="back" pos="-2 0 .5" xyaxes="0 -1 0 1 0 3" />
      <joint armature="0" axis="0 0 1" damping="0.05750596270062504" limited="false" name="rootz" type="slide" />
      <joint armature="0" axis="1 0 0" damping="0.06689373371484654" limited="false" name="rootx" type="slide" />
      <joint armature="0" axis="0 1 0" damping="0.16253541704503585" limited="false" name="rooty" type="hinge" />
      <geom density="999.0705830440764" friction="0.6665670022841478 0.0646117822109031 0.10559486896746012" name="torso" size="0.07 0.3" />
      <body name="right_thigh" pos="0 -.05 -0.3">
        <joint damping="0.04608937397973064" name="right_hip" range="-20 100" />
        <geom density="1388.255151809878" friction="0.3473513990329053 0.15729092963129476 0.1890815131214723" name="right_thigh" pos="0 0 -0.225" size="0.05 0.225" />
        <body name="right_leg" pos="0 0 -0.7">
          <joint damping="0.10223474975193435" name="right_knee" pos="0 0 0.25" range="-150 0" />
          <geom density="2125.2433392295598" friction="0.4492541461761094 0.2125026651197333 0.10797050792300902" name="right_leg" size="0.04 0.25" />
          <body name="right_foot" pos="0.06 0 -0.25">
            <joint damping="0.19023429055960683" name="right_ankle" pos="-0.06 0 0" range="-45 45" />
            <geom density="1735.587895492199" friction="1.2023864218872293 0.16013002520009445 0.1832051890753268" name="right_foot" size="0.05 0.06454590607479123" zaxis="1 0 0" />
          </body>
        </body>
      </body>
      <body name="left_thigh" pos="0 .05 -0.3">
        <joint damping="0.05314118429483852" name="left_hip" range="-20 100" />
        <geom density="1860.782534692021" friction="0.5837187039164122 0.05942451113464895 0.054677619684306636" name="left_thigh" pos="0 0 -0.225" size="0.05 0.225" />
        <body name="left_leg" pos="0 0 -0.7">
          <joint damping="0.16422025406509913" name="left_knee" pos="0 0 0.25" range="-150 0" />
          <geom density="2079.9697740751126" friction="0.5879939848051131 0.17938475342769158 0.08294987217739348" name="left_leg" size="0.04 0.25" />
          <body name="left_foot" pos="0.06 0 -0.25">
            <joint damping="0.17201549547398687" name="left_ankle" pos="-0.06 0 0" range="-45 45" />
            <geom density="1377.1601721936493" friction="1.4954716526234908 0.17722066376582382 0.0856655994640373" name="left_foot" size="0.05 0.14858986891947373" zaxis="1 0 0" />
          </body>
        </body>
      </body>
    </body>
  </worldbody>

  <sensor>
    <subtreelinvel body="torso" name="torso_subtreelinvel" />
  </sensor>

  <actuator>
    <motor gear="100" joint="right_hip" name="right_hip" />
    <motor gear="50" joint="right_knee" name="right_knee" />
    <motor gear="20" joint="right_ankle" name="right_ankle" />
    <motor gear="100" joint="left_hip" name="left_hip" />
    <motor gear="50" joint="left_knee" name="left_knee" />
    <motor gear="20" joint="left_ankle" name="left_ankle" />
  </actuator>
</mujoco>