<mujoco model="planar walker">
  <include file="./common/visual.xml" />
  <include file="./common/skybox.xml" />
  <include file="./common/materials.xml" />

  <option timestep="0.0025" />

  <statistic center="0 0 1" extent="2" />

  <default>
    <joint armature="0.01" damping=".1" limited="true" solimplimit="0 .99 .01" />
    <geom conaffinity="0" contype="1" friction=".7 .1 .1" />
    <motor ctrllimited="true" ctrlrange="-1 1" />
    <site size="0.01" />
    <default class="walker">
      <geom material="self" type="capsule" />
      <joint axis="0 -1 0" />
    </default>
  </default>

  <worldbody>
    <geom conaffinity="1" material="grid" name="floor" pos="248 0 0" size="250 .8 .2" type="plane" zaxis="-0.07105467352758169 0.0 0.9974724223605828" />
    <body childclass="walker" name="torso" pos="0.6126283198699696 0.0 -16.32206455036814">
      <light mode="trackcom" name="light" pos="0 0 2" />
      <camera euler="60 0 0" mode="trackcom" name="side" pos="0 -2 .7" />
      <camera mode="trackcom" name="back" pos="-2 0 .5" xyaxes="0 -1 0 1 0 3" />
      <joint armature="0" axis="0 0 1" damping="0.1559634893975961" limited="false" name="rootz" type="slide" />
      <joint armature="0" axis="1 0 0" damping="0.14587934829867186" limited="false" name="rootx" type="slide" />
      <joint armature="0" axis="0 1 0" damping="0.06946021381967418" limited="false" name="rooty" type="hinge" />
      <geom density="1563.8410108465428" friction="0.9934076878066491 0.11840226240034842 0.058289244049111656" name="torso" size="0.07 0.3" />
      <body name="right_thigh" pos="0 -.05 -0.3">
        <joint damping="0.16748973918712837" name="right_hip" range="-20 100" />
        <geom density="757.5962853546374" friction="0.7346463718986469 0.17734676272496125 0.1155685757129247" name="right_thigh" pos="0 0 -0.225" size="0.05 0.225" />
        <body name="right_leg" pos="0 0 -0.7">
          <joint damping="0.06475583846193333" name="right_knee" pos="0 0 0.25" range="-150 0" />
          <geom density="1259.5668868654445" friction="1.4524986965746622 0.12864414290829637 0.07022644381288638" name="right_leg" size="0.04 0.25" />
          <body name="right_foot" pos="0.06 0 -0.25">
            <joint damping="0.09608705172226428" name="right_ankle" pos="-0.06 0 0" range="-45 45" />
            <geom density="538.586179316943" friction="0.5637875300059769 0.21954652517969964 0.07524126839665336" name="right_foot" size="0.05 0.06823304365829495" zaxis="1 0 0" />
          </body>
        </body>
      </body>
      <body name="left_thigh" pos="0 .05 -0.3">
        <joint damping="0.1601725371179748" name="left_hip" range="-20 100" />
        <geom density="618.9376683404123" friction="0.7040422805794541 0.2169458685451056 0.08160253480373002" name="left_thigh" pos="0 0 -0.225" size="0.05 0.225" />
        <body name="left_leg" pos="0 0 -0.7">
          <joint damping="0.046150883135014954" name="left_knee" pos="0 0 0.25" range="-150 0" />
          <geom density="964.8555111576492" friction="0.5180147780330427 0.11405821294587 0.051812303951170174" name="left_leg" size="0.04 0.25" />
          <body name="left_foot" pos="0.06 0 -0.25">
            <joint damping="0.09794631257452004" name="left_ankle" pos="-0.06 0 0" range="-45 45" />
            <geom density="1703.1643987235104" friction="0.7990891108681273 0.14963343803341567 0.1276119092328443" name="left_foot" size="0.05 0.04822173043100636" zaxis="1 0 0" />
          </body>
        </body>
      </body>
    </body>
  </worldbody>

  <sensor>
    <subtreelinvel body="torso" name="torso_subtreelinvel" />
  </sensor>

  <actuator>
    <motor gear="100" joint="right_hip" name="right_hip" />
    <motor gear="50" joint="right_knee" name="right_knee" />
    <motor gear="20" joint="right_ankle" name="right_ankle" />
    <motor gear="100" joint="left_hip" name="left_hip" />
    <motor gear="50" joint="left_knee" name="left_knee" />
    <motor gear="20" joint="left_ankle" name="left_ankle" />
  </actuator>
</mujoco>