<mujoco model="planar walker">
  <include file="./common/visual.xml" />
  <include file="./common/skybox.xml" />
  <include file="./common/materials.xml" />

  <option timestep="0.0025" />

  <statistic center="0 0 1" extent="2" />

  <default>
    <joint armature="0.01" damping=".1" limited="true" solimplimit="0 .99 .01" />
    <geom conaffinity="0" contype="1" friction=".7 .1 .1" />
    <motor ctrllimited="true" ctrlrange="-1 1" />
    <site size="0.01" />
    <default class="walker">
      <geom material="self" type="capsule" />
      <joint axis="0 -1 0" />
    </default>
  </default>

  <worldbody>
    <geom conaffinity="1" material="grid" name="floor" pos="248 0 0" size="250 .8 .2" type="plane" zaxis="0.1880828041885687 0.0 0.9821531747994121" />
    <body childclass="walker" name="torso" pos="4.463629210583491 0.0 47.94096607372492">
      <light mode="trackcom" name="light" pos="0 0 2" />
      <camera euler="60 0 0" mode="trackcom" name="side" pos="0 -2 .7" />
      <camera mode="trackcom" name="back" pos="-2 0 .5" xyaxes="0 -1 0 1 0 3" />
      <joint armature="0" axis="0 0 1" damping="0.05814460293097547" limited="false" name="rootz" type="slide" />
      <joint armature="0" axis="1 0 0" damping="0.12166313327269146" limited="false" name="rootx" type="slide" />
      <joint armature="0" axis="0 1 0" damping="0.1735047561887261" limited="false" name="rooty" type="hinge" />
      <geom density="1498.0658523036243" friction="0.4134381580570709 0.11122987042926061 0.06866355141841145" name="torso" size="0.07 0.3" />
      <body name="right_thigh" pos="0 -.05 -0.3">
        <joint damping="0.21467620171115798" name="right_hip" range="-20 100" />
        <geom density="1408.1995784904236" friction="0.5282474458096492 0.0584907370005634 0.12179931030903479" name="right_thigh" pos="0 0 -0.225" size="0.05 0.225" />
        <body name="right_leg" pos="0 0 -0.7">
          <joint damping="0.07345346044613514" name="right_knee" pos="0 0 0.25" range="-150 0" />
          <geom density="900.3961158442468" friction="0.49266106023326717 0.13612510202669925 0.04936537784248888" name="right_leg" size="0.04 0.25" />
          <body name="right_foot" pos="0.06 0 -0.25">
            <joint damping="0.18467651832658386" name="right_ankle" pos="-0.06 0 0" range="-45 45" />
            <geom density="918.6739161133786" friction="0.4004188219100123 0.19237001392422529 0.04662356523363604" name="right_foot" size="0.05 0.10115130427827423" zaxis="1 0 0" />
          </body>
        </body>
      </body>
      <body name="left_thigh" pos="0 .05 -0.3">
        <joint damping="0.04661707723352712" name="left_hip" range="-20 100" />
        <geom density="480.81782000936425" friction="0.603441910847046 0.05904865146467021 0.19566533186861412" name="left_thigh" pos="0 0 -0.225" size="0.05 0.225" />
        <body name="left_leg" pos="0 0 -0.7">
          <joint damping="0.059904746875639396" name="left_knee" pos="0 0 0.25" range="-150 0" />
          <geom density="510.99655544144895" friction="1.3573123188553753 0.05186094161980862 0.21089610943229903" name="left_leg" size="0.04 0.25" />
          <body name="left_foot" pos="0.06 0 -0.25">
            <joint damping="0.062454946559352346" name="left_ankle" pos="-0.06 0 0" range="-45 45" />
            <geom density="843.3963673718073" friction="0.49348944060536193 0.19398512089510486 0.11010164825121711" name="left_foot" size="0.05 0.05765845155962277" zaxis="1 0 0" />
          </body>
        </body>
      </body>
    </body>
  </worldbody>

  <sensor>
    <subtreelinvel body="torso" name="torso_subtreelinvel" />
  </sensor>

  <actuator>
    <motor gear="100" joint="right_hip" name="right_hip" />
    <motor gear="50" joint="right_knee" name="right_knee" />
    <motor gear="20" joint="right_ankle" name="right_ankle" />
    <motor gear="100" joint="left_hip" name="left_hip" />
    <motor gear="50" joint="left_knee" name="left_knee" />
    <motor gear="20" joint="left_ankle" name="left_ankle" />
  </actuator>
</mujoco>