<mujoco model="planar walker">
  <include file="./common/visual.xml" />
  <include file="./common/skybox.xml" />
  <include file="./common/materials.xml" />

  <option timestep="0.0025" />

  <statistic center="0 0 1" extent="2" />

  <default>
    <joint armature="0.01" damping=".1" limited="true" solimplimit="0 .99 .01" />
    <geom conaffinity="0" contype="1" friction=".7 .1 .1" />
    <motor ctrllimited="true" ctrlrange="-1 1" />
    <site size="0.01" />
    <default class="walker">
      <geom material="self" type="capsule" />
      <joint axis="0 -1 0" />
    </default>
  </default>

  <worldbody>
    <geom conaffinity="1" material="grid" name="floor" pos="248 0 0" size="250 .8 .2" type="plane" zaxis="0.11201478275329547 0.0 0.9937065404055324" />
    <body childclass="walker" name="torso" pos="1.5831809359786178 0.0 29.078407430898388">
      <light mode="trackcom" name="light" pos="0 0 2" />
      <camera euler="60 0 0" mode="trackcom" name="side" pos="0 -2 .7" />
      <camera mode="trackcom" name="back" pos="-2 0 .5" xyaxes="0 -1 0 1 0 3" />
      <joint armature="0" axis="0 0 1" damping="0.15771345964973005" limited="false" name="rootz" type="slide" />
      <joint armature="0" axis="1 0 0" damping="0.17775172943985806" limited="false" name="rootx" type="slide" />
      <joint armature="0" axis="0 1 0" damping="0.06513223179919655" limited="false" name="rooty" type="hinge" />
      <geom density="2195.2210417278698" friction="0.7344234115912187 0.06070194742043288 0.15106378696700887" name="torso" size="0.07 0.3" />
      <body name="right_thigh" pos="0 -.05 -0.3">
        <joint damping="0.07354384730270061" name="right_hip" range="-20 100" />
        <geom density="571.0164288511539" friction="0.35187261186595664 0.2172280824187746 0.12463369906851395" name="right_thigh" pos="0 0 -0.225" size="0.05 0.225" />
        <body name="right_leg" pos="0 0 -0.7">
          <joint damping="0.1051170447435848" name="right_knee" pos="0 0 0.25" range="-150 0" />
          <geom density="1257.0022077164588" friction="0.3570269143498392 0.11083558326127284 0.08071092429090368" name="right_leg" size="0.04 0.25" />
          <body name="right_foot" pos="0.06 0 -0.25">
            <joint damping="0.16125669703836557" name="right_ankle" pos="-0.06 0 0" range="-45 45" />
            <geom density="1275.074785785055" friction="1.5180954232613095 0.12251419254404135 0.059047851596489745" name="right_foot" size="0.05 0.04650683794774789" zaxis="1 0 0" />
          </body>
        </body>
      </body>
      <body name="left_thigh" pos="0 .05 -0.3">
        <joint damping="0.12065313583631516" name="left_hip" range="-20 100" />
        <geom density="632.3355887873905" friction="0.7883674496565486 0.18682725024720814 0.11377516979181335" name="left_thigh" pos="0 0 -0.225" size="0.05 0.225" />
        <body name="left_leg" pos="0 0 -0.7">
          <joint damping="0.20466756600941466" name="left_knee" pos="0 0 0.25" range="-150 0" />
          <geom density="553.382157967076" friction="0.6647051026915718 0.04719943814540707 0.15047871427567247" name="left_leg" size="0.04 0.25" />
          <body name="left_foot" pos="0.06 0 -0.25">
            <joint damping="0.06568512879897123" name="left_ankle" pos="-0.06 0 0" range="-45 45" />
            <geom density="1135.10546177907" friction="1.1243258563952125 0.07436509551228189 0.05188921354066361" name="left_foot" size="0.05 0.08210746393460953" zaxis="1 0 0" />
          </body>
        </body>
      </body>
    </body>
  </worldbody>

  <sensor>
    <subtreelinvel body="torso" name="torso_subtreelinvel" />
  </sensor>

  <actuator>
    <motor gear="100" joint="right_hip" name="right_hip" />
    <motor gear="50" joint="right_knee" name="right_knee" />
    <motor gear="20" joint="right_ankle" name="right_ankle" />
    <motor gear="100" joint="left_hip" name="left_hip" />
    <motor gear="50" joint="left_knee" name="left_knee" />
    <motor gear="20" joint="left_ankle" name="left_ankle" />
  </actuator>
</mujoco>