<mujoco model="planar walker">
  <include file="./common/visual.xml" />
  <include file="./common/skybox.xml" />
  <include file="./common/materials.xml" />

  <option timestep="0.0025" />

  <statistic center="0 0 1" extent="2" />

  <default>
    <joint armature="0.01" damping=".1" limited="true" solimplimit="0 .99 .01" />
    <geom conaffinity="0" contype="1" friction=".7 .1 .1" />
    <motor ctrllimited="true" ctrlrange="-1 1" />
    <site size="0.01" />
    <default class="walker">
      <geom material="self" type="capsule" />
      <joint axis="0 -1 0" />
    </default>
  </default>

  <worldbody>
    <geom conaffinity="1" material="grid" name="floor" pos="248 0 0" size="250 .8 .2" type="plane" zaxis="0.18352323304147747 0.0 0.9830153726844781" />
    <body childclass="walker" name="torso" pos="4.248892220857698 0.0 46.81036486882331">
      <light mode="trackcom" name="light" pos="0 0 2" />
      <camera euler="60 0 0" mode="trackcom" name="side" pos="0 -2 .7" />
      <camera mode="trackcom" name="back" pos="-2 0 .5" xyaxes="0 -1 0 1 0 3" />
      <joint armature="0" axis="0 0 1" damping="0.04770626677636101" limited="false" name="rootz" type="slide" />
      <joint armature="0" axis="1 0 0" damping="0.06047752527041714" limited="false" name="rootx" type="slide" />
      <joint armature="0" axis="0 1 0" damping="0.10563830456112577" limited="false" name="rooty" type="hinge" />
      <geom density="875.9433048605151" friction="0.4087667283593796 0.21314967776173166 0.07837873904031495" name="torso" size="0.07 0.3" />
      <body name="right_thigh" pos="0 -.05 -0.3">
        <joint damping="0.05534659683820389" name="right_hip" range="-20 100" />
        <geom density="628.0700486517445" friction="1.1688680373953513 0.10026020917442785 0.17289922875489097" name="right_thigh" pos="0 0 -0.225" size="0.05 0.225" />
        <body name="right_leg" pos="0 0 -0.7">
          <joint damping="0.14519121308927" name="right_knee" pos="0 0 0.25" range="-150 0" />
          <geom density="944.1629761515276" friction="0.654641521676747 0.07172776975135486 0.06396534332977538" name="right_leg" size="0.04 0.25" />
          <body name="right_foot" pos="0.06 0 -0.25">
            <joint damping="0.07685223234440833" name="right_ankle" pos="-0.06 0 0" range="-45 45" />
            <geom density="520.2945155397325" friction="0.9753986493465778 0.15722564109553389 0.09913528376261688" name="right_foot" size="0.05 0.13494074927113883" zaxis="1 0 0" />
          </body>
        </body>
      </body>
      <body name="left_thigh" pos="0 .05 -0.3">
        <joint damping="0.12949466722154057" name="left_hip" range="-20 100" />
        <geom density="952.2848221866607" friction="1.1703311798952836 0.045812350728933526 0.1374765105064821" name="left_thigh" pos="0 0 -0.225" size="0.05 0.225" />
        <body name="left_leg" pos="0 0 -0.7">
          <joint damping="0.1623992934167292" name="left_knee" pos="0 0 0.25" range="-150 0" />
          <geom density="752.5117966214701" friction="0.6852738594293616 0.06527095613203261 0.08499288449147895" name="left_leg" size="0.04 0.25" />
          <body name="left_foot" pos="0.06 0 -0.25">
            <joint damping="0.11742218829295868" name="left_ankle" pos="-0.06 0 0" range="-45 45" />
            <geom density="599.964727993339" friction="0.4464291000841838 0.09759512136239998 0.13025383138831487" name="left_foot" size="0.05 0.08034003245746739" zaxis="1 0 0" />
          </body>
        </body>
      </body>
    </body>
  </worldbody>

  <sensor>
    <subtreelinvel body="torso" name="torso_subtreelinvel" />
  </sensor>

  <actuator>
    <motor gear="100" joint="right_hip" name="right_hip" />
    <motor gear="50" joint="right_knee" name="right_knee" />
    <motor gear="20" joint="right_ankle" name="right_ankle" />
    <motor gear="100" joint="left_hip" name="left_hip" />
    <motor gear="50" joint="left_knee" name="left_knee" />
    <motor gear="20" joint="left_ankle" name="left_ankle" />
  </actuator>
</mujoco>