<mujoco model="planar walker">
  <include file="./common/visual.xml" />
  <include file="./common/skybox.xml" />
  <include file="./common/materials.xml" />

  <option timestep="0.0025" />

  <statistic center="0 0 1" extent="2" />

  <default>
    <joint armature="0.01" damping=".1" limited="true" solimplimit="0 .99 .01" />
    <geom conaffinity="0" contype="1" friction=".7 .1 .1" />
    <motor ctrllimited="true" ctrlrange="-1 1" />
    <site size="0.01" />
    <default class="walker">
      <geom material="self" type="capsule" />
      <joint axis="0 -1 0" />
    </default>
  </default>

  <worldbody>
    <geom conaffinity="1" material="grid" name="floor" pos="248 0 0" size="250 .8 .2" type="plane" zaxis="0.12436381604381462 0.0 0.9922366861082189" />
    <body childclass="walker" name="torso" pos="1.9501746083704745 0.0 32.14067371608767">
      <light mode="trackcom" name="light" pos="0 0 2" />
      <camera euler="60 0 0" mode="trackcom" name="side" pos="0 -2 .7" />
      <camera mode="trackcom" name="back" pos="-2 0 .5" xyaxes="0 -1 0 1 0 3" />
      <joint armature="0" axis="0 0 1" damping="0.07883006331829606" limited="false" name="rootz" type="slide" />
      <joint armature="0" axis="1 0 0" damping="0.0455209182216589" limited="false" name="rootx" type="slide" />
      <joint armature="0" axis="0 1 0" damping="0.06277974403264623" limited="false" name="rooty" type="hinge" />
      <geom density="812.177545718881" friction="1.113583846012087 0.1245445555900126 0.07479596404065146" name="torso" size="0.07 0.3" />
      <body name="right_thigh" pos="0 -.05 -0.3">
        <joint damping="0.11292232678950985" name="right_hip" range="-20 100" />
        <geom density="747.2353995358889" friction="0.5366463122871816 0.11889747613378479 0.05442463769453124" name="right_thigh" pos="0 0 -0.225" size="0.05 0.225" />
        <body name="right_leg" pos="0 0 -0.7">
          <joint damping="0.10845126463694049" name="right_knee" pos="0 0 0.25" range="-150 0" />
          <geom density="607.4611888190137" friction="0.388061891136481 0.09634668417766604 0.21223429774810204" name="right_leg" size="0.04 0.25" />
          <body name="right_foot" pos="0.06 0 -0.25">
            <joint damping="0.04894232579917648" name="right_ankle" pos="-0.06 0 0" range="-45 45" />
            <geom density="509.7365090923073" friction="0.9570824867143274 0.19084063711600513 0.047638384340112916" name="right_foot" size="0.05 0.21131970981946396" zaxis="1 0 0" />
          </body>
        </body>
      </body>
      <body name="left_thigh" pos="0 .05 -0.3">
        <joint damping="0.04617053047924577" name="left_hip" range="-20 100" />
        <geom density="1890.188518994153" friction="0.33483518937662077 0.07009176990400716 0.10036240883982664" name="left_thigh" pos="0 0 -0.225" size="0.05 0.225" />
        <body name="left_leg" pos="0 0 -0.7">
          <joint damping="0.06910504229941052" name="left_knee" pos="0 0 0.25" range="-150 0" />
          <geom density="533.0938222888666" friction="1.4164384777084313 0.1435284370454459 0.13429729405055618" name="left_leg" size="0.04 0.25" />
          <body name="left_foot" pos="0.06 0 -0.25">
            <joint damping="0.14644711380098704" name="left_ankle" pos="-0.06 0 0" range="-45 45" />
            <geom density="718.6310937262148" friction="0.5468193944725059 0.086817088781167 0.07987930054983233" name="left_foot" size="0.05 0.19993994348469044" zaxis="1 0 0" />
          </body>
        </body>
      </body>
    </body>
  </worldbody>

  <sensor>
    <subtreelinvel body="torso" name="torso_subtreelinvel" />
  </sensor>

  <actuator>
    <motor gear="100" joint="right_hip" name="right_hip" />
    <motor gear="50" joint="right_knee" name="right_knee" />
    <motor gear="20" joint="right_ankle" name="right_ankle" />
    <motor gear="100" joint="left_hip" name="left_hip" />
    <motor gear="50" joint="left_knee" name="left_knee" />
    <motor gear="20" joint="left_ankle" name="left_ankle" />
  </actuator>
</mujoco>