<mujoco model="planar walker">
  <include file="./common/visual.xml" />
  <include file="./common/skybox.xml" />
  <include file="./common/materials.xml" />

  <option timestep="0.0025" />

  <statistic center="0 0 1" extent="2" />

  <default>
    <joint armature="0.01" damping=".1" limited="true" solimplimit="0 .99 .01" />
    <geom conaffinity="0" contype="1" friction=".7 .1 .1" />
    <motor ctrllimited="true" ctrlrange="-1 1" />
    <site size="0.01" />
    <default class="walker">
      <geom material="self" type="capsule" />
      <joint axis="0 -1 0" />
    </default>
  </default>

  <worldbody>
    <geom conaffinity="1" material="grid" name="floor" pos="248 0 0" size="250 .8 .2" type="plane" zaxis="-0.1706005094328949 0.0 0.9853402793863837" />
    <body childclass="walker" name="torso" pos="3.601490610290284 0.0 -41.011858283480656">
      <light mode="trackcom" name="light" pos="0 0 2" />
      <camera euler="60 0 0" mode="trackcom" name="side" pos="0 -2 .7" />
      <camera mode="trackcom" name="back" pos="-2 0 .5" xyaxes="0 -1 0 1 0 3" />
      <joint armature="0" axis="0 0 1" damping="0.17146980241280588" limited="false" name="rootz" type="slide" />
      <joint armature="0" axis="1 0 0" damping="0.04585033666238519" limited="false" name="rootx" type="slide" />
      <joint armature="0" axis="0 1 0" damping="0.16636012016520402" limited="false" name="rooty" type="hinge" />
      <geom density="1186.2513091961375" friction="0.845550344041417 0.07935482243873597 0.15073537583376545" name="torso" size="0.07 0.3" />
      <body name="right_thigh" pos="0 -.05 -0.3">
        <joint damping="0.04856203445544099" name="right_hip" range="-20 100" />
        <geom density="2167.7001320067" friction="1.1739634476236978 0.13255854393896316 0.1476741091073348" name="right_thigh" pos="0 0 -0.225" size="0.05 0.225" />
        <body name="right_leg" pos="0 0 -0.7">
          <joint damping="0.14182843535079007" name="right_knee" pos="0 0 0.25" range="-150 0" />
          <geom density="1513.6681267887916" friction="0.8087724199061239 0.10600543049022737 0.09481171706397867" name="right_leg" size="0.04 0.25" />
          <body name="right_foot" pos="0.06 0 -0.25">
            <joint damping="0.06837765107938153" name="right_ankle" pos="-0.06 0 0" range="-45 45" />
            <geom density="1554.996826283521" friction="1.12786406731558 0.07952134698157509 0.046540868665683084" name="right_foot" size="0.05 0.07470002220456931" zaxis="1 0 0" />
          </body>
        </body>
      </body>
      <body name="left_thigh" pos="0 .05 -0.3">
        <joint damping="0.0847664459119053" name="left_hip" range="-20 100" />
        <geom density="550.2223823722464" friction="0.3505574990917489 0.057521915351432806 0.12830459250578247" name="left_thigh" pos="0 0 -0.225" size="0.05 0.225" />
        <body name="left_leg" pos="0 0 -0.7">
          <joint damping="0.064143113525882" name="left_knee" pos="0 0 0.25" range="-150 0" />
          <geom density="726.7783723497513" friction="0.6934512657301454 0.11628702482492076 0.13382099229038855" name="left_leg" size="0.04 0.25" />
          <body name="left_foot" pos="0.06 0 -0.25">
            <joint damping="0.08530721865700429" name="left_ankle" pos="-0.06 0 0" range="-45 45" />
            <geom density="1687.5795830151262" friction="0.47067901857267336 0.09551425492976155 0.1692504165968546" name="left_foot" size="0.05 0.09350475996420032" zaxis="1 0 0" />
          </body>
        </body>
      </body>
    </body>
  </worldbody>

  <sensor>
    <subtreelinvel body="torso" name="torso_subtreelinvel" />
  </sensor>

  <actuator>
    <motor gear="100" joint="right_hip" name="right_hip" />
    <motor gear="50" joint="right_knee" name="right_knee" />
    <motor gear="20" joint="right_ankle" name="right_ankle" />
    <motor gear="100" joint="left_hip" name="left_hip" />
    <motor gear="50" joint="left_knee" name="left_knee" />
    <motor gear="20" joint="left_ankle" name="left_ankle" />
  </actuator>
</mujoco>