<mujoco model="planar walker">
  <include file="./common/visual.xml" />
  <include file="./common/skybox.xml" />
  <include file="./common/materials.xml" />

  <option timestep="0.0025" />

  <statistic center="0 0 1" extent="2" />

  <default>
    <joint armature="0.01" damping=".1" limited="true" solimplimit="0 .99 .01" />
    <geom conaffinity="0" contype="1" friction=".7 .1 .1" />
    <motor ctrllimited="true" ctrlrange="-1 1" />
    <site size="0.01" />
    <default class="walker">
      <geom material="self" type="capsule" />
      <joint axis="0 -1 0" />
    </default>
  </default>

  <worldbody>
    <geom conaffinity="1" material="grid" name="floor" pos="248 0 0" size="250 .8 .2" type="plane" zaxis="-0.0980493407775384 0.0 0.9951815546788888" />
    <body childclass="walker" name="torso" pos="1.1753645714800882 0.0 -23.017200201893743">
      <light mode="trackcom" name="light" pos="0 0 2" />
      <camera euler="60 0 0" mode="trackcom" name="side" pos="0 -2 .7" />
      <camera mode="trackcom" name="back" pos="-2 0 .5" xyaxes="0 -1 0 1 0 3" />
      <joint armature="0" axis="0 0 1" damping="0.09426470958141193" limited="false" name="rootz" type="slide" />
      <joint armature="0" axis="1 0 0" damping="0.19187390505418003" limited="false" name="rootx" type="slide" />
      <joint armature="0" axis="0 1 0" damping="0.1168296521257211" limited="false" name="rooty" type="hinge" />
      <geom density="1353.1714388417158" friction="0.32751685039335293 0.13513522358283567 0.0669080437352002" name="torso" size="0.07 0.3" />
      <body name="right_thigh" pos="0 -.05 -0.3">
        <joint damping="0.05368977670431008" name="right_hip" range="-20 100" />
        <geom density="915.0878977200932" friction="0.3824838854767736 0.1038968442690682 0.2173778173425737" name="right_thigh" pos="0 0 -0.225" size="0.05 0.225" />
        <body name="right_leg" pos="0 0 -0.7">
          <joint damping="0.12916117866729476" name="right_knee" pos="0 0 0.25" range="-150 0" />
          <geom density="522.5721310210675" friction="1.1803648453144695 0.09403425181305336 0.06892150534162532" name="right_leg" size="0.04 0.25" />
          <body name="right_foot" pos="0.06 0 -0.25">
            <joint damping="0.0472764080529893" name="right_ankle" pos="-0.06 0 0" range="-45 45" />
            <geom density="2196.0823310062074" friction="0.35844659028613957 0.07218842767488548 0.04929762121817849" name="right_foot" size="0.05 0.2130069902822673" zaxis="1 0 0" />
          </body>
        </body>
      </body>
      <body name="left_thigh" pos="0 .05 -0.3">
        <joint damping="0.21338232611277186" name="left_hip" range="-20 100" />
        <geom density="662.7444221435443" friction="1.1845330913255834 0.18521679407670855 0.05234407270346363" name="left_thigh" pos="0 0 -0.225" size="0.05 0.225" />
        <body name="left_leg" pos="0 0 -0.7">
          <joint damping="0.05040139100461932" name="left_knee" pos="0 0 0.25" range="-150 0" />
          <geom density="946.6268387949624" friction="1.2745125109122786 0.06766643414526657 0.12642575532314923" name="left_leg" size="0.04 0.25" />
          <body name="left_foot" pos="0.06 0 -0.25">
            <joint damping="0.06587883079678354" name="left_ankle" pos="-0.06 0 0" range="-45 45" />
            <geom density="1254.2215744258074" friction="0.4630973760245501 0.0992997141397095 0.14727708880054402" name="left_foot" size="0.05 0.04647031016471996" zaxis="1 0 0" />
          </body>
        </body>
      </body>
    </body>
  </worldbody>

  <sensor>
    <subtreelinvel body="torso" name="torso_subtreelinvel" />
  </sensor>

  <actuator>
    <motor gear="100" joint="right_hip" name="right_hip" />
    <motor gear="50" joint="right_knee" name="right_knee" />
    <motor gear="20" joint="right_ankle" name="right_ankle" />
    <motor gear="100" joint="left_hip" name="left_hip" />
    <motor gear="50" joint="left_knee" name="left_knee" />
    <motor gear="20" joint="left_ankle" name="left_ankle" />
  </actuator>
</mujoco>