<mujoco model="planar walker">
  <include file="./common/visual.xml" />
  <include file="./common/skybox.xml" />
  <include file="./common/materials.xml" />

  <option timestep="0.0025" />

  <statistic center="0 0 1" extent="2" />

  <default>
    <joint armature="0.01" damping=".1" limited="true" solimplimit="0 .99 .01" />
    <geom conaffinity="0" contype="1" friction=".7 .1 .1" />
    <motor ctrllimited="true" ctrlrange="-1 1" />
    <site size="0.01" />
    <default class="walker">
      <geom material="self" type="capsule" />
      <joint axis="0 -1 0" />
    </default>
  </default>

  <worldbody>
    <geom conaffinity="1" material="grid" name="floor" pos="248 0 0" size="250 .8 .2" type="plane" zaxis="0.030666570235733794 0.0 0.999529670129895" />
    <body childclass="walker" name="torso" pos="0.12277512183317185 0.0 8.905215352487959">
      <light mode="trackcom" name="light" pos="0 0 2" />
      <camera euler="60 0 0" mode="trackcom" name="side" pos="0 -2 .7" />
      <camera mode="trackcom" name="back" pos="-2 0 .5" xyaxes="0 -1 0 1 0 3" />
      <joint armature="0" axis="0 0 1" damping="0.08263373797600299" limited="false" name="rootz" type="slide" />
      <joint armature="0" axis="1 0 0" damping="0.19643488599590384" limited="false" name="rootx" type="slide" />
      <joint armature="0" axis="0 1 0" damping="0.052988535254441006" limited="false" name="rooty" type="hinge" />
      <geom density="767.6956997137348" friction="1.4845739888078324 0.19179373082874374 0.13761734374756" name="torso" size="0.07 0.3" />
      <body name="right_thigh" pos="0 -.05 -0.3">
        <joint damping="0.12715032380389488" name="right_hip" range="-20 100" />
        <geom density="715.4066874627631" friction="1.158875206158783 0.188677883911521 0.08473956317698472" name="right_thigh" pos="0 0 -0.225" size="0.05 0.225" />
        <body name="right_leg" pos="0 0 -0.7">
          <joint damping="0.16991670238980414" name="right_knee" pos="0 0 0.25" range="-150 0" />
          <geom density="1470.048899408073" friction="0.5906945368587335 0.062062739539030215 0.05210933566417734" name="right_leg" size="0.04 0.25" />
          <body name="right_foot" pos="0.06 0 -0.25">
            <joint damping="0.19972837126831755" name="right_ankle" pos="-0.06 0 0" range="-45 45" />
            <geom density="782.7538032850256" friction="1.3970685280323263 0.048936450452550004 0.12355483233591216" name="right_foot" size="0.05 0.11419283319957617" zaxis="1 0 0" />
          </body>
        </body>
      </body>
      <body name="left_thigh" pos="0 .05 -0.3">
        <joint damping="0.09246740502886439" name="left_hip" range="-20 100" />
        <geom density="1592.5186949718397" friction="0.8998881449310314 0.152460818896562 0.05508874501355807" name="left_thigh" pos="0 0 -0.225" size="0.05 0.225" />
        <body name="left_leg" pos="0 0 -0.7">
          <joint damping="0.07191882772565521" name="left_knee" pos="0 0 0.25" range="-150 0" />
          <geom density="720.4412729444642" friction="0.630573905057896 0.053957307350552534 0.11829693264786134" name="left_leg" size="0.04 0.25" />
          <body name="left_foot" pos="0.06 0 -0.25">
            <joint damping="0.11022050738380396" name="left_ankle" pos="-0.06 0 0" range="-45 45" />
            <geom density="1004.9423709964391" friction="0.6492701079741631 0.09587497550935829 0.12541412434325303" name="left_foot" size="0.05 0.09857578093718629" zaxis="1 0 0" />
          </body>
        </body>
      </body>
    </body>
  </worldbody>

  <sensor>
    <subtreelinvel body="torso" name="torso_subtreelinvel" />
  </sensor>

  <actuator>
    <motor gear="100" joint="right_hip" name="right_hip" />
    <motor gear="50" joint="right_knee" name="right_knee" />
    <motor gear="20" joint="right_ankle" name="right_ankle" />
    <motor gear="100" joint="left_hip" name="left_hip" />
    <motor gear="50" joint="left_knee" name="left_knee" />
    <motor gear="20" joint="left_ankle" name="left_ankle" />
  </actuator>
</mujoco>