<mujoco model="planar walker">
  <include file="./common/visual.xml" />
  <include file="./common/skybox.xml" />
  <include file="./common/materials.xml" />

  <option timestep="0.0025" />

  <statistic center="0 0 1" extent="2" />

  <default>
    <joint armature="0.01" damping=".1" limited="true" solimplimit="0 .99 .01" />
    <geom conaffinity="0" contype="1" friction=".7 .1 .1" />
    <motor ctrllimited="true" ctrlrange="-1 1" />
    <site size="0.01" />
    <default class="walker">
      <geom material="self" type="capsule" />
      <joint axis="0 -1 0" />
    </default>
  </default>

  <worldbody>
    <geom conaffinity="1" material="grid" name="floor" pos="248 0 0" size="250 .8 .2" type="plane" zaxis="-0.06208050130257508 0.0 0.9980711454390518" />
    <body childclass="walker" name="torso" pos="0.4659398308546372 0.0 -14.096350093950809">
      <light mode="trackcom" name="light" pos="0 0 2" />
      <camera euler="60 0 0" mode="trackcom" name="side" pos="0 -2 .7" />
      <camera mode="trackcom" name="back" pos="-2 0 .5" xyaxes="0 -1 0 1 0 3" />
      <joint armature="0" axis="0 0 1" damping="0.13196385589501544" limited="false" name="rootz" type="slide" />
      <joint armature="0" axis="1 0 0" damping="0.15763876703552296" limited="false" name="rootx" type="slide" />
      <joint armature="0" axis="0 1 0" damping="0.08289032791875918" limited="false" name="rooty" type="hinge" />
      <geom density="875.2989344562715" friction="0.8250686891381159 0.12113794538834494 0.17914009198310907" name="torso" size="0.07 0.3" />
      <body name="right_thigh" pos="0 -.05 -0.3">
        <joint damping="0.12230158241399583" name="right_hip" range="-20 100" />
        <geom density="460.92516572855845" friction="0.5519605464342048 0.13724759625718885 0.10412713498378792" name="right_thigh" pos="0 0 -0.225" size="0.05 0.225" />
        <body name="right_leg" pos="0 0 -0.7">
          <joint damping="0.1692718147188809" name="right_knee" pos="0 0 0.25" range="-150 0" />
          <geom density="1128.6058456006515" friction="0.6056619928400548 0.10005176698817926 0.06031143534628802" name="right_leg" size="0.04 0.25" />
          <body name="right_foot" pos="0.06 0 -0.25">
            <joint damping="0.14844258690190792" name="right_ankle" pos="-0.06 0 0" range="-45 45" />
            <geom density="753.7858969707916" friction="1.0184151258842364 0.14185697773916073 0.05363573287239831" name="right_foot" size="0.05 0.14836497531975465" zaxis="1 0 0" />
          </body>
        </body>
      </body>
      <body name="left_thigh" pos="0 .05 -0.3">
        <joint damping="0.0456506696066886" name="left_hip" range="-20 100" />
        <geom density="1812.7663080308291" friction="0.5593862159653874 0.1019709180034309 0.11252820741400969" name="left_thigh" pos="0 0 -0.225" size="0.05 0.225" />
        <body name="left_leg" pos="0 0 -0.7">
          <joint damping="0.08857621518170505" name="left_knee" pos="0 0 0.25" range="-150 0" />
          <geom density="520.6822500295831" friction="0.32241772960822435 0.15713053666564383 0.06300918404085758" name="left_leg" size="0.04 0.25" />
          <body name="left_foot" pos="0.06 0 -0.25">
            <joint damping="0.07770992449750541" name="left_ankle" pos="-0.06 0 0" range="-45 45" />
            <geom density="634.8101477122818" friction="0.8926381039299923 0.20288613759843313 0.07891234723348411" name="left_foot" size="0.05 0.05996185332336049" zaxis="1 0 0" />
          </body>
        </body>
      </body>
    </body>
  </worldbody>

  <sensor>
    <subtreelinvel body="torso" name="torso_subtreelinvel" />
  </sensor>

  <actuator>
    <motor gear="100" joint="right_hip" name="right_hip" />
    <motor gear="50" joint="right_knee" name="right_knee" />
    <motor gear="20" joint="right_ankle" name="right_ankle" />
    <motor gear="100" joint="left_hip" name="left_hip" />
    <motor gear="50" joint="left_knee" name="left_knee" />
    <motor gear="20" joint="left_ankle" name="left_ankle" />
  </actuator>
</mujoco>