<mujoco model="planar walker">
  <include file="./common/visual.xml" />
  <include file="./common/skybox.xml" />
  <include file="./common/materials.xml" />

  <option timestep="0.0025" />

  <statistic center="0 0 1" extent="2" />

  <default>
    <joint armature="0.01" damping=".1" limited="true" solimplimit="0 .99 .01" />
    <geom conaffinity="0" contype="1" friction=".7 .1 .1" />
    <motor ctrllimited="true" ctrlrange="-1 1" />
    <site size="0.01" />
    <default class="walker">
      <geom material="self" type="capsule" />
      <joint axis="0 -1 0" />
    </default>
  </default>

  <worldbody>
    <geom conaffinity="1" material="grid" name="floor" pos="248 0 0" size="250 .8 .2" type="plane" zaxis="0.12149425577877696 0.0 0.9925921346720218" />
    <body childclass="walker" name="torso" pos="1.8614494524943552 0.0 31.42909386007109">
      <light mode="trackcom" name="light" pos="0 0 2" />
      <camera euler="60 0 0" mode="trackcom" name="side" pos="0 -2 .7" />
      <camera mode="trackcom" name="back" pos="-2 0 .5" xyaxes="0 -1 0 1 0 3" />
      <joint armature="0" axis="0 0 1" damping="0.1655357800068097" limited="false" name="rootz" type="slide" />
      <joint armature="0" axis="1 0 0" damping="0.09612910926189172" limited="false" name="rootx" type="slide" />
      <joint armature="0" axis="0 1 0" damping="0.07343090143891766" limited="false" name="rooty" type="hinge" />
      <geom density="660.6419732473929" friction="0.4056415166058991 0.07694050517689396 0.0711753457989515" name="torso" size="0.07 0.3" />
      <body name="right_thigh" pos="0 -.05 -0.3">
        <joint damping="0.07862657891386027" name="right_hip" range="-20 100" />
        <geom density="649.9782774457996" friction="0.9810390051797448 0.07766662351948038 0.05362675628332684" name="right_thigh" pos="0 0 -0.225" size="0.05 0.225" />
        <body name="right_leg" pos="0 0 -0.7">
          <joint damping="0.15596261265780886" name="right_knee" pos="0 0 0.25" range="-150 0" />
          <geom density="820.3196799539766" friction="0.806209771689093 0.08077956657434936 0.10318871910431049" name="right_leg" size="0.04 0.25" />
          <body name="right_foot" pos="0.06 0 -0.25">
            <joint damping="0.11592643403868104" name="right_ankle" pos="-0.06 0 0" range="-45 45" />
            <geom density="2089.7225416184892" friction="0.5712399083563591 0.09487645022248284 0.05740745473170853" name="right_foot" size="0.05 0.052286877400455484" zaxis="1 0 0" />
          </body>
        </body>
      </body>
      <body name="left_thigh" pos="0 .05 -0.3">
        <joint damping="0.05491072487959797" name="left_hip" range="-20 100" />
        <geom density="735.5467083169322" friction="0.5100158251512144 0.14676542661018321 0.06457393277904865" name="left_thigh" pos="0 0 -0.225" size="0.05 0.225" />
        <body name="left_leg" pos="0 0 -0.7">
          <joint damping="0.1782472119449411" name="left_knee" pos="0 0 0.25" range="-150 0" />
          <geom density="1957.153935809934" friction="0.43629755007349763 0.09819530965983066 0.054972352755391835" name="left_leg" size="0.04 0.25" />
          <body name="left_foot" pos="0.06 0 -0.25">
            <joint damping="0.06278549606364556" name="left_ankle" pos="-0.06 0 0" range="-45 45" />
            <geom density="851.9171183120362" friction="0.4876736129697348 0.04709881828272599 0.047999095071229333" name="left_foot" size="0.05 0.05412961829949691" zaxis="1 0 0" />
          </body>
        </body>
      </body>
    </body>
  </worldbody>

  <sensor>
    <subtreelinvel body="torso" name="torso_subtreelinvel" />
  </sensor>

  <actuator>
    <motor gear="100" joint="right_hip" name="right_hip" />
    <motor gear="50" joint="right_knee" name="right_knee" />
    <motor gear="20" joint="right_ankle" name="right_ankle" />
    <motor gear="100" joint="left_hip" name="left_hip" />
    <motor gear="50" joint="left_knee" name="left_knee" />
    <motor gear="20" joint="left_ankle" name="left_ankle" />
  </actuator>
</mujoco>