<mujoco model="planar walker">
  <include file="./common/visual.xml" />
  <include file="./common/skybox.xml" />
  <include file="./common/materials.xml" />

  <option timestep="0.0025" />

  <statistic center="0 0 1" extent="2" />

  <default>
    <joint armature="0.01" damping=".1" limited="true" solimplimit="0 .99 .01" />
    <geom conaffinity="0" contype="1" friction=".7 .1 .1" />
    <motor ctrllimited="true" ctrlrange="-1 1" />
    <site size="0.01" />
    <default class="walker">
      <geom material="self" type="capsule" />
      <joint axis="0 -1 0" />
    </default>
  </default>

  <worldbody>
    <geom conaffinity="1" material="grid" name="floor" pos="248 0 0" size="250 .8 .2" type="plane" zaxis="-0.033217591139568466 0.0 0.9994481435466697" />
    <body childclass="walker" name="torso" pos="0.13021688219799898 0.0 -6.938072973903646">
      <light mode="trackcom" name="light" pos="0 0 2" />
      <camera euler="60 0 0" mode="trackcom" name="side" pos="0 -2 .7" />
      <camera mode="trackcom" name="back" pos="-2 0 .5" xyaxes="0 -1 0 1 0 3" />
      <joint armature="0" axis="0 0 1" damping="0.05525641564367665" limited="false" name="rootz" type="slide" />
      <joint armature="0" axis="1 0 0" damping="0.16446700794488195" limited="false" name="rootx" type="slide" />
      <joint armature="0" axis="0 1 0" damping="0.09703093145877689" limited="false" name="rooty" type="hinge" />
      <geom density="907.7564047961821" friction="0.8219871543825388 0.05140382609763046 0.11711726948321276" name="torso" size="0.07 0.3" />
      <body name="right_thigh" pos="0 -.05 -0.3">
        <joint damping="0.16407020778309422" name="right_hip" range="-20 100" />
        <geom density="658.4243006601104" friction="0.33488116712483984 0.058167074127115026 0.10288862062140301" name="right_thigh" pos="0 0 -0.225" size="0.05 0.225" />
        <body name="right_leg" pos="0 0 -0.7">
          <joint damping="0.13260351657907424" name="right_knee" pos="0 0 0.25" range="-150 0" />
          <geom density="950.0141765909752" friction="0.6388823220975438 0.1636285795629759 0.1713140047796129" name="right_leg" size="0.04 0.25" />
          <body name="right_foot" pos="0.06 0 -0.25">
            <joint damping="0.09649776584419285" name="right_ankle" pos="-0.06 0 0" range="-45 45" />
            <geom density="776.5433850573992" friction="1.1109195109250745 0.12437122818828981 0.11845763187762644" name="right_foot" size="0.05 0.09250887013956668" zaxis="1 0 0" />
          </body>
        </body>
      </body>
      <body name="left_thigh" pos="0 .05 -0.3">
        <joint damping="0.19527766553219594" name="left_hip" range="-20 100" />
        <geom density="591.7241817586449" friction="0.7559522740162752 0.11002933919136647 0.1028963892674961" name="left_thigh" pos="0 0 -0.225" size="0.05 0.225" />
        <body name="left_leg" pos="0 0 -0.7">
          <joint damping="0.04850857087841147" name="left_knee" pos="0 0 0.25" range="-150 0" />
          <geom density="709.2116379918575" friction="0.60937787705289 0.11034368852535213 0.18629127278812768" name="left_leg" size="0.04 0.25" />
          <body name="left_foot" pos="0.06 0 -0.25">
            <joint damping="0.1702769318902524" name="left_ankle" pos="-0.06 0 0" range="-45 45" />
            <geom density="889.2225875657149" friction="1.0669532509212438 0.10525805047693133 0.0709657092972598" name="left_foot" size="0.05 0.20939436567559017" zaxis="1 0 0" />
          </body>
        </body>
      </body>
    </body>
  </worldbody>

  <sensor>
    <subtreelinvel body="torso" name="torso_subtreelinvel" />
  </sensor>

  <actuator>
    <motor gear="100" joint="right_hip" name="right_hip" />
    <motor gear="50" joint="right_knee" name="right_knee" />
    <motor gear="20" joint="right_ankle" name="right_ankle" />
    <motor gear="100" joint="left_hip" name="left_hip" />
    <motor gear="50" joint="left_knee" name="left_knee" />
    <motor gear="20" joint="left_ankle" name="left_ankle" />
  </actuator>
</mujoco>