<mujoco model="planar walker">
  <include file="./common/visual.xml" />
  <include file="./common/skybox.xml" />
  <include file="./common/materials.xml" />

  <option timestep="0.0025" />

  <statistic center="0 0 1" extent="2" />

  <default>
    <joint armature="0.01" damping=".1" limited="true" solimplimit="0 .99 .01" />
    <geom conaffinity="0" contype="1" friction=".7 .1 .1" />
    <motor ctrllimited="true" ctrlrange="-1 1" />
    <site size="0.01" />
    <default class="walker">
      <geom material="self" type="capsule" />
      <joint axis="0 -1 0" />
    </default>
  </default>

  <worldbody>
    <geom conaffinity="1" material="grid" name="floor" pos="248 0 0" size="250 .8 .2" type="plane" zaxis="0.03960172193565886 0.0 0.999215544124355" />
    <body childclass="walker" name="torso" pos="0.20246540154710146 0.0 11.121070148868268">
      <light mode="trackcom" name="light" pos="0 0 2" />
      <camera euler="60 0 0" mode="trackcom" name="side" pos="0 -2 .7" />
      <camera mode="trackcom" name="back" pos="-2 0 .5" xyaxes="0 -1 0 1 0 3" />
      <joint armature="0" axis="0 0 1" damping="0.08054443093005685" limited="false" name="rootz" type="slide" />
      <joint armature="0" axis="1 0 0" damping="0.07200271859633581" limited="false" name="rootx" type="slide" />
      <joint armature="0" axis="0 1 0" damping="0.21628408939962723" limited="false" name="rooty" type="hinge" />
      <geom density="2125.7859436874246" friction="0.40333295587415835 0.14666754696611933 0.07156396996167051" name="torso" size="0.07 0.3" />
      <body name="right_thigh" pos="0 -.05 -0.3">
        <joint damping="0.05583459890503828" name="right_hip" range="-20 100" />
        <geom density="2062.4665979870615" friction="1.4094417911394799 0.05077306388270322 0.19743504846019905" name="right_thigh" pos="0 0 -0.225" size="0.05 0.225" />
        <body name="right_leg" pos="0 0 -0.7">
          <joint damping="0.1489288828809429" name="right_knee" pos="0 0 0.25" range="-150 0" />
          <geom density="1280.140525843171" friction="0.7253808555054775 0.07632562346371584 0.10439721552263859" name="right_leg" size="0.04 0.25" />
          <body name="right_foot" pos="0.06 0 -0.25">
            <joint damping="0.1201911109109392" name="right_ankle" pos="-0.06 0 0" range="-45 45" />
            <geom density="570.1687029181746" friction="1.2441861403919383 0.13332308753829344 0.20974658187448605" name="right_foot" size="0.05 0.049402822229084264" zaxis="1 0 0" />
          </body>
        </body>
      </body>
      <body name="left_thigh" pos="0 .05 -0.3">
        <joint damping="0.1314581787637441" name="left_hip" range="-20 100" />
        <geom density="1157.9545798551212" friction="1.0907824556968304 0.07877238157718637 0.07791826416131967" name="left_thigh" pos="0 0 -0.225" size="0.05 0.225" />
        <body name="left_leg" pos="0 0 -0.7">
          <joint damping="0.07194521665873885" name="left_knee" pos="0 0 0.25" range="-150 0" />
          <geom density="787.1913129235011" friction="1.3059575119838722 0.14053733502081436 0.08560619203317417" name="left_leg" size="0.04 0.25" />
          <body name="left_foot" pos="0.06 0 -0.25">
            <joint damping="0.052234705338768665" name="left_ankle" pos="-0.06 0 0" range="-45 45" />
            <geom density="2043.765064863619" friction="0.39290666468881263 0.08454848858505565 0.0836242391700649" name="left_foot" size="0.05 0.13859362576049256" zaxis="1 0 0" />
          </body>
        </body>
      </body>
    </body>
  </worldbody>

  <sensor>
    <subtreelinvel body="torso" name="torso_subtreelinvel" />
  </sensor>

  <actuator>
    <motor gear="100" joint="right_hip" name="right_hip" />
    <motor gear="50" joint="right_knee" name="right_knee" />
    <motor gear="20" joint="right_ankle" name="right_ankle" />
    <motor gear="100" joint="left_hip" name="left_hip" />
    <motor gear="50" joint="left_knee" name="left_knee" />
    <motor gear="20" joint="left_ankle" name="left_ankle" />
  </actuator>
</mujoco>