<mujoco model="planar walker">
  <include file="./common/visual.xml" />
  <include file="./common/skybox.xml" />
  <include file="./common/materials.xml" />

  <option timestep="0.0025" />

  <statistic center="0 0 1" extent="2" />

  <default>
    <joint armature="0.01" damping=".1" limited="true" solimplimit="0 .99 .01" />
    <geom conaffinity="0" contype="1" friction=".7 .1 .1" />
    <motor ctrllimited="true" ctrlrange="-1 1" />
    <site size="0.01" />
    <default class="walker">
      <geom material="self" type="capsule" />
      <joint axis="0 -1 0" />
    </default>
  </default>

  <worldbody>
    <geom conaffinity="1" material="grid" name="floor" pos="248 0 0" size="250 .8 .2" type="plane" zaxis="-0.13348545026915495 0.0 0.9910507729508317" />
    <body childclass="walker" name="torso" pos="2.1927112181399195 0.0 -31.806181512160265">
      <light mode="trackcom" name="light" pos="0 0 2" />
      <camera euler="60 0 0" mode="trackcom" name="side" pos="0 -2 .7" />
      <camera mode="trackcom" name="back" pos="-2 0 .5" xyaxes="0 -1 0 1 0 3" />
      <joint armature="0" axis="0 0 1" damping="0.18737999888820256" limited="false" name="rootz" type="slide" />
      <joint armature="0" axis="1 0 0" damping="0.13383165509519018" limited="false" name="rootx" type="slide" />
      <joint armature="0" axis="0 1 0" damping="0.14017125482764456" limited="false" name="rooty" type="hinge" />
      <geom density="1307.5374988094652" friction="1.0823882682099266 0.0760888187747632 0.08578634514458501" name="torso" size="0.07 0.3" />
      <body name="right_thigh" pos="0 -.05 -0.3">
        <joint damping="0.18387510998286138" name="right_hip" range="-20 100" />
        <geom density="1767.589382126205" friction="1.5296391328869934 0.04939189096601662 0.19349055131138307" name="right_thigh" pos="0 0 -0.225" size="0.05 0.225" />
        <body name="right_leg" pos="0 0 -0.7">
          <joint damping="0.07513359959717536" name="right_knee" pos="0 0 0.25" range="-150 0" />
          <geom density="1301.8717550848216" friction="0.36534147779360654 0.11195009276443645 0.07031632537756415" name="right_leg" size="0.04 0.25" />
          <body name="right_foot" pos="0.06 0 -0.25">
            <joint damping="0.05917201264800237" name="right_ankle" pos="-0.06 0 0" range="-45 45" />
            <geom density="590.7336857348547" friction="0.40266752225707975 0.18370145748756975 0.2096146328834495" name="right_foot" size="0.05 0.1124146406618586" zaxis="1 0 0" />
          </body>
        </body>
      </body>
      <body name="left_thigh" pos="0 .05 -0.3">
        <joint damping="0.15310603038913362" name="left_hip" range="-20 100" />
        <geom density="664.4714423594725" friction="0.8441537619967174 0.11751364904885586 0.11235938181643752" name="left_thigh" pos="0 0 -0.225" size="0.05 0.225" />
        <body name="left_leg" pos="0 0 -0.7">
          <joint damping="0.08101827361913067" name="left_knee" pos="0 0 0.25" range="-150 0" />
          <geom density="892.5368682278968" friction="1.4988303006395658 0.13108182196810012 0.1651769728577016" name="left_leg" size="0.04 0.25" />
          <body name="left_foot" pos="0.06 0 -0.25">
            <joint damping="0.10491325382801334" name="left_ankle" pos="-0.06 0 0" range="-45 45" />
            <geom density="670.1178351046703" friction="0.5103137242369871 0.054130949957881196 0.11945145078863924" name="left_foot" size="0.05 0.09509057162211482" zaxis="1 0 0" />
          </body>
        </body>
      </body>
    </body>
  </worldbody>

  <sensor>
    <subtreelinvel body="torso" name="torso_subtreelinvel" />
  </sensor>

  <actuator>
    <motor gear="100" joint="right_hip" name="right_hip" />
    <motor gear="50" joint="right_knee" name="right_knee" />
    <motor gear="20" joint="right_ankle" name="right_ankle" />
    <motor gear="100" joint="left_hip" name="left_hip" />
    <motor gear="50" joint="left_knee" name="left_knee" />
    <motor gear="20" joint="left_ankle" name="left_ankle" />
  </actuator>
</mujoco>