<mujoco model="planar walker">
  <include file="./common/visual.xml" />
  <include file="./common/skybox.xml" />
  <include file="./common/materials.xml" />

  <option timestep="0.0025" />

  <statistic center="0 0 1" extent="2" />

  <default>
    <joint armature="0.01" damping=".1" limited="true" solimplimit="0 .99 .01" />
    <geom conaffinity="0" contype="1" friction=".7 .1 .1" />
    <motor ctrllimited="true" ctrlrange="-1 1" />
    <site size="0.01" />
    <default class="walker">
      <geom material="self" type="capsule" />
      <joint axis="0 -1 0" />
    </default>
  </default>

  <worldbody>
    <geom conaffinity="1" material="grid" name="floor" pos="248 0 0" size="250 .8 .2" type="plane" zaxis="0.03685492843388736 0.0 0.9993206263507889" />
    <body childclass="walker" name="torso" pos="0.17585565069111908 0.0 10.439886376874224">
      <light mode="trackcom" name="light" pos="0 0 2" />
      <camera euler="60 0 0" mode="trackcom" name="side" pos="0 -2 .7" />
      <camera mode="trackcom" name="back" pos="-2 0 .5" xyaxes="0 -1 0 1 0 3" />
      <joint armature="0" axis="0 0 1" damping="0.15944476112549674" limited="false" name="rootz" type="slide" />
      <joint armature="0" axis="1 0 0" damping="0.1877562455819018" limited="false" name="rootx" type="slide" />
      <joint armature="0" axis="0 1 0" damping="0.10562561730726945" limited="false" name="rooty" type="hinge" />
      <geom density="521.8794304706964" friction="0.886927391650647 0.05705801463702932 0.2095185395284931" name="torso" size="0.07 0.3" />
      <body name="right_thigh" pos="0 -.05 -0.3">
        <joint damping="0.10876144016055854" name="right_hip" range="-20 100" />
        <geom density="1005.3167828970022" friction="0.5367818668801315 0.08145020680195875 0.18562644406585016" name="right_thigh" pos="0 0 -0.225" size="0.05 0.225" />
        <body name="right_leg" pos="0 0 -0.7">
          <joint damping="0.08028084825108778" name="right_knee" pos="0 0 0.25" range="-150 0" />
          <geom density="1404.9244917450367" friction="1.009994994317949 0.060577125165379886 0.07749428910677479" name="right_leg" size="0.04 0.25" />
          <body name="right_foot" pos="0.06 0 -0.25">
            <joint damping="0.062045946891175686" name="right_ankle" pos="-0.06 0 0" range="-45 45" />
            <geom density="1413.7502510593952" friction="0.9194334476976389 0.12542025846758662 0.09498624994618747" name="right_foot" size="0.05 0.10361201023768665" zaxis="1 0 0" />
          </body>
        </body>
      </body>
      <body name="left_thigh" pos="0 .05 -0.3">
        <joint damping="0.13286666053029791" name="left_hip" range="-20 100" />
        <geom density="473.75707203483483" friction="1.1833710158452337 0.05817209168993806 0.09431270043929545" name="left_thigh" pos="0 0 -0.225" size="0.05 0.225" />
        <body name="left_leg" pos="0 0 -0.7">
          <joint damping="0.0659010527060226" name="left_knee" pos="0 0 0.25" range="-150 0" />
          <geom density="1181.8885412655359" friction="0.44511992887548324 0.18643895517638787 0.0737740026970564" name="left_leg" size="0.04 0.25" />
          <body name="left_foot" pos="0.06 0 -0.25">
            <joint damping="0.08676532081951882" name="left_ankle" pos="-0.06 0 0" range="-45 45" />
            <geom density="480.7211270122957" friction="0.3500790505105093 0.19955897735698064 0.06976717996282636" name="left_foot" size="0.05 0.17033570270595402" zaxis="1 0 0" />
          </body>
        </body>
      </body>
    </body>
  </worldbody>

  <sensor>
    <subtreelinvel body="torso" name="torso_subtreelinvel" />
  </sensor>

  <actuator>
    <motor gear="100" joint="right_hip" name="right_hip" />
    <motor gear="50" joint="right_knee" name="right_knee" />
    <motor gear="20" joint="right_ankle" name="right_ankle" />
    <motor gear="100" joint="left_hip" name="left_hip" />
    <motor gear="50" joint="left_knee" name="left_knee" />
    <motor gear="20" joint="left_ankle" name="left_ankle" />
  </actuator>
</mujoco>