<mujoco model="planar walker">
  <include file="./common/visual.xml" />
  <include file="./common/skybox.xml" />
  <include file="./common/materials.xml" />

  <option timestep="0.0025" />

  <statistic center="0 0 1" extent="2" />

  <default>
    <joint armature="0.01" damping=".1" limited="true" solimplimit="0 .99 .01" />
    <geom conaffinity="0" contype="1" friction=".7 .1 .1" />
    <motor ctrllimited="true" ctrlrange="-1 1" />
    <site size="0.01" />
    <default class="walker">
      <geom material="self" type="capsule" />
      <joint axis="0 -1 0" />
    </default>
  </default>

  <worldbody>
    <geom conaffinity="1" material="grid" name="floor" pos="248 0 0" size="250 .8 .2" type="plane" zaxis="0.14149684853935 0.0 0.989938706109339" />
    <body childclass="walker" name="torso" pos="2.523500254591795 0.0 36.389206178980665">
      <light mode="trackcom" name="light" pos="0 0 2" />
      <camera euler="60 0 0" mode="trackcom" name="side" pos="0 -2 .7" />
      <camera mode="trackcom" name="back" pos="-2 0 .5" xyaxes="0 -1 0 1 0 3" />
      <joint armature="0" axis="0 0 1" damping="0.20918999803327976" limited="false" name="rootz" type="slide" />
      <joint armature="0" axis="1 0 0" damping="0.1474705926250104" limited="false" name="rootx" type="slide" />
      <joint armature="0" axis="0 1 0" damping="0.051797058480337346" limited="false" name="rooty" type="hinge" />
      <geom density="647.3168211217454" friction="0.523847051432656 0.11178502192327998 0.21445212423107926" name="torso" size="0.07 0.3" />
      <body name="right_thigh" pos="0 -.05 -0.3">
        <joint damping="0.05331438431843147" name="right_hip" range="-20 100" />
        <geom density="1886.8681870555429" friction="0.8606114104398819 0.12912196160983067 0.0825945213201513" name="right_thigh" pos="0 0 -0.225" size="0.05 0.225" />
        <body name="right_leg" pos="0 0 -0.7">
          <joint damping="0.0602373308510765" name="right_knee" pos="0 0 0.25" range="-150 0" />
          <geom density="1008.7309836479787" friction="1.3668605502476707 0.04631083697907176 0.0634823169696476" name="right_leg" size="0.04 0.25" />
          <body name="right_foot" pos="0.06 0 -0.25">
            <joint damping="0.10432309241046536" name="right_ankle" pos="-0.06 0 0" range="-45 45" />
            <geom density="622.9706493558347" friction="0.8221494156829352 0.17851448206299422 0.04818236678881102" name="right_foot" size="0.05 0.07825113290573776" zaxis="1 0 0" />
          </body>
        </body>
      </body>
      <body name="left_thigh" pos="0 .05 -0.3">
        <joint damping="0.09610964068488081" name="left_hip" range="-20 100" />
        <geom density="705.8779321057569" friction="0.32343456915016644 0.07960653032046361 0.10701122490689526" name="left_thigh" pos="0 0 -0.225" size="0.05 0.225" />
        <body name="left_leg" pos="0 0 -0.7">
          <joint damping="0.20091992822968915" name="left_knee" pos="0 0 0.25" range="-150 0" />
          <geom density="656.9288781353107" friction="1.2412515522751626 0.13139349155825197 0.05323391095596369" name="left_leg" size="0.04 0.25" />
          <body name="left_foot" pos="0.06 0 -0.25">
            <joint damping="0.05458583159351326" name="left_ankle" pos="-0.06 0 0" range="-45 45" />
            <geom density="615.5104809374195" friction="0.7036861522964403 0.06261148700489964 0.0836757987558529" name="left_foot" size="0.05 0.06392306925919132" zaxis="1 0 0" />
          </body>
        </body>
      </body>
    </body>
  </worldbody>

  <sensor>
    <subtreelinvel body="torso" name="torso_subtreelinvel" />
  </sensor>

  <actuator>
    <motor gear="100" joint="right_hip" name="right_hip" />
    <motor gear="50" joint="right_knee" name="right_knee" />
    <motor gear="20" joint="right_ankle" name="right_ankle" />
    <motor gear="100" joint="left_hip" name="left_hip" />
    <motor gear="50" joint="left_knee" name="left_knee" />
    <motor gear="20" joint="left_ankle" name="left_ankle" />
  </actuator>
</mujoco>