<mujoco model="planar walker">
  <include file="./common/visual.xml" />
  <include file="./common/skybox.xml" />
  <include file="./common/materials.xml" />

  <option timestep="0.0025" />

  <statistic center="0 0 1" extent="2" />

  <default>
    <joint armature="0.01" damping=".1" limited="true" solimplimit="0 .99 .01" />
    <geom conaffinity="0" contype="1" friction=".7 .1 .1" />
    <motor ctrllimited="true" ctrlrange="-1 1" />
    <site size="0.01" />
    <default class="walker">
      <geom material="self" type="capsule" />
      <joint axis="0 -1 0" />
    </default>
  </default>

  <worldbody>
    <geom conaffinity="1" material="grid" name="floor" pos="248 0 0" size="250 .8 .2" type="plane" zaxis="-0.07931903918197555 0.0 0.9968492814980849" />
    <body childclass="walker" name="torso" pos="0.7655143806385638 0.0 -18.37175186083032">
      <light mode="trackcom" name="light" pos="0 0 2" />
      <camera euler="60 0 0" mode="trackcom" name="side" pos="0 -2 .7" />
      <camera mode="trackcom" name="back" pos="-2 0 .5" xyaxes="0 -1 0 1 0 3" />
      <joint armature="0" axis="0 0 1" damping="0.07310950689954203" limited="false" name="rootz" type="slide" />
      <joint armature="0" axis="1 0 0" damping="0.12040815264677805" limited="false" name="rootx" type="slide" />
      <joint armature="0" axis="0 1 0" damping="0.20689410123855587" limited="false" name="rooty" type="hinge" />
      <geom density="1821.7896293455249" friction="0.46556608933731614 0.0603937752804135 0.09421640299095485" name="torso" size="0.07 0.3" />
      <body name="right_thigh" pos="0 -.05 -0.3">
        <joint damping="0.0820249436222606" name="right_hip" range="-20 100" />
        <geom density="1140.5246065673873" friction="0.8559650490545906 0.0991415570396184 0.14427222434332607" name="right_thigh" pos="0 0 -0.225" size="0.05 0.225" />
        <body name="right_leg" pos="0 0 -0.7">
          <joint damping="0.0732001063151797" name="right_knee" pos="0 0 0.25" range="-150 0" />
          <geom density="1247.87403265881" friction="0.3930765339751115 0.1642587044869338 0.17274585367088438" name="right_leg" size="0.04 0.25" />
          <body name="right_foot" pos="0.06 0 -0.25">
            <joint damping="0.05067149110572338" name="right_ankle" pos="-0.06 0 0" range="-45 45" />
            <geom density="1239.534087542449" friction="0.3370877806178937 0.10880669890596883 0.10828661195256775" name="right_foot" size="0.05 0.10357648735591783" zaxis="1 0 0" />
          </body>
        </body>
      </body>
      <body name="left_thigh" pos="0 .05 -0.3">
        <joint damping="0.08059455485690165" name="left_hip" range="-20 100" />
        <geom density="1487.280178632473" friction="0.4131875008201626 0.14515065059581553 0.053859491789863594" name="left_thigh" pos="0 0 -0.225" size="0.05 0.225" />
        <body name="left_leg" pos="0 0 -0.7">
          <joint damping="0.056839911322996955" name="left_knee" pos="0 0 0.25" range="-150 0" />
          <geom density="990.4873939552016" friction="0.638069972330467 0.14043864932376723 0.15432344245523186" name="left_leg" size="0.04 0.25" />
          <body name="left_foot" pos="0.06 0 -0.25">
            <joint damping="0.09902676481600244" name="left_ankle" pos="-0.06 0 0" range="-45 45" />
            <geom density="1399.6584750069635" friction="1.3538943374086954 0.062223832211759325 0.07581131220119702" name="left_foot" size="0.05 0.06830785608610603" zaxis="1 0 0" />
          </body>
        </body>
      </body>
    </body>
  </worldbody>

  <sensor>
    <subtreelinvel body="torso" name="torso_subtreelinvel" />
  </sensor>

  <actuator>
    <motor gear="100" joint="right_hip" name="right_hip" />
    <motor gear="50" joint="right_knee" name="right_knee" />
    <motor gear="20" joint="right_ankle" name="right_ankle" />
    <motor gear="100" joint="left_hip" name="left_hip" />
    <motor gear="50" joint="left_knee" name="left_knee" />
    <motor gear="20" joint="left_ankle" name="left_ankle" />
  </actuator>
</mujoco>