<mujoco model="planar walker">
  <include file="./common/visual.xml" />
  <include file="./common/skybox.xml" />
  <include file="./common/materials.xml" />

  <option timestep="0.0025" />

  <statistic center="0 0 1" extent="2" />

  <default>
    <joint armature="0.01" damping=".1" limited="true" solimplimit="0 .99 .01" />
    <geom conaffinity="0" contype="1" friction=".7 .1 .1" />
    <motor ctrllimited="true" ctrlrange="-1 1" />
    <site size="0.01" />
    <default class="walker">
      <geom material="self" type="capsule" />
      <joint axis="0 -1 0" />
    </default>
  </default>

  <worldbody>
    <geom conaffinity="1" material="grid" name="floor" pos="248 0 0" size="250 .8 .2" type="plane" zaxis="0.12037178349906259 0.0 0.9927288822922675" />
    <body childclass="walker" name="torso" pos="1.827311548217466 0.0 31.150748084225977">
      <light mode="trackcom" name="light" pos="0 0 2" />
      <camera euler="60 0 0" mode="trackcom" name="side" pos="0 -2 .7" />
      <camera mode="trackcom" name="back" pos="-2 0 .5" xyaxes="0 -1 0 1 0 3" />
      <joint armature="0" axis="0 0 1" damping="0.1297420607123933" limited="false" name="rootz" type="slide" />
      <joint armature="0" axis="1 0 0" damping="0.14718303104809807" limited="false" name="rootx" type="slide" />
      <joint armature="0" axis="0 1 0" damping="0.05244959868397867" limited="false" name="rooty" type="hinge" />
      <geom density="1218.3565770350149" friction="1.2223040943255645 0.1201551064172509 0.11887819029527379" name="torso" size="0.07 0.3" />
      <body name="right_thigh" pos="0 -.05 -0.3">
        <joint damping="0.09941244170479459" name="right_hip" range="-20 100" />
        <geom density="1359.1179762172626" friction="1.3515881086301926 0.08935795285818267 0.07559089683904868" name="right_thigh" pos="0 0 -0.225" size="0.05 0.225" />
        <body name="right_leg" pos="0 0 -0.7">
          <joint damping="0.06293560441194357" name="right_knee" pos="0 0 0.25" range="-150 0" />
          <geom density="2001.183269798308" friction="0.6945251822505519 0.07348193409700224 0.06719081210407134" name="right_leg" size="0.04 0.25" />
          <body name="right_foot" pos="0.06 0 -0.25">
            <joint damping="0.10364467018798845" name="right_ankle" pos="-0.06 0 0" range="-45 45" />
            <geom density="1457.5473715789685" friction="1.046610230731513 0.060930927423675535 0.13787944303739583" name="right_foot" size="0.05 0.07188160185882299" zaxis="1 0 0" />
          </body>
        </body>
      </body>
      <body name="left_thigh" pos="0 .05 -0.3">
        <joint damping="0.20229965864809066" name="left_hip" range="-20 100" />
        <geom density="743.0651456288895" friction="0.6304692346854698 0.045564152679109515 0.08530902828358752" name="left_thigh" pos="0 0 -0.225" size="0.05 0.225" />
        <body name="left_leg" pos="0 0 -0.7">
          <joint damping="0.10687911769168704" name="left_knee" pos="0 0 0.25" range="-150 0" />
          <geom density="599.706692983035" friction="0.8510059892691177 0.08625499850330892 0.1265251675573956" name="left_leg" size="0.04 0.25" />
          <body name="left_foot" pos="0.06 0 -0.25">
            <joint damping="0.06692100358876175" name="left_ankle" pos="-0.06 0 0" range="-45 45" />
            <geom density="467.8367788246128" friction="0.3488797058536623 0.04997032878837643 0.14750771202147758" name="left_foot" size="0.05 0.06781765290727888" zaxis="1 0 0" />
          </body>
        </body>
      </body>
    </body>
  </worldbody>

  <sensor>
    <subtreelinvel body="torso" name="torso_subtreelinvel" />
  </sensor>

  <actuator>
    <motor gear="100" joint="right_hip" name="right_hip" />
    <motor gear="50" joint="right_knee" name="right_knee" />
    <motor gear="20" joint="right_ankle" name="right_ankle" />
    <motor gear="100" joint="left_hip" name="left_hip" />
    <motor gear="50" joint="left_knee" name="left_knee" />
    <motor gear="20" joint="left_ankle" name="left_ankle" />
  </actuator>
</mujoco>