<mujoco model="planar walker">
  <include file="./common/visual.xml" />
  <include file="./common/skybox.xml" />
  <include file="./common/materials.xml" />

  <option timestep="0.0025" />

  <statistic center="0 0 1" extent="2" />

  <default>
    <joint armature="0.01" damping=".1" limited="true" solimplimit="0 .99 .01" />
    <geom conaffinity="0" contype="1" friction=".7 .1 .1" />
    <motor ctrllimited="true" ctrlrange="-1 1" />
    <site size="0.01" />
    <default class="walker">
      <geom material="self" type="capsule" />
      <joint axis="0 -1 0" />
    </default>
  </default>

  <worldbody>
    <geom conaffinity="1" material="grid" name="floor" pos="248 0 0" size="250 .8 .2" type="plane" zaxis="0.14927172176193967 0.0 0.9887962141322276" />
    <body childclass="walker" name="torso" pos="2.808393239559962 0.0 38.31714623978748">
      <light mode="trackcom" name="light" pos="0 0 2" />
      <camera euler="60 0 0" mode="trackcom" name="side" pos="0 -2 .7" />
      <camera mode="trackcom" name="back" pos="-2 0 .5" xyaxes="0 -1 0 1 0 3" />
      <joint armature="0" axis="0 0 1" damping="0.09540772801893024" limited="false" name="rootz" type="slide" />
      <joint armature="0" axis="1 0 0" damping="0.050927749580675724" limited="false" name="rootx" type="slide" />
      <joint armature="0" axis="0 1 0" damping="0.051444121424735784" limited="false" name="rooty" type="hinge" />
      <geom density="847.6063869298713" friction="0.5387362561869689 0.15484085903849307 0.048652335552412815" name="torso" size="0.07 0.3" />
      <body name="right_thigh" pos="0 -.05 -0.3">
        <joint damping="0.13159427169081" name="right_hip" range="-20 100" />
        <geom density="1287.948481448875" friction="0.36753177270614074 0.11589277050736113 0.09145295658452199" name="right_thigh" pos="0 0 -0.225" size="0.05 0.225" />
        <body name="right_leg" pos="0 0 -0.7">
          <joint damping="0.13941011299387704" name="right_knee" pos="0 0 0.25" range="-150 0" />
          <geom density="474.43280890123395" friction="1.4164639014187337 0.1512396866157723 0.07177188763926827" name="right_leg" size="0.04 0.25" />
          <body name="right_foot" pos="0.06 0 -0.25">
            <joint damping="0.1184883056655325" name="right_ankle" pos="-0.06 0 0" range="-45 45" />
            <geom density="584.0851314339707" friction="0.3439384500900329 0.11373352289818406 0.09715269092757026" name="right_foot" size="0.05 0.11984598343531327" zaxis="1 0 0" />
          </body>
        </body>
      </body>
      <body name="left_thigh" pos="0 .05 -0.3">
        <joint damping="0.08568532398948128" name="left_hip" range="-20 100" />
        <geom density="652.5708612265352" friction="1.4898958737196053 0.14493471592067575 0.06682896464268002" name="left_thigh" pos="0 0 -0.225" size="0.05 0.225" />
        <body name="left_leg" pos="0 0 -0.7">
          <joint damping="0.1271799419024959" name="left_knee" pos="0 0 0.25" range="-150 0" />
          <geom density="1068.4683636376606" friction="1.2775386949830365 0.05034929339035347 0.07695042787427721" name="left_leg" size="0.04 0.25" />
          <body name="left_foot" pos="0.06 0 -0.25">
            <joint damping="0.07947020318795311" name="left_ankle" pos="-0.06 0 0" range="-45 45" />
            <geom density="1166.3752849790135" friction="0.5270598617138698 0.14643617155742786 0.18040261872125118" name="left_foot" size="0.05 0.06706385297121595" zaxis="1 0 0" />
          </body>
        </body>
      </body>
    </body>
  </worldbody>

  <sensor>
    <subtreelinvel body="torso" name="torso_subtreelinvel" />
  </sensor>

  <actuator>
    <motor gear="100" joint="right_hip" name="right_hip" />
    <motor gear="50" joint="right_knee" name="right_knee" />
    <motor gear="20" joint="right_ankle" name="right_ankle" />
    <motor gear="100" joint="left_hip" name="left_hip" />
    <motor gear="50" joint="left_knee" name="left_knee" />
    <motor gear="20" joint="left_ankle" name="left_ankle" />
  </actuator>
</mujoco>