<mujoco model="planar walker">
  <include file="./common/visual.xml" />
  <include file="./common/skybox.xml" />
  <include file="./common/materials.xml" />

  <option timestep="0.0025" />

  <statistic center="0 0 1" extent="2" />

  <default>
    <joint armature="0.01" damping=".1" limited="true" solimplimit="0 .99 .01" />
    <geom conaffinity="0" contype="1" friction=".7 .1 .1" />
    <motor ctrllimited="true" ctrlrange="-1 1" />
    <site size="0.01" />
    <default class="walker">
      <geom material="self" type="capsule" />
      <joint axis="0 -1 0" />
    </default>
  </default>

  <worldbody>
    <geom conaffinity="1" material="grid" name="floor" pos="248 0 0" size="250 .8 .2" type="plane" zaxis="-0.12040695048689676 0.0 0.9927246175422699" />
    <body childclass="walker" name="torso" pos="1.780213459419656 0.0 -28.56237879724194">
      <light mode="trackcom" name="light" pos="0 0 2" />
      <camera euler="60 0 0" mode="trackcom" name="side" pos="0 -2 .7" />
      <camera mode="trackcom" name="back" pos="-2 0 .5" xyaxes="0 -1 0 1 0 3" />
      <joint armature="0" axis="0 0 1" damping="0.10536221313664867" limited="false" name="rootz" type="slide" />
      <joint armature="0" axis="1 0 0" damping="0.05328558194433484" limited="false" name="rootx" type="slide" />
      <joint armature="0" axis="0 1 0" damping="0.05890421824757444" limited="false" name="rooty" type="hinge" />
      <geom density="1846.0952293588832" friction="0.5623952330039127 0.18006612740061967 0.21254039995452595" name="torso" size="0.07 0.3" />
      <body name="right_thigh" pos="0 -.05 -0.3">
        <joint damping="0.07559856172320513" name="right_hip" range="-20 100" />
        <geom density="1906.6331085246006" friction="0.548268309541117 0.13024955397844612 0.065797056673644" name="right_thigh" pos="0 0 -0.225" size="0.05 0.225" />
        <body name="right_leg" pos="0 0 -0.7">
          <joint damping="0.20261678048512752" name="right_knee" pos="0 0 0.25" range="-150 0" />
          <geom density="1862.2163524554603" friction="1.2553811517224436 0.10433273334492908 0.052545376075610044" name="right_leg" size="0.04 0.25" />
          <body name="right_foot" pos="0.06 0 -0.25">
            <joint damping="0.11016744274736015" name="right_ankle" pos="-0.06 0 0" range="-45 45" />
            <geom density="507.3507091594369" friction="1.0104303711879021 0.16086333576717443 0.12575656635240232" name="right_foot" size="0.05 0.13172510161862896" zaxis="1 0 0" />
          </body>
        </body>
      </body>
      <body name="left_thigh" pos="0 .05 -0.3">
        <joint damping="0.202234525962723" name="left_hip" range="-20 100" />
        <geom density="553.3442771731283" friction="0.6321115725570638 0.06352895894081426 0.06286970768530724" name="left_thigh" pos="0 0 -0.225" size="0.05 0.225" />
        <body name="left_leg" pos="0 0 -0.7">
          <joint damping="0.10876388964653252" name="left_knee" pos="0 0 0.25" range="-150 0" />
          <geom density="1440.9526131569742" friction="0.5568890103249441 0.18061795574041395 0.18137933494296454" name="left_leg" size="0.04 0.25" />
          <body name="left_foot" pos="0.06 0 -0.25">
            <joint damping="0.217895432769874" name="left_ankle" pos="-0.06 0 0" range="-45 45" />
            <geom density="624.8778391083811" friction="0.7071981941501287 0.0918545977878093 0.046222480658167836" name="left_foot" size="0.05 0.14274404033777097" zaxis="1 0 0" />
          </body>
        </body>
      </body>
    </body>
  </worldbody>

  <sensor>
    <subtreelinvel body="torso" name="torso_subtreelinvel" />
  </sensor>

  <actuator>
    <motor gear="100" joint="right_hip" name="right_hip" />
    <motor gear="50" joint="right_knee" name="right_knee" />
    <motor gear="20" joint="right_ankle" name="right_ankle" />
    <motor gear="100" joint="left_hip" name="left_hip" />
    <motor gear="50" joint="left_knee" name="left_knee" />
    <motor gear="20" joint="left_ankle" name="left_ankle" />
  </actuator>
</mujoco>