<mujoco model="planar walker">
  <include file="./common/visual.xml" />
  <include file="./common/skybox.xml" />
  <include file="./common/materials.xml" />

  <option timestep="0.0025" />

  <statistic center="0 0 1" extent="2" />

  <default>
    <joint armature="0.01" damping=".1" limited="true" solimplimit="0 .99 .01" />
    <geom conaffinity="0" contype="1" friction=".7 .1 .1" />
    <motor ctrllimited="true" ctrlrange="-1 1" />
    <site size="0.01" />
    <default class="walker">
      <geom material="self" type="capsule" />
      <joint axis="0 -1 0" />
    </default>
  </default>

  <worldbody>
    <geom conaffinity="1" material="grid" name="floor" pos="248 0 0" size="250 .8 .2" type="plane" zaxis="-0.03684807015125204 0.0 0.9993208792605749" />
    <body childclass="walker" name="torso" pos="0.16105232934719993 0.0 -7.838457221658391">
      <light mode="trackcom" name="light" pos="0 0 2" />
      <camera euler="60 0 0" mode="trackcom" name="side" pos="0 -2 .7" />
      <camera mode="trackcom" name="back" pos="-2 0 .5" xyaxes="0 -1 0 1 0 3" />
      <joint armature="0" axis="0 0 1" damping="0.17376982348150996" limited="false" name="rootz" type="slide" />
      <joint armature="0" axis="1 0 0" damping="0.05711546149686911" limited="false" name="rootx" type="slide" />
      <joint armature="0" axis="0 1 0" damping="0.14212540534037144" limited="false" name="rooty" type="hinge" />
      <geom density="861.3419555111197" friction="0.5448173436372707 0.1407366605992259 0.10064306151726912" name="torso" size="0.07 0.3" />
      <body name="right_thigh" pos="0 -.05 -0.3">
        <joint damping="0.12396315735662947" name="right_hip" range="-20 100" />
        <geom density="1202.706281193872" friction="0.45743412640541653 0.1291625199281029 0.0876467332359622" name="right_thigh" pos="0 0 -0.225" size="0.05 0.225" />
        <body name="right_leg" pos="0 0 -0.7">
          <joint damping="0.06431794558153517" name="right_knee" pos="0 0 0.25" range="-150 0" />
          <geom density="887.2834052261826" friction="0.5802902712720547 0.05744292748620318 0.14834147899980146" name="right_leg" size="0.04 0.25" />
          <body name="right_foot" pos="0.06 0 -0.25">
            <joint damping="0.20423520638939607" name="right_ankle" pos="-0.06 0 0" range="-45 45" />
            <geom density="954.7001070748953" friction="0.45948992741169215 0.17680556026477356 0.08178855190877544" name="right_foot" size="0.05 0.17501474618289514" zaxis="1 0 0" />
          </body>
        </body>
      </body>
      <body name="left_thigh" pos="0 .05 -0.3">
        <joint damping="0.07389657272059942" name="left_hip" range="-20 100" />
        <geom density="1227.7923218351143" friction="0.6837387408704004 0.0796708323325888 0.1225490423051129" name="left_thigh" pos="0 0 -0.225" size="0.05 0.225" />
        <body name="left_leg" pos="0 0 -0.7">
          <joint damping="0.16876256618636137" name="left_knee" pos="0 0 0.25" range="-150 0" />
          <geom density="573.6350687080318" friction="0.4330126972867611 0.0768245442434973 0.10802524155750877" name="left_leg" size="0.04 0.25" />
          <body name="left_foot" pos="0.06 0 -0.25">
            <joint damping="0.07111766965091817" name="left_ankle" pos="-0.06 0 0" range="-45 45" />
            <geom density="1178.246590440616" friction="1.1553087202339936 0.14981429839532204 0.10020286461466266" name="left_foot" size="0.05 0.047757522735993346" zaxis="1 0 0" />
          </body>
        </body>
      </body>
    </body>
  </worldbody>

  <sensor>
    <subtreelinvel body="torso" name="torso_subtreelinvel" />
  </sensor>

  <actuator>
    <motor gear="100" joint="right_hip" name="right_hip" />
    <motor gear="50" joint="right_knee" name="right_knee" />
    <motor gear="20" joint="right_ankle" name="right_ankle" />
    <motor gear="100" joint="left_hip" name="left_hip" />
    <motor gear="50" joint="left_knee" name="left_knee" />
    <motor gear="20" joint="left_ankle" name="left_ankle" />
  </actuator>
</mujoco>