<mujoco model="planar walker">
  <include file="./common/visual.xml" />
  <include file="./common/skybox.xml" />
  <include file="./common/materials.xml" />

  <option timestep="0.0025" />

  <statistic center="0 0 1" extent="2" />

  <default>
    <joint armature="0.01" damping=".1" limited="true" solimplimit="0 .99 .01" />
    <geom conaffinity="0" contype="1" friction=".7 .1 .1" />
    <motor ctrllimited="true" ctrlrange="-1 1" />
    <site size="0.01" />
    <default class="walker">
      <geom material="self" type="capsule" />
      <joint axis="0 -1 0" />
    </default>
  </default>

  <worldbody>
    <geom conaffinity="1" material="grid" name="floor" pos="248 0 0" size="250 .8 .2" type="plane" zaxis="0.041815988807140214 0.0 0.9991253290153749" />
    <body childclass="walker" name="torso" pos="0.22528160194846691 0.0 11.670190289973847">
      <light mode="trackcom" name="light" pos="0 0 2" />
      <camera euler="60 0 0" mode="trackcom" name="side" pos="0 -2 .7" />
      <camera mode="trackcom" name="back" pos="-2 0 .5" xyaxes="0 -1 0 1 0 3" />
      <joint armature="0" axis="0 0 1" damping="0.19437675220908113" limited="false" name="rootz" type="slide" />
      <joint armature="0" axis="1 0 0" damping="0.06677334856699098" limited="false" name="rootx" type="slide" />
      <joint armature="0" axis="0 1 0" damping="0.12832271982647359" limited="false" name="rooty" type="hinge" />
      <geom density="1312.7785962206133" friction="0.6107522944119445 0.18458905929567695 0.12992264776867055" name="torso" size="0.07 0.3" />
      <body name="right_thigh" pos="0 -.05 -0.3">
        <joint damping="0.04944253334037209" name="right_hip" range="-20 100" />
        <geom density="833.6501628337376" friction="0.3487213039588389 0.08389234467460704 0.07625959610599573" name="right_thigh" pos="0 0 -0.225" size="0.05 0.225" />
        <body name="right_leg" pos="0 0 -0.7">
          <joint damping="0.06527459932106248" name="right_knee" pos="0 0 0.25" range="-150 0" />
          <geom density="1604.8563254179444" friction="0.4906979195367046 0.10729745843890218 0.14244946002901274" name="right_leg" size="0.04 0.25" />
          <body name="right_foot" pos="0.06 0 -0.25">
            <joint damping="0.13557234877814112" name="right_ankle" pos="-0.06 0 0" range="-45 45" />
            <geom density="581.1854033970031" friction="0.4464555366265488 0.07733257887996317 0.06337252438798399" name="right_foot" size="0.05 0.14941692591054817" zaxis="1 0 0" />
          </body>
        </body>
      </body>
      <body name="left_thigh" pos="0 .05 -0.3">
        <joint damping="0.05061800551857996" name="left_hip" range="-20 100" />
        <geom density="1569.6462491985624" friction="1.5215947899539086 0.09951469790516379 0.13448369148723097" name="left_thigh" pos="0 0 -0.225" size="0.05 0.225" />
        <body name="left_leg" pos="0 0 -0.7">
          <joint damping="0.054263145540964425" name="left_knee" pos="0 0 0.25" range="-150 0" />
          <geom density="768.9659338185962" friction="0.3336349725586712 0.12576561285940824 0.18217065196677706" name="left_leg" size="0.04 0.25" />
          <body name="left_foot" pos="0.06 0 -0.25">
            <joint damping="0.05255721334332221" name="left_ankle" pos="-0.06 0 0" range="-45 45" />
            <geom density="1596.88830389078" friction="1.5092849253080198 0.1498006350334153 0.07310895230844165" name="left_foot" size="0.05 0.04874119743623849" zaxis="1 0 0" />
          </body>
        </body>
      </body>
    </body>
  </worldbody>

  <sensor>
    <subtreelinvel body="torso" name="torso_subtreelinvel" />
  </sensor>

  <actuator>
    <motor gear="100" joint="right_hip" name="right_hip" />
    <motor gear="50" joint="right_knee" name="right_knee" />
    <motor gear="20" joint="right_ankle" name="right_ankle" />
    <motor gear="100" joint="left_hip" name="left_hip" />
    <motor gear="50" joint="left_knee" name="left_knee" />
    <motor gear="20" joint="left_ankle" name="left_ankle" />
  </actuator>
</mujoco>