<mujoco model="planar walker">
  <include file="./common/visual.xml" />
  <include file="./common/skybox.xml" />
  <include file="./common/materials.xml" />

  <option timestep="0.0025" />

  <statistic center="0 0 1" extent="2" />

  <default>
    <joint armature="0.01" damping=".1" limited="true" solimplimit="0 .99 .01" />
    <geom conaffinity="0" contype="1" friction=".7 .1 .1" />
    <motor ctrllimited="true" ctrlrange="-1 1" />
    <site size="0.01" />
    <default class="walker">
      <geom material="self" type="capsule" />
      <joint axis="0 -1 0" />
    </default>
  </default>

  <worldbody>
    <geom conaffinity="1" material="grid" name="floor" pos="248 0 0" size="250 .8 .2" type="plane" zaxis="-0.12595191854672963 0.0 0.9920363472244341" />
    <body childclass="walker" name="torso" pos="1.9497955046309983 0.0 -29.937668530144062">
      <light mode="trackcom" name="light" pos="0 0 2" />
      <camera euler="60 0 0" mode="trackcom" name="side" pos="0 -2 .7" />
      <camera mode="trackcom" name="back" pos="-2 0 .5" xyaxes="0 -1 0 1 0 3" />
      <joint armature="0" axis="0 0 1" damping="0.15295582015821055" limited="false" name="rootz" type="slide" />
      <joint armature="0" axis="1 0 0" damping="0.06099651998872542" limited="false" name="rootx" type="slide" />
      <joint armature="0" axis="0 1 0" damping="0.1263448601152452" limited="false" name="rooty" type="hinge" />
      <geom density="639.0332860820266" friction="0.8277893361533141 0.1071792158425541 0.10393019953293599" name="torso" size="0.07 0.3" />
      <body name="right_thigh" pos="0 -.05 -0.3">
        <joint damping="0.17396978634916965" name="right_hip" range="-20 100" />
        <geom density="856.3785037067448" friction="1.1886640387741088 0.18396766132888773 0.06274252700091787" name="right_thigh" pos="0 0 -0.225" size="0.05 0.225" />
        <body name="right_leg" pos="0 0 -0.7">
          <joint damping="0.07542736233675759" name="right_knee" pos="0 0 0.25" range="-150 0" />
          <geom density="771.6716244275341" friction="1.1788168916447759 0.08230512630375074 0.20241259132080242" name="right_leg" size="0.04 0.25" />
          <body name="right_foot" pos="0.06 0 -0.25">
            <joint damping="0.06563397756141316" name="right_ankle" pos="-0.06 0 0" range="-45 45" />
            <geom density="1090.1068170508809" friction="0.5552040009251307 0.07174400244783519 0.18353342511362702" name="right_foot" size="0.05 0.07374256748598695" zaxis="1 0 0" />
          </body>
        </body>
      </body>
      <body name="left_thigh" pos="0 .05 -0.3">
        <joint damping="0.12597641013507352" name="left_hip" range="-20 100" />
        <geom density="664.5313667826804" friction="0.9115456447327696 0.045876306155213216 0.052768018801454875" name="left_thigh" pos="0 0 -0.225" size="0.05 0.225" />
        <body name="left_leg" pos="0 0 -0.7">
          <joint damping="0.05133779797178604" name="left_knee" pos="0 0 0.25" range="-150 0" />
          <geom density="650.2553964202779" friction="1.3878147859286873 0.06427683257338339 0.14538709250794463" name="left_leg" size="0.04 0.25" />
          <body name="left_foot" pos="0.06 0 -0.25">
            <joint damping="0.07170409412870374" name="left_ankle" pos="-0.06 0 0" range="-45 45" />
            <geom density="2088.5487047096904" friction="1.3317576841769247 0.0965046826261447 0.1831709902347247" name="left_foot" size="0.05 0.08361678486442298" zaxis="1 0 0" />
          </body>
        </body>
      </body>
    </body>
  </worldbody>

  <sensor>
    <subtreelinvel body="torso" name="torso_subtreelinvel" />
  </sensor>

  <actuator>
    <motor gear="100" joint="right_hip" name="right_hip" />
    <motor gear="50" joint="right_knee" name="right_knee" />
    <motor gear="20" joint="right_ankle" name="right_ankle" />
    <motor gear="100" joint="left_hip" name="left_hip" />
    <motor gear="50" joint="left_knee" name="left_knee" />
    <motor gear="20" joint="left_ankle" name="left_ankle" />
  </actuator>
</mujoco>