<mujoco model="planar walker">
  <include file="./common/visual.xml" />
  <include file="./common/skybox.xml" />
  <include file="./common/materials.xml" />

  <option timestep="0.0025" />

  <statistic center="0 0 1" extent="2" />

  <default>
    <joint armature="0.01" damping=".1" limited="true" solimplimit="0 .99 .01" />
    <geom conaffinity="0" contype="1" friction=".7 .1 .1" />
    <motor ctrllimited="true" ctrlrange="-1 1" />
    <site size="0.01" />
    <default class="walker">
      <geom material="self" type="capsule" />
      <joint axis="0 -1 0" />
    </default>
  </default>

  <worldbody>
    <geom conaffinity="1" material="grid" name="floor" pos="248 0 0" size="250 .8 .2" type="plane" zaxis="-0.16179544387527325 0.0 0.986824317870817" />
    <body childclass="walker" name="torso" pos="3.235210079262316 0.0 -38.8279052174936">
      <light mode="trackcom" name="light" pos="0 0 2" />
      <camera euler="60 0 0" mode="trackcom" name="side" pos="0 -2 .7" />
      <camera mode="trackcom" name="back" pos="-2 0 .5" xyaxes="0 -1 0 1 0 3" />
      <joint armature="0" axis="0 0 1" damping="0.1843332479543035" limited="false" name="rootz" type="slide" />
      <joint armature="0" axis="1 0 0" damping="0.0519845233259415" limited="false" name="rootx" type="slide" />
      <joint armature="0" axis="0 1 0" damping="0.07217869611389709" limited="false" name="rooty" type="hinge" />
      <geom density="2048.784442958049" friction="1.0669935167669764 0.1442338005393423 0.1424034889950568" name="torso" size="0.07 0.3" />
      <body name="right_thigh" pos="0 -.05 -0.3">
        <joint damping="0.04673666032646804" name="right_hip" range="-20 100" />
        <geom density="1325.027715261521" friction="0.9085686249291894 0.07642597048785048 0.1837085787057517" name="right_thigh" pos="0 0 -0.225" size="0.05 0.225" />
        <body name="right_leg" pos="0 0 -0.7">
          <joint damping="0.1411507106732188" name="right_knee" pos="0 0 0.25" range="-150 0" />
          <geom density="1402.6987567117098" friction="1.27448478185852 0.09578983849719741 0.16785896890187738" name="right_leg" size="0.04 0.25" />
          <body name="right_foot" pos="0.06 0 -0.25">
            <joint damping="0.056026861853905346" name="right_ankle" pos="-0.06 0 0" range="-45 45" />
            <geom density="2070.237614725923" friction="1.4730421033603445 0.061011802460969815 0.11963781475455515" name="right_foot" size="0.05 0.07279575691705559" zaxis="1 0 0" />
          </body>
        </body>
      </body>
      <body name="left_thigh" pos="0 .05 -0.3">
        <joint damping="0.18836528903318303" name="left_hip" range="-20 100" />
        <geom density="667.1686177637653" friction="0.9286416337390525 0.14597849823008932 0.0973969206377266" name="left_thigh" pos="0 0 -0.225" size="0.05 0.225" />
        <body name="left_leg" pos="0 0 -0.7">
          <joint damping="0.08083283115873291" name="left_knee" pos="0 0 0.25" range="-150 0" />
          <geom density="812.8410288612931" friction="1.1759049649224895 0.17543804239205896 0.14820805076943408" name="left_leg" size="0.04 0.25" />
          <body name="left_foot" pos="0.06 0 -0.25">
            <joint damping="0.0979733734828369" name="left_ankle" pos="-0.06 0 0" range="-45 45" />
            <geom density="555.8200938620333" friction="1.036949057711365 0.05945809214433968 0.11598912596388933" name="left_foot" size="0.05 0.0555345138379518" zaxis="1 0 0" />
          </body>
        </body>
      </body>
    </body>
  </worldbody>

  <sensor>
    <subtreelinvel body="torso" name="torso_subtreelinvel" />
  </sensor>

  <actuator>
    <motor gear="100" joint="right_hip" name="right_hip" />
    <motor gear="50" joint="right_knee" name="right_knee" />
    <motor gear="20" joint="right_ankle" name="right_ankle" />
    <motor gear="100" joint="left_hip" name="left_hip" />
    <motor gear="50" joint="left_knee" name="left_knee" />
    <motor gear="20" joint="left_ankle" name="left_ankle" />
  </actuator>
</mujoco>