<mujoco model="planar walker">
  <include file="./common/visual.xml" />
  <include file="./common/skybox.xml" />
  <include file="./common/materials.xml" />

  <option timestep="0.0025" />

  <statistic center="0 0 1" extent="2" />

  <default>
    <joint armature="0.01" damping=".1" limited="true" solimplimit="0 .99 .01" />
    <geom conaffinity="0" contype="1" friction=".7 .1 .1" />
    <motor ctrllimited="true" ctrlrange="-1 1" />
    <site size="0.01" />
    <default class="walker">
      <geom material="self" type="capsule" />
      <joint axis="0 -1 0" />
    </default>
  </default>

  <worldbody>
    <geom conaffinity="1" material="grid" name="floor" pos="248 0 0" size="250 .8 .2" type="plane" zaxis="0.15003749883333348 0.0 0.9886803067442163" />
    <body childclass="walker" name="torso" pos="2.8372914272010235 0.0 38.50703577201555">
      <light mode="trackcom" name="light" pos="0 0 2" />
      <camera euler="60 0 0" mode="trackcom" name="side" pos="0 -2 .7" />
      <camera mode="trackcom" name="back" pos="-2 0 .5" xyaxes="0 -1 0 1 0 3" />
      <joint armature="0" axis="0 0 1" damping="0.16072330452593464" limited="false" name="rootz" type="slide" />
      <joint armature="0" axis="1 0 0" damping="0.1686558638915074" limited="false" name="rootx" type="slide" />
      <joint armature="0" axis="0 1 0" damping="0.07107736862951701" limited="false" name="rooty" type="hinge" />
      <geom density="1144.2067966049299" friction="0.6792200384250514 0.1155271527597986 0.0895623635792771" name="torso" size="0.07 0.3" />
      <body name="right_thigh" pos="0 -.05 -0.3">
        <joint damping="0.08026930452672008" name="right_hip" range="-20 100" />
        <geom density="905.759516525208" friction="1.1789480220812452 0.18018416503669837 0.11436621605901692" name="right_thigh" pos="0 0 -0.225" size="0.05 0.225" />
        <body name="right_leg" pos="0 0 -0.7">
          <joint damping="0.13335407747103095" name="right_knee" pos="0 0 0.25" range="-150 0" />
          <geom density="1264.6602411236677" friction="0.34633940362656995 0.051962569115680785 0.06395559245316705" name="right_leg" size="0.04 0.25" />
          <body name="right_foot" pos="0.06 0 -0.25">
            <joint damping="0.18838418327375794" name="right_ankle" pos="-0.06 0 0" range="-45 45" />
            <geom density="604.7467737399464" friction="1.1132034141857465 0.08732831535986722 0.09156677503282126" name="right_foot" size="0.05 0.07849169169428269" zaxis="1 0 0" />
          </body>
        </body>
      </body>
      <body name="left_thigh" pos="0 .05 -0.3">
        <joint damping="0.1501499814815819" name="left_hip" range="-20 100" />
        <geom density="786.101901252353" friction="0.6511631322642576 0.09388692057455889 0.0504774919277268" name="left_thigh" pos="0 0 -0.225" size="0.05 0.225" />
        <body name="left_leg" pos="0 0 -0.7">
          <joint damping="0.1158563903875861" name="left_knee" pos="0 0 0.25" range="-150 0" />
          <geom density="1387.6962936390337" friction="0.4907598169378693 0.061097655572937205 0.21277732577832517" name="left_leg" size="0.04 0.25" />
          <body name="left_foot" pos="0.06 0 -0.25">
            <joint damping="0.09406070970510799" name="left_ankle" pos="-0.06 0 0" range="-45 45" />
            <geom density="1408.0413939741734" friction="0.5118075399981853 0.12365283746998013 0.1326080248664974" name="left_foot" size="0.05 0.07153017148321139" zaxis="1 0 0" />
          </body>
        </body>
      </body>
    </body>
  </worldbody>

  <sensor>
    <subtreelinvel body="torso" name="torso_subtreelinvel" />
  </sensor>

  <actuator>
    <motor gear="100" joint="right_hip" name="right_hip" />
    <motor gear="50" joint="right_knee" name="right_knee" />
    <motor gear="20" joint="right_ankle" name="right_ankle" />
    <motor gear="100" joint="left_hip" name="left_hip" />
    <motor gear="50" joint="left_knee" name="left_knee" />
    <motor gear="20" joint="left_ankle" name="left_ankle" />
  </actuator>
</mujoco>