<mujoco model="planar walker">
  <include file="./common/visual.xml" />
  <include file="./common/skybox.xml" />
  <include file="./common/materials.xml" />

  <option timestep="0.0025" />

  <statistic center="0 0 1" extent="2" />

  <default>
    <joint armature="0.01" damping=".1" limited="true" solimplimit="0 .99 .01" />
    <geom conaffinity="0" contype="1" friction=".7 .1 .1" />
    <motor ctrllimited="true" ctrlrange="-1 1" />
    <site size="0.01" />
    <default class="walker">
      <geom material="self" type="capsule" />
      <joint axis="0 -1 0" />
    </default>
  </default>

  <worldbody>
    <geom conaffinity="1" material="grid" name="floor" pos="248 0 0" size="250 .8 .2" type="plane" zaxis="0.06920971196293275 0.0 0.9976021330019338" />
    <body childclass="walker" name="torso" pos="0.6085129579130069 0.0 18.46352899340771">
      <light mode="trackcom" name="light" pos="0 0 2" />
      <camera euler="60 0 0" mode="trackcom" name="side" pos="0 -2 .7" />
      <camera mode="trackcom" name="back" pos="-2 0 .5" xyaxes="0 -1 0 1 0 3" />
      <joint armature="0" axis="0 0 1" damping="0.07435960476849958" limited="false" name="rootz" type="slide" />
      <joint armature="0" axis="1 0 0" damping="0.07009117207834224" limited="false" name="rootx" type="slide" />
      <joint armature="0" axis="0 1 0" damping="0.11340251870301502" limited="false" name="rooty" type="hinge" />
      <geom density="837.9940794863351" friction="0.5510087214300324 0.10688361433634706 0.1083550019345466" name="torso" size="0.07 0.3" />
      <body name="right_thigh" pos="0 -.05 -0.3">
        <joint damping="0.07208290218119436" name="right_hip" range="-20 100" />
        <geom density="1209.9809109052073" friction="0.523312423772923 0.14105726008595418 0.06740661356607006" name="right_thigh" pos="0 0 -0.225" size="0.05 0.225" />
        <body name="right_leg" pos="0 0 -0.7">
          <joint damping="0.12594938708304046" name="right_knee" pos="0 0 0.25" range="-150 0" />
          <geom density="708.0676005912487" friction="0.40920952970244245 0.20009012949853133 0.18936982307772024" name="right_leg" size="0.04 0.25" />
          <body name="right_foot" pos="0.06 0 -0.25">
            <joint damping="0.21659806521061703" name="right_ankle" pos="-0.06 0 0" range="-45 45" />
            <geom density="1131.3116853837982" friction="0.97567189532831 0.16708418767665748 0.1466340730000781" name="right_foot" size="0.05 0.0666495651958358" zaxis="1 0 0" />
          </body>
        </body>
      </body>
      <body name="left_thigh" pos="0 .05 -0.3">
        <joint damping="0.05935573547487286" name="left_hip" range="-20 100" />
        <geom density="736.507243051821" friction="0.5504729242469744 0.08086846112096341 0.11354788818444686" name="left_thigh" pos="0 0 -0.225" size="0.05 0.225" />
        <body name="left_leg" pos="0 0 -0.7">
          <joint damping="0.11777534105601567" name="left_knee" pos="0 0 0.25" range="-150 0" />
          <geom density="1770.1903288516503" friction="0.48739302491175646 0.06435126734466785 0.050065264375408494" name="left_leg" size="0.04 0.25" />
          <body name="left_foot" pos="0.06 0 -0.25">
            <joint damping="0.07329173888698486" name="left_ankle" pos="-0.06 0 0" range="-45 45" />
            <geom density="1906.7160875418645" friction="1.2844889233339847 0.1312892456928582 0.047426588929635506" name="left_foot" size="0.05 0.04560119075999218" zaxis="1 0 0" />
          </body>
        </body>
      </body>
    </body>
  </worldbody>

  <sensor>
    <subtreelinvel body="torso" name="torso_subtreelinvel" />
  </sensor>

  <actuator>
    <motor gear="100" joint="right_hip" name="right_hip" />
    <motor gear="50" joint="right_knee" name="right_knee" />
    <motor gear="20" joint="right_ankle" name="right_ankle" />
    <motor gear="100" joint="left_hip" name="left_hip" />
    <motor gear="50" joint="left_knee" name="left_knee" />
    <motor gear="20" joint="left_ankle" name="left_ankle" />
  </actuator>
</mujoco>