<mujoco model="planar walker">
  <include file="./common/visual.xml" />
  <include file="./common/skybox.xml" />
  <include file="./common/materials.xml" />

  <option timestep="0.0025" />

  <statistic center="0 0 1" extent="2" />

  <default>
    <joint armature="0.01" damping=".1" limited="true" solimplimit="0 .99 .01" />
    <geom conaffinity="0" contype="1" friction=".7 .1 .1" />
    <motor ctrllimited="true" ctrlrange="-1 1" />
    <site size="0.01" />
    <default class="walker">
      <geom material="self" type="capsule" />
      <joint axis="0 -1 0" />
    </default>
  </default>

  <worldbody>
    <geom conaffinity="1" material="grid" name="floor" pos="248 0 0" size="250 .8 .2" type="plane" zaxis="0.09057924069080509 0.0 0.9958892514511225" />
    <body childclass="walker" name="torso" pos="1.0375814882597751 0.0 23.762829541609886">
      <light mode="trackcom" name="light" pos="0 0 2" />
      <camera euler="60 0 0" mode="trackcom" name="side" pos="0 -2 .7" />
      <camera mode="trackcom" name="back" pos="-2 0 .5" xyaxes="0 -1 0 1 0 3" />
      <joint armature="0" axis="0 0 1" damping="0.050163094827712286" limited="false" name="rootz" type="slide" />
      <joint armature="0" axis="1 0 0" damping="0.06925476920690152" limited="false" name="rootx" type="slide" />
      <joint armature="0" axis="0 1 0" damping="0.08982491833532483" limited="false" name="rooty" type="hinge" />
      <geom density="1227.6203495552154" friction="1.1177866756793287 0.06696889993109632 0.06479990578165215" name="torso" size="0.07 0.3" />
      <body name="right_thigh" pos="0 -.05 -0.3">
        <joint damping="0.20541371770881192" name="right_hip" range="-20 100" />
        <geom density="479.7002878758715" friction="1.039854551553621 0.05346331335418743 0.05085499649595733" name="right_thigh" pos="0 0 -0.225" size="0.05 0.225" />
        <body name="right_leg" pos="0 0 -0.7">
          <joint damping="0.1832600317819751" name="right_knee" pos="0 0 0.25" range="-150 0" />
          <geom density="2046.3345123130532" friction="0.9830944580349129 0.06305529537650696 0.09276717865494623" name="right_leg" size="0.04 0.25" />
          <body name="right_foot" pos="0.06 0 -0.25">
            <joint damping="0.21874368750138584" name="right_ankle" pos="-0.06 0 0" range="-45 45" />
            <geom density="1687.4449962329427" friction="0.5251367769236304 0.2108118533850299 0.04711688302878535" name="right_foot" size="0.05 0.09883239207765035" zaxis="1 0 0" />
          </body>
        </body>
      </body>
      <body name="left_thigh" pos="0 .05 -0.3">
        <joint damping="0.09887815441350908" name="left_hip" range="-20 100" />
        <geom density="602.3749752367553" friction="0.42106524856570426 0.1413185626157201 0.11957927720268838" name="left_thigh" pos="0 0 -0.225" size="0.05 0.225" />
        <body name="left_leg" pos="0 0 -0.7">
          <joint damping="0.04739484978910555" name="left_knee" pos="0 0 0.25" range="-150 0" />
          <geom density="480.9455055191748" friction="1.4796526301310302 0.09975938692814623 0.07702089587434169" name="left_leg" size="0.04 0.25" />
          <body name="left_foot" pos="0.06 0 -0.25">
            <joint damping="0.20365539843630437" name="left_ankle" pos="-0.06 0 0" range="-45 45" />
            <geom density="1628.7961175165788" friction="0.3404220089128553 0.13867409729039856 0.06506129321695596" name="left_foot" size="0.05 0.1167967694347814" zaxis="1 0 0" />
          </body>
        </body>
      </body>
    </body>
  </worldbody>

  <sensor>
    <subtreelinvel body="torso" name="torso_subtreelinvel" />
  </sensor>

  <actuator>
    <motor gear="100" joint="right_hip" name="right_hip" />
    <motor gear="50" joint="right_knee" name="right_knee" />
    <motor gear="20" joint="right_ankle" name="right_ankle" />
    <motor gear="100" joint="left_hip" name="left_hip" />
    <motor gear="50" joint="left_knee" name="left_knee" />
    <motor gear="20" joint="left_ankle" name="left_ankle" />
  </actuator>
</mujoco>