<mujoco model="planar walker">
  <include file="./common/visual.xml" />
  <include file="./common/skybox.xml" />
  <include file="./common/materials.xml" />

  <option timestep="0.0025" />

  <statistic center="0 0 1" extent="2" />

  <default>
    <joint armature="0.01" damping=".1" limited="true" solimplimit="0 .99 .01" />
    <geom conaffinity="0" contype="1" friction=".7 .1 .1" />
    <motor ctrllimited="true" ctrlrange="-1 1" />
    <site size="0.01" />
    <default class="walker">
      <geom material="self" type="capsule" />
      <joint axis="0 -1 0" />
    </default>
  </default>

  <worldbody>
    <geom conaffinity="1" material="grid" name="floor" pos="248 0 0" size="250 .8 .2" type="plane" zaxis="-0.015909196809278693 0.0 0.9998734407198161" />
    <body childclass="walker" name="torso" pos="0.028204862123772045 0.0 -2.6455061205571524">
      <light mode="trackcom" name="light" pos="0 0 2" />
      <camera euler="60 0 0" mode="trackcom" name="side" pos="0 -2 .7" />
      <camera mode="trackcom" name="back" pos="-2 0 .5" xyaxes="0 -1 0 1 0 3" />
      <joint armature="0" axis="0 0 1" damping="0.12052098286496998" limited="false" name="rootz" type="slide" />
      <joint armature="0" axis="1 0 0" damping="0.09172723562163937" limited="false" name="rootx" type="slide" />
      <joint armature="0" axis="0 1 0" damping="0.05241432033223255" limited="false" name="rooty" type="hinge" />
      <geom density="1902.2988809929004" friction="1.0216119248879239 0.08559356449009875 0.12386947379355649" name="torso" size="0.07 0.3" />
      <body name="right_thigh" pos="0 -.05 -0.3">
        <joint damping="0.0646886407320425" name="right_hip" range="-20 100" />
        <geom density="2146.5940781675426" friction="1.3835081295808849 0.1963237240295611 0.16071341843634457" name="right_thigh" pos="0 0 -0.225" size="0.05 0.225" />
        <body name="right_leg" pos="0 0 -0.7">
          <joint damping="0.14069117163440562" name="right_knee" pos="0 0 0.25" range="-150 0" />
          <geom density="707.9648422896333" friction="0.5973271839643184 0.1400756029152426 0.11471634380507789" name="right_leg" size="0.04 0.25" />
          <body name="right_foot" pos="0.06 0 -0.25">
            <joint damping="0.1683208151916894" name="right_ankle" pos="-0.06 0 0" range="-45 45" />
            <geom density="874.8104696469866" friction="0.9828726693330451 0.06562446137283563 0.06424385372618614" name="right_foot" size="0.05 0.14627829657981165" zaxis="1 0 0" />
          </body>
        </body>
      </body>
      <body name="left_thigh" pos="0 .05 -0.3">
        <joint damping="0.12872303604612934" name="left_hip" range="-20 100" />
        <geom density="892.9594748311703" friction="0.5516083077812659 0.16500169300085354 0.150407743902935" name="left_thigh" pos="0 0 -0.225" size="0.05 0.225" />
        <body name="left_leg" pos="0 0 -0.7">
          <joint damping="0.1055533751752285" name="left_knee" pos="0 0 0.25" range="-150 0" />
          <geom density="1104.129826154727" friction="0.6908374181309612 0.09895080013016228 0.11771137478326939" name="left_leg" size="0.04 0.25" />
          <body name="left_foot" pos="0.06 0 -0.25">
            <joint damping="0.17176339193624432" name="left_ankle" pos="-0.06 0 0" range="-45 45" />
            <geom density="1322.8359614792614" friction="1.303763825247256 0.08590721348246909 0.09521104215307963" name="left_foot" size="0.05 0.04756865466522985" zaxis="1 0 0" />
          </body>
        </body>
      </body>
    </body>
  </worldbody>

  <sensor>
    <subtreelinvel body="torso" name="torso_subtreelinvel" />
  </sensor>

  <actuator>
    <motor gear="100" joint="right_hip" name="right_hip" />
    <motor gear="50" joint="right_knee" name="right_knee" />
    <motor gear="20" joint="right_ankle" name="right_ankle" />
    <motor gear="100" joint="left_hip" name="left_hip" />
    <motor gear="50" joint="left_knee" name="left_knee" />
    <motor gear="20" joint="left_ankle" name="left_ankle" />
  </actuator>
</mujoco>