<mujoco model="planar walker">
  <include file="./common/visual.xml" />
  <include file="./common/skybox.xml" />
  <include file="./common/materials.xml" />

  <option timestep="0.0025" />

  <statistic center="0 0 1" extent="2" />

  <default>
    <joint armature="0.01" damping=".1" limited="true" solimplimit="0 .99 .01" />
    <geom conaffinity="0" contype="1" friction=".7 .1 .1" />
    <motor ctrllimited="true" ctrlrange="-1 1" />
    <site size="0.01" />
    <default class="walker">
      <geom material="self" type="capsule" />
      <joint axis="0 -1 0" />
    </default>
  </default>

  <worldbody>
    <geom conaffinity="1" material="grid" name="floor" pos="248 0 0" size="250 .8 .2" type="plane" zaxis="-0.10604681058546997 0.0 0.9943611386033997" />
    <body childclass="walker" name="torso" pos="1.3772282642397613 0.0 -25.00073679747587">
      <light mode="trackcom" name="light" pos="0 0 2" />
      <camera euler="60 0 0" mode="trackcom" name="side" pos="0 -2 .7" />
      <camera mode="trackcom" name="back" pos="-2 0 .5" xyaxes="0 -1 0 1 0 3" />
      <joint armature="0" axis="0 0 1" damping="0.13565490660431498" limited="false" name="rootz" type="slide" />
      <joint armature="0" axis="1 0 0" damping="0.18719626174344073" limited="false" name="rootx" type="slide" />
      <joint armature="0" axis="0 1 0" damping="0.046678462423552725" limited="false" name="rooty" type="hinge" />
      <geom density="1614.5377803994" friction="0.3449236694445593 0.050212820819628017 0.20723431124833144" name="torso" size="0.07 0.3" />
      <body name="right_thigh" pos="0 -.05 -0.3">
        <joint damping="0.1345845217516178" name="right_hip" range="-20 100" />
        <geom density="2127.6245327703527" friction="0.5563783969510946 0.0641075201188841 0.19057869313175124" name="right_thigh" pos="0 0 -0.225" size="0.05 0.225" />
        <body name="right_leg" pos="0 0 -0.7">
          <joint damping="0.0633138264809201" name="right_knee" pos="0 0 0.25" range="-150 0" />
          <geom density="1709.6535926814975" friction="0.33233593119867516 0.11878242486548769 0.09105127826689696" name="right_leg" size="0.04 0.25" />
          <body name="right_foot" pos="0.06 0 -0.25">
            <joint damping="0.05814875857252472" name="right_ankle" pos="-0.06 0 0" range="-45 45" />
            <geom density="2034.9524928621538" friction="0.8096053109530564 0.20042454881952995 0.2104463258797379" name="right_foot" size="0.05 0.14218977590775775" zaxis="1 0 0" />
          </body>
        </body>
      </body>
      <body name="left_thigh" pos="0 .05 -0.3">
        <joint damping="0.05109330642087841" name="left_hip" range="-20 100" />
        <geom density="1126.2984903948472" friction="0.8215588878096722 0.15070427044671272 0.046020119376655844" name="left_thigh" pos="0 0 -0.225" size="0.05 0.225" />
        <body name="left_leg" pos="0 0 -0.7">
          <joint damping="0.1205082431698533" name="left_knee" pos="0 0 0.25" range="-150 0" />
          <geom density="1281.2724607759963" friction="0.5077514945132174 0.11576385540622357 0.10063837055832413" name="left_leg" size="0.04 0.25" />
          <body name="left_foot" pos="0.06 0 -0.25">
            <joint damping="0.07020832103177334" name="left_ankle" pos="-0.06 0 0" range="-45 45" />
            <geom density="508.12040207667275" friction="0.7043276178976543 0.18334039098360255 0.20874187344812115" name="left_foot" size="0.05 0.11611038715278199" zaxis="1 0 0" />
          </body>
        </body>
      </body>
    </body>
  </worldbody>

  <sensor>
    <subtreelinvel body="torso" name="torso_subtreelinvel" />
  </sensor>

  <actuator>
    <motor gear="100" joint="right_hip" name="right_hip" />
    <motor gear="50" joint="right_knee" name="right_knee" />
    <motor gear="20" joint="right_ankle" name="right_ankle" />
    <motor gear="100" joint="left_hip" name="left_hip" />
    <motor gear="50" joint="left_knee" name="left_knee" />
    <motor gear="20" joint="left_ankle" name="left_ankle" />
  </actuator>
</mujoco>