<mujoco model="planar walker">
  <include file="./common/visual.xml" />
  <include file="./common/skybox.xml" />
  <include file="./common/materials.xml" />

  <option timestep="0.0025" />

  <statistic center="0 0 1" extent="2" />

  <default>
    <joint armature="0.01" damping=".1" limited="true" solimplimit="0 .99 .01" />
    <geom conaffinity="0" contype="1" friction=".7 .1 .1" />
    <motor ctrllimited="true" ctrlrange="-1 1" />
    <site size="0.01" />
    <default class="walker">
      <geom material="self" type="capsule" />
      <joint axis="0 -1 0" />
    </default>
  </default>

  <worldbody>
    <geom conaffinity="1" material="grid" name="floor" pos="248 0 0" size="250 .8 .2" type="plane" zaxis="0.028367974247291632 0.0 0.9995975480347603" />
    <body childclass="walker" name="torso" pos="0.10548168222891263 0.0 8.335177122935276">
      <light mode="trackcom" name="light" pos="0 0 2" />
      <camera euler="60 0 0" mode="trackcom" name="side" pos="0 -2 .7" />
      <camera mode="trackcom" name="back" pos="-2 0 .5" xyaxes="0 -1 0 1 0 3" />
      <joint armature="0" axis="0 0 1" damping="0.14816780185437084" limited="false" name="rootz" type="slide" />
      <joint armature="0" axis="1 0 0" damping="0.047421028531578896" limited="false" name="rootx" type="slide" />
      <joint armature="0" axis="0 1 0" damping="0.0683634012839309" limited="false" name="rooty" type="hinge" />
      <geom density="1345.1823216549171" friction="0.7417716280685124 0.16439562423733947 0.10838421288384217" name="torso" size="0.07 0.3" />
      <body name="right_thigh" pos="0 -.05 -0.3">
        <joint damping="0.11891483543306194" name="right_hip" range="-20 100" />
        <geom density="1625.7265196161757" friction="0.5805839533759252 0.07355726375199997 0.18163176104129822" name="right_thigh" pos="0 0 -0.225" size="0.05 0.225" />
        <body name="right_leg" pos="0 0 -0.7">
          <joint damping="0.045983721745898834" name="right_knee" pos="0 0 0.25" range="-150 0" />
          <geom density="961.9602980721638" friction="0.9150806310888189 0.19690741686579355 0.1530590529433237" name="right_leg" size="0.04 0.25" />
          <body name="right_foot" pos="0.06 0 -0.25">
            <joint damping="0.0765234061398236" name="right_ankle" pos="-0.06 0 0" range="-45 45" />
            <geom density="530.7769819812138" friction="1.1170783815416854 0.04759594554542999 0.2007039361098778" name="right_foot" size="0.05 0.13910214004049412" zaxis="1 0 0" />
          </body>
        </body>
      </body>
      <body name="left_thigh" pos="0 .05 -0.3">
        <joint damping="0.07229197104235359" name="left_hip" range="-20 100" />
        <geom density="694.8314093917006" friction="0.47156742719501904 0.08689370063272638 0.04629228411068493" name="left_thigh" pos="0 0 -0.225" size="0.05 0.225" />
        <body name="left_leg" pos="0 0 -0.7">
          <joint damping="0.0929590411974441" name="left_knee" pos="0 0 0.25" range="-150 0" />
          <geom density="884.4738606223026" friction="0.5691744743563695 0.0900716735264257 0.18521964674668853" name="left_leg" size="0.04 0.25" />
          <body name="left_foot" pos="0.06 0 -0.25">
            <joint damping="0.1744784204893079" name="left_ankle" pos="-0.06 0 0" range="-45 45" />
            <geom density="2064.42659155986" friction="0.9614154523740769 0.049130044996870556 0.05700006778681863" name="left_foot" size="0.05 0.09471604159697349" zaxis="1 0 0" />
          </body>
        </body>
      </body>
    </body>
  </worldbody>

  <sensor>
    <subtreelinvel body="torso" name="torso_subtreelinvel" />
  </sensor>

  <actuator>
    <motor gear="100" joint="right_hip" name="right_hip" />
    <motor gear="50" joint="right_knee" name="right_knee" />
    <motor gear="20" joint="right_ankle" name="right_ankle" />
    <motor gear="100" joint="left_hip" name="left_hip" />
    <motor gear="50" joint="left_knee" name="left_knee" />
    <motor gear="20" joint="left_ankle" name="left_ankle" />
  </actuator>
</mujoco>