<mujoco model="planar walker">
  <include file="./common/visual.xml" />
  <include file="./common/skybox.xml" />
  <include file="./common/materials.xml" />

  <option timestep="0.0025" />

  <statistic center="0 0 1" extent="2" />

  <default>
    <joint armature="0.01" damping=".1" limited="true" solimplimit="0 .99 .01" />
    <geom conaffinity="0" contype="1" friction=".7 .1 .1" />
    <motor ctrllimited="true" ctrlrange="-1 1" />
    <site size="0.01" />
    <default class="walker">
      <geom material="self" type="capsule" />
      <joint axis="0 -1 0" />
    </default>
  </default>

  <worldbody>
    <geom conaffinity="1" material="grid" name="floor" pos="248 0 0" size="250 .8 .2" type="plane" zaxis="-0.16326917406263844 0.0 0.9865815611498645" />
    <body childclass="walker" name="torso" pos="3.2951190000210886 0.0 -39.19343885530436">
      <light mode="trackcom" name="light" pos="0 0 2" />
      <camera euler="60 0 0" mode="trackcom" name="side" pos="0 -2 .7" />
      <camera mode="trackcom" name="back" pos="-2 0 .5" xyaxes="0 -1 0 1 0 3" />
      <joint armature="0" axis="0 0 1" damping="0.05387971382993341" limited="false" name="rootz" type="slide" />
      <joint armature="0" axis="1 0 0" damping="0.1386433820575663" limited="false" name="rootx" type="slide" />
      <joint armature="0" axis="0 1 0" damping="0.06861849844777938" limited="false" name="rooty" type="hinge" />
      <geom density="751.7945267224118" friction="0.3544910552314998 0.13776500145197443 0.2009605025509138" name="torso" size="0.07 0.3" />
      <body name="right_thigh" pos="0 -.05 -0.3">
        <joint damping="0.05751200521893849" name="right_hip" range="-20 100" />
        <geom density="910.4849884048303" friction="0.9864760048859861 0.11318497420640161 0.05210033020074453" name="right_thigh" pos="0 0 -0.225" size="0.05 0.225" />
        <body name="right_leg" pos="0 0 -0.7">
          <joint damping="0.1701880391564407" name="right_knee" pos="0 0 0.25" range="-150 0" />
          <geom density="681.0586984156698" friction="0.6466583737598609 0.07597768994072823 0.12957166403467632" name="right_leg" size="0.04 0.25" />
          <body name="right_foot" pos="0.06 0 -0.25">
            <joint damping="0.06244115576726174" name="right_ankle" pos="-0.06 0 0" range="-45 45" />
            <geom density="1182.7779734813275" friction="1.248867139479154 0.14833272668024153 0.18525983545312524" name="right_foot" size="0.05 0.10323522082242208" zaxis="1 0 0" />
          </body>
        </body>
      </body>
      <body name="left_thigh" pos="0 .05 -0.3">
        <joint damping="0.10763014614763583" name="left_hip" range="-20 100" />
        <geom density="1312.9466860543605" friction="0.9396882229644531 0.1361406125219393 0.1503840509000682" name="left_thigh" pos="0 0 -0.225" size="0.05 0.225" />
        <body name="left_leg" pos="0 0 -0.7">
          <joint damping="0.06244860928607004" name="left_knee" pos="0 0 0.25" range="-150 0" />
          <geom density="657.4556885254713" friction="0.9344042543450395 0.04825457917869849 0.08078131788359914" name="left_leg" size="0.04 0.25" />
          <body name="left_foot" pos="0.06 0 -0.25">
            <joint damping="0.06610101868024014" name="left_ankle" pos="-0.06 0 0" range="-45 45" />
            <geom density="469.59357804798225" friction="0.4812381907047214 0.1599653005475276 0.1889140382661414" name="left_foot" size="0.05 0.07187362128605027" zaxis="1 0 0" />
          </body>
        </body>
      </body>
    </body>
  </worldbody>

  <sensor>
    <subtreelinvel body="torso" name="torso_subtreelinvel" />
  </sensor>

  <actuator>
    <motor gear="100" joint="right_hip" name="right_hip" />
    <motor gear="50" joint="right_knee" name="right_knee" />
    <motor gear="20" joint="right_ankle" name="right_ankle" />
    <motor gear="100" joint="left_hip" name="left_hip" />
    <motor gear="50" joint="left_knee" name="left_knee" />
    <motor gear="20" joint="left_ankle" name="left_ankle" />
  </actuator>
</mujoco>