<mujoco model="planar walker">
  <include file="./common/visual.xml" />
  <include file="./common/skybox.xml" />
  <include file="./common/materials.xml" />

  <option timestep="0.0025" />

  <statistic center="0 0 1" extent="2" />

  <default>
    <joint armature="0.01" damping=".1" limited="true" solimplimit="0 .99 .01" />
    <geom conaffinity="0" contype="1" friction=".7 .1 .1" />
    <motor ctrllimited="true" ctrlrange="-1 1" />
    <site size="0.01" />
    <default class="walker">
      <geom material="self" type="capsule" />
      <joint axis="0 -1 0" />
    </default>
  </default>

  <worldbody>
    <geom conaffinity="1" material="grid" name="floor" pos="248 0 0" size="250 .8 .2" type="plane" zaxis="0.04581264032530426 0.0 0.9989500497954962" />
    <body childclass="walker" name="torso" pos="0.26955017878199783 0.0 12.661324810634554">
      <light mode="trackcom" name="light" pos="0 0 2" />
      <camera euler="60 0 0" mode="trackcom" name="side" pos="0 -2 .7" />
      <camera mode="trackcom" name="back" pos="-2 0 .5" xyaxes="0 -1 0 1 0 3" />
      <joint armature="0" axis="0 0 1" damping="0.13346446574394016" limited="false" name="rootz" type="slide" />
      <joint armature="0" axis="1 0 0" damping="0.061114969934264296" limited="false" name="rootx" type="slide" />
      <joint armature="0" axis="0 1 0" damping="0.055350942373821335" limited="false" name="rooty" type="hinge" />
      <geom density="1106.9111207731041" friction="0.41484534622030256 0.10876889599408551 0.05642257787887006" name="torso" size="0.07 0.3" />
      <body name="right_thigh" pos="0 -.05 -0.3">
        <joint damping="0.08268292337594944" name="right_hip" range="-20 100" />
        <geom density="482.3889498908019" friction="0.5751365479604007 0.05085299914802158 0.08299376642734971" name="right_thigh" pos="0 0 -0.225" size="0.05 0.225" />
        <body name="right_leg" pos="0 0 -0.7">
          <joint damping="0.05077883864351619" name="right_knee" pos="0 0 0.25" range="-150 0" />
          <geom density="807.8305749467602" friction="1.2461535065748925 0.06605905518635917 0.10480435121628207" name="right_leg" size="0.04 0.25" />
          <body name="right_foot" pos="0.06 0 -0.25">
            <joint damping="0.10301279388085274" name="right_ankle" pos="-0.06 0 0" range="-45 45" />
            <geom density="541.942153836156" friction="1.0489833163314568 0.12742137132108577 0.05068206125218147" name="right_foot" size="0.05 0.07575521202598498" zaxis="1 0 0" />
          </body>
        </body>
      </body>
      <body name="left_thigh" pos="0 .05 -0.3">
        <joint damping="0.08984111874649857" name="left_hip" range="-20 100" />
        <geom density="509.1653266465287" friction="0.436397196542708 0.21109904411767622 0.052496489001624874" name="left_thigh" pos="0 0 -0.225" size="0.05 0.225" />
        <body name="left_leg" pos="0 0 -0.7">
          <joint damping="0.17780820309495965" name="left_knee" pos="0 0 0.25" range="-150 0" />
          <geom density="1229.916515277412" friction="0.9491147755795337 0.07937454809926214 0.05424313850457696" name="left_leg" size="0.04 0.25" />
          <body name="left_foot" pos="0.06 0 -0.25">
            <joint damping="0.0492329690958634" name="left_ankle" pos="-0.06 0 0" range="-45 45" />
            <geom density="958.0048079817619" friction="0.368236707768132 0.12623925813228135 0.2062924362695535" name="left_foot" size="0.05 0.05639905388907405" zaxis="1 0 0" />
          </body>
        </body>
      </body>
    </body>
  </worldbody>

  <sensor>
    <subtreelinvel body="torso" name="torso_subtreelinvel" />
  </sensor>

  <actuator>
    <motor gear="100" joint="right_hip" name="right_hip" />
    <motor gear="50" joint="right_knee" name="right_knee" />
    <motor gear="20" joint="right_ankle" name="right_ankle" />
    <motor gear="100" joint="left_hip" name="left_hip" />
    <motor gear="50" joint="left_knee" name="left_knee" />
    <motor gear="20" joint="left_ankle" name="left_ankle" />
  </actuator>
</mujoco>