<mujoco model="planar walker">
  <include file="./common/visual.xml" />
  <include file="./common/skybox.xml" />
  <include file="./common/materials.xml" />

  <option timestep="0.0025" />

  <statistic center="0 0 1" extent="2" />

  <default>
    <joint armature="0.01" damping=".1" limited="true" solimplimit="0 .99 .01" />
    <geom conaffinity="0" contype="1" friction=".7 .1 .1" />
    <motor ctrllimited="true" ctrlrange="-1 1" />
    <site size="0.01" />
    <default class="walker">
      <geom material="self" type="capsule" />
      <joint axis="0 -1 0" />
    </default>
  </default>

  <worldbody>
    <geom conaffinity="1" material="grid" name="floor" pos="248 0 0" size="250 .8 .2" type="plane" zaxis="-0.04645971187921741 0.0 0.9989201645637654" />
    <body childclass="walker" name="torso" pos="0.25850724581033546 0.0 -10.222224513133165">
      <light mode="trackcom" name="light" pos="0 0 2" />
      <camera euler="60 0 0" mode="trackcom" name="side" pos="0 -2 .7" />
      <camera mode="trackcom" name="back" pos="-2 0 .5" xyaxes="0 -1 0 1 0 3" />
      <joint armature="0" axis="0 0 1" damping="0.09762568330316737" limited="false" name="rootz" type="slide" />
      <joint armature="0" axis="1 0 0" damping="0.15237581003685136" limited="false" name="rootx" type="slide" />
      <joint armature="0" axis="0 1 0" damping="0.14962336184585126" limited="false" name="rooty" type="hinge" />
      <geom density="726.7027519878006" friction="0.365452715606116 0.050330558753888234 0.06979462149195358" name="torso" size="0.07 0.3" />
      <body name="right_thigh" pos="0 -.05 -0.3">
        <joint damping="0.06965868990982996" name="right_hip" range="-20 100" />
        <geom density="629.4023370873746" friction="0.7503999550038167 0.06657524628309382 0.11322064521582574" name="right_thigh" pos="0 0 -0.225" size="0.05 0.225" />
        <body name="right_leg" pos="0 0 -0.7">
          <joint damping="0.07066381683046563" name="right_knee" pos="0 0 0.25" range="-150 0" />
          <geom density="523.2426779251575" friction="0.9398609981230234 0.07178512836198156 0.14985569269242782" name="right_leg" size="0.04 0.25" />
          <body name="right_foot" pos="0.06 0 -0.25">
            <joint damping="0.04661366652086003" name="right_ankle" pos="-0.06 0 0" range="-45 45" />
            <geom density="900.7575253115389" friction="0.6376355722962068 0.11277126897654058 0.08279315087729049" name="right_foot" size="0.05 0.08788428867104231" zaxis="1 0 0" />
          </body>
        </body>
      </body>
      <body name="left_thigh" pos="0 .05 -0.3">
        <joint damping="0.09685836844137134" name="left_hip" range="-20 100" />
        <geom density="1845.7458586875832" friction="1.03571960454327 0.12916978973111268 0.14246641077396124" name="left_thigh" pos="0 0 -0.225" size="0.05 0.225" />
        <body name="left_leg" pos="0 0 -0.7">
          <joint damping="0.17506088969724654" name="left_knee" pos="0 0 0.25" range="-150 0" />
          <geom density="529.184818291031" friction="1.2830586191892261 0.05039856504667056 0.13722698381784063" name="left_leg" size="0.04 0.25" />
          <body name="left_foot" pos="0.06 0 -0.25">
            <joint damping="0.16959757275402876" name="left_ankle" pos="-0.06 0 0" range="-45 45" />
            <geom density="1509.8403739084508" friction="1.4679629518424795 0.15420299377083663 0.08301297556080989" name="left_foot" size="0.05 0.09101895484464302" zaxis="1 0 0" />
          </body>
        </body>
      </body>
    </body>
  </worldbody>

  <sensor>
    <subtreelinvel body="torso" name="torso_subtreelinvel" />
  </sensor>

  <actuator>
    <motor gear="100" joint="right_hip" name="right_hip" />
    <motor gear="50" joint="right_knee" name="right_knee" />
    <motor gear="20" joint="right_ankle" name="right_ankle" />
    <motor gear="100" joint="left_hip" name="left_hip" />
    <motor gear="50" joint="left_knee" name="left_knee" />
    <motor gear="20" joint="left_ankle" name="left_ankle" />
  </actuator>
</mujoco>