<mujoco model="planar walker">
  <include file="./common/visual.xml" />
  <include file="./common/skybox.xml" />
  <include file="./common/materials.xml" />

  <option timestep="0.0025" />

  <statistic center="0 0 1" extent="2" />

  <default>
    <joint armature="0.01" damping=".1" limited="true" solimplimit="0 .99 .01" />
    <geom conaffinity="0" contype="1" friction=".7 .1 .1" />
    <motor ctrllimited="true" ctrlrange="-1 1" />
    <site size="0.01" />
    <default class="walker">
      <geom material="self" type="capsule" />
      <joint axis="0 -1 0" />
    </default>
  </default>

  <worldbody>
    <geom conaffinity="1" material="grid" name="floor" pos="248 0 0" size="250 .8 .2" type="plane" zaxis="-0.14472196120980754 0.0 0.989472361384383" />
    <body childclass="walker" name="torso" pos="2.5819099844310642 0.0 -34.59315190775539">
      <light mode="trackcom" name="light" pos="0 0 2" />
      <camera euler="60 0 0" mode="trackcom" name="side" pos="0 -2 .7" />
      <camera mode="trackcom" name="back" pos="-2 0 .5" xyaxes="0 -1 0 1 0 3" />
      <joint armature="0" axis="0 0 1" damping="0.11461688199255349" limited="false" name="rootz" type="slide" />
      <joint armature="0" axis="1 0 0" damping="0.1091013543240924" limited="false" name="rootx" type="slide" />
      <joint armature="0" axis="0 1 0" damping="0.13679633431710067" limited="false" name="rooty" type="hinge" />
      <geom density="897.0727043735118" friction="0.5670071689970358 0.1469462808772554 0.061579993395294685" name="torso" size="0.07 0.3" />
      <body name="right_thigh" pos="0 -.05 -0.3">
        <joint damping="0.0865212082670847" name="right_hip" range="-20 100" />
        <geom density="1097.6110031157154" friction="0.6159638993911913 0.05149108118135168 0.18497275054598314" name="right_thigh" pos="0 0 -0.225" size="0.05 0.225" />
        <body name="right_leg" pos="0 0 -0.7">
          <joint damping="0.2009290639768706" name="right_knee" pos="0 0 0.25" range="-150 0" />
          <geom density="483.4765058828" friction="0.3598111168051604 0.06021504074343349 0.1144439502618167" name="right_leg" size="0.04 0.25" />
          <body name="right_foot" pos="0.06 0 -0.25">
            <joint damping="0.07290252735475779" name="right_ankle" pos="-0.06 0 0" range="-45 45" />
            <geom density="1971.2280645114618" friction="0.6473490173617487 0.06367719638050763 0.07432108300288146" name="right_foot" size="0.05 0.13453446357481505" zaxis="1 0 0" />
          </body>
        </body>
      </body>
      <body name="left_thigh" pos="0 .05 -0.3">
        <joint damping="0.15058703523018935" name="left_hip" range="-20 100" />
        <geom density="1817.8587989810467" friction="0.9928220288550491 0.0962574382327904 0.1323823583673407" name="left_thigh" pos="0 0 -0.225" size="0.05 0.225" />
        <body name="left_leg" pos="0 0 -0.7">
          <joint damping="0.08830439377993093" name="left_knee" pos="0 0 0.25" range="-150 0" />
          <geom density="2091.1782712101717" friction="0.7187299583398289 0.06083827288729692 0.14038516189903347" name="left_leg" size="0.04 0.25" />
          <body name="left_foot" pos="0.06 0 -0.25">
            <joint damping="0.07433991360010621" name="left_ankle" pos="-0.06 0 0" range="-45 45" />
            <geom density="899.22560602054" friction="1.5070047238356319 0.2012538250649384 0.053455977469837435" name="left_foot" size="0.05 0.10535845969753421" zaxis="1 0 0" />
          </body>
        </body>
      </body>
    </body>
  </worldbody>

  <sensor>
    <subtreelinvel body="torso" name="torso_subtreelinvel" />
  </sensor>

  <actuator>
    <motor gear="100" joint="right_hip" name="right_hip" />
    <motor gear="50" joint="right_knee" name="right_knee" />
    <motor gear="20" joint="right_ankle" name="right_ankle" />
    <motor gear="100" joint="left_hip" name="left_hip" />
    <motor gear="50" joint="left_knee" name="left_knee" />
    <motor gear="20" joint="left_ankle" name="left_ankle" />
  </actuator>
</mujoco>