<mujoco model="planar walker">
  <include file="./common/visual.xml" />
  <include file="./common/skybox.xml" />
  <include file="./common/materials.xml" />

  <option timestep="0.0025" />

  <statistic center="0 0 1" extent="2" />

  <default>
    <joint armature="0.01" damping=".1" limited="true" solimplimit="0 .99 .01" />
    <geom conaffinity="0" contype="1" friction=".7 .1 .1" />
    <motor ctrllimited="true" ctrlrange="-1 1" />
    <site size="0.01" />
    <default class="walker">
      <geom material="self" type="capsule" />
      <joint axis="0 -1 0" />
    </default>
  </default>

  <worldbody>
    <geom conaffinity="1" material="grid" name="floor" pos="248 0 0" size="250 .8 .2" type="plane" zaxis="0.13645565882323868 0.0 0.9906461796096101" />
    <body childclass="walker" name="torso" pos="2.3470385885813414 0.0 35.13913262408512">
      <light mode="trackcom" name="light" pos="0 0 2" />
      <camera euler="60 0 0" mode="trackcom" name="side" pos="0 -2 .7" />
      <camera mode="trackcom" name="back" pos="-2 0 .5" xyaxes="0 -1 0 1 0 3" />
      <joint armature="0" axis="0 0 1" damping="0.11058632637199135" limited="false" name="rootz" type="slide" />
      <joint armature="0" axis="1 0 0" damping="0.11349049164785568" limited="false" name="rootx" type="slide" />
      <joint armature="0" axis="0 1 0" damping="0.0555178199181837" limited="false" name="rooty" type="hinge" />
      <geom density="497.29055563782623" friction="0.9566696760357566 0.12610560457855732 0.05250411477234033" name="torso" size="0.07 0.3" />
      <body name="right_thigh" pos="0 -.05 -0.3">
        <joint damping="0.16337182436271358" name="right_hip" range="-20 100" />
        <geom density="1692.3573323094436" friction="1.0530844029510875 0.054728533980492204 0.05480978947677465" name="right_thigh" pos="0 0 -0.225" size="0.05 0.225" />
        <body name="right_leg" pos="0 0 -0.7">
          <joint damping="0.05525189669006275" name="right_knee" pos="0 0 0.25" range="-150 0" />
          <geom density="1067.055834875529" friction="0.8115308607596416 0.11886632627251317 0.05994861029882497" name="right_leg" size="0.04 0.25" />
          <body name="right_foot" pos="0.06 0 -0.25">
            <joint damping="0.11979348037370739" name="right_ankle" pos="-0.06 0 0" range="-45 45" />
            <geom density="904.2109327638028" friction="1.0619027390296985 0.0499733944690392 0.06579468877980593" name="right_foot" size="0.05 0.15885729831697473" zaxis="1 0 0" />
          </body>
        </body>
      </body>
      <body name="left_thigh" pos="0 .05 -0.3">
        <joint damping="0.051009143830119674" name="left_hip" range="-20 100" />
        <geom density="2014.1872939322375" friction="0.5637116997654142 0.11571053189063236 0.1143882643606321" name="left_thigh" pos="0 0 -0.225" size="0.05 0.225" />
        <body name="left_leg" pos="0 0 -0.7">
          <joint damping="0.06566004872124412" name="left_knee" pos="0 0 0.25" range="-150 0" />
          <geom density="1156.7703559287334" friction="0.4589129855951306 0.1725942922965411 0.05556017701424735" name="left_leg" size="0.04 0.25" />
          <body name="left_foot" pos="0.06 0 -0.25">
            <joint damping="0.09448428087296523" name="left_ankle" pos="-0.06 0 0" range="-45 45" />
            <geom density="852.9465411576455" friction="1.1740174924769335 0.08598523117485521 0.20680649850751728" name="left_foot" size="0.05 0.12028293248780678" zaxis="1 0 0" />
          </body>
        </body>
      </body>
    </body>
  </worldbody>

  <sensor>
    <subtreelinvel body="torso" name="torso_subtreelinvel" />
  </sensor>

  <actuator>
    <motor gear="100" joint="right_hip" name="right_hip" />
    <motor gear="50" joint="right_knee" name="right_knee" />
    <motor gear="20" joint="right_ankle" name="right_ankle" />
    <motor gear="100" joint="left_hip" name="left_hip" />
    <motor gear="50" joint="left_knee" name="left_knee" />
    <motor gear="20" joint="left_ankle" name="left_ankle" />
  </actuator>
</mujoco>