<mujoco model="planar walker">
  <include file="./common/visual.xml" />
  <include file="./common/skybox.xml" />
  <include file="./common/materials.xml" />

  <option timestep="0.0025" />

  <statistic center="0 0 1" extent="2" />

  <default>
    <joint armature="0.01" damping=".1" limited="true" solimplimit="0 .99 .01" />
    <geom conaffinity="0" contype="1" friction=".7 .1 .1" />
    <motor ctrllimited="true" ctrlrange="-1 1" />
    <site size="0.01" />
    <default class="walker">
      <geom material="self" type="capsule" />
      <joint axis="0 -1 0" />
    </default>
  </default>

  <worldbody>
    <geom conaffinity="1" material="grid" name="floor" pos="248 0 0" size="250 .8 .2" type="plane" zaxis="0.1545426280495739 0.0 0.9879861214184797" />
    <body childclass="walker" name="torso" pos="3.0103504138269273 0.0 39.62416898057802">
      <light mode="trackcom" name="light" pos="0 0 2" />
      <camera euler="60 0 0" mode="trackcom" name="side" pos="0 -2 .7" />
      <camera mode="trackcom" name="back" pos="-2 0 .5" xyaxes="0 -1 0 1 0 3" />
      <joint armature="0" axis="0 0 1" damping="0.14079905956345362" limited="false" name="rootz" type="slide" />
      <joint armature="0" axis="1 0 0" damping="0.21763966539474866" limited="false" name="rootx" type="slide" />
      <joint armature="0" axis="0 1 0" damping="0.053300358031218714" limited="false" name="rooty" type="hinge" />
      <geom density="1963.9704598476424" friction="1.0645643584192734 0.08555357924462226 0.18146262989364062" name="torso" size="0.07 0.3" />
      <body name="right_thigh" pos="0 -.05 -0.3">
        <joint damping="0.1060179707790814" name="right_hip" range="-20 100" />
        <geom density="2044.8696748918667" friction="1.1640116241375869 0.08492301209313118 0.05680378052259284" name="right_thigh" pos="0 0 -0.225" size="0.05 0.225" />
        <body name="right_leg" pos="0 0 -0.7">
          <joint damping="0.1557662211439121" name="right_knee" pos="0 0 0.25" range="-150 0" />
          <geom density="1940.5350034035948" friction="0.3293886111159542 0.10770184033785049 0.08955748974457707" name="right_leg" size="0.04 0.25" />
          <body name="right_foot" pos="0.06 0 -0.25">
            <joint damping="0.11182269091622908" name="right_ankle" pos="-0.06 0 0" range="-45 45" />
            <geom density="1815.79082985139" friction="1.1746399635537632 0.09307340844055532 0.1358041506483344" name="right_foot" size="0.05 0.17153230549314422" zaxis="1 0 0" />
          </body>
        </body>
      </body>
      <body name="left_thigh" pos="0 .05 -0.3">
        <joint damping="0.1590762670322612" name="left_hip" range="-20 100" />
        <geom density="564.3985713081803" friction="0.3510241483098415 0.09066840690259503 0.06517416199917157" name="left_thigh" pos="0 0 -0.225" size="0.05 0.225" />
        <body name="left_leg" pos="0 0 -0.7">
          <joint damping="0.04966879087832668" name="left_knee" pos="0 0 0.25" range="-150 0" />
          <geom density="1127.4270977179874" friction="1.4292511480415697 0.15919282511934693 0.10045487166200445" name="left_leg" size="0.04 0.25" />
          <body name="left_foot" pos="0.06 0 -0.25">
            <joint damping="0.1704243913270192" name="left_ankle" pos="-0.06 0 0" range="-45 45" />
            <geom density="1115.7075298794798" friction="0.5772216477338149 0.0840734988027085 0.09084664093963457" name="left_foot" size="0.05 0.1269890738475087" zaxis="1 0 0" />
          </body>
        </body>
      </body>
    </body>
  </worldbody>

  <sensor>
    <subtreelinvel body="torso" name="torso_subtreelinvel" />
  </sensor>

  <actuator>
    <motor gear="100" joint="right_hip" name="right_hip" />
    <motor gear="50" joint="right_knee" name="right_knee" />
    <motor gear="20" joint="right_ankle" name="right_ankle" />
    <motor gear="100" joint="left_hip" name="left_hip" />
    <motor gear="50" joint="left_knee" name="left_knee" />
    <motor gear="20" joint="left_ankle" name="left_ankle" />
  </actuator>
</mujoco>