<mujoco model="planar walker">
  <include file="./common/visual.xml" />
  <include file="./common/skybox.xml" />
  <include file="./common/materials.xml" />

  <option timestep="0.0025" />

  <statistic center="0 0 1" extent="2" />

  <default>
    <joint armature="0.01" damping=".1" limited="true" solimplimit="0 .99 .01" />
    <geom conaffinity="0" contype="1" friction=".7 .1 .1" />
    <motor ctrllimited="true" ctrlrange="-1 1" />
    <site size="0.01" />
    <default class="walker">
      <geom material="self" type="capsule" />
      <joint axis="0 -1 0" />
    </default>
  </default>

  <worldbody>
    <geom conaffinity="1" material="grid" name="floor" pos="248 0 0" size="250 .8 .2" type="plane" zaxis="-0.03983937623815982 0.0 0.9992060969094185" />
    <body childclass="walker" name="torso" pos="0.18892009121657338 0.0 -8.58032408768175">
      <light mode="trackcom" name="light" pos="0 0 2" />
      <camera euler="60 0 0" mode="trackcom" name="side" pos="0 -2 .7" />
      <camera mode="trackcom" name="back" pos="-2 0 .5" xyaxes="0 -1 0 1 0 3" />
      <joint armature="0" axis="0 0 1" damping="0.165954076339407" limited="false" name="rootz" type="slide" />
      <joint armature="0" axis="1 0 0" damping="0.0895061117570421" limited="false" name="rootx" type="slide" />
      <joint armature="0" axis="0 1 0" damping="0.10636502405419593" limited="false" name="rooty" type="hinge" />
      <geom density="890.651395168247" friction="0.9288374735324484 0.20312943026551922 0.09116114024604867" name="torso" size="0.07 0.3" />
      <body name="right_thigh" pos="0 -.05 -0.3">
        <joint damping="0.1588777969475982" name="right_hip" range="-20 100" />
        <geom density="468.80302063981645" friction="0.8686641221352014 0.15015670399720288 0.08399149843121778" name="right_thigh" pos="0 0 -0.225" size="0.05 0.225" />
        <body name="right_leg" pos="0 0 -0.7">
          <joint damping="0.12340982033366235" name="right_knee" pos="0 0 0.25" range="-150 0" />
          <geom density="2037.9056096983636" friction="1.4608683010176544 0.09650134989977954 0.1504951349383474" name="right_leg" size="0.04 0.25" />
          <body name="right_foot" pos="0.06 0 -0.25">
            <joint damping="0.08704178012212166" name="right_ankle" pos="-0.06 0 0" range="-45 45" />
            <geom density="1464.6871129131093" friction="0.9660429247150865 0.07508902235806875 0.2142812459534067" name="right_foot" size="0.05 0.09555085811911249" zaxis="1 0 0" />
          </body>
        </body>
      </body>
      <body name="left_thigh" pos="0 .05 -0.3">
        <joint damping="0.1625037318309188" name="left_hip" range="-20 100" />
        <geom density="636.2926844769777" friction="0.5316667330809275 0.11599932702032728 0.13047729923286955" name="left_thigh" pos="0 0 -0.225" size="0.05 0.225" />
        <body name="left_leg" pos="0 0 -0.7">
          <joint damping="0.18955040954100433" name="left_knee" pos="0 0 0.25" range="-150 0" />
          <geom density="1478.778501521153" friction="0.5368661883556656 0.16788634407950898 0.12507331860442672" name="left_leg" size="0.04 0.25" />
          <body name="left_foot" pos="0.06 0 -0.25">
            <joint damping="0.07236483800491848" name="left_ankle" pos="-0.06 0 0" range="-45 45" />
            <geom density="514.2006175973313" friction="0.912891871512576 0.07549568706285487 0.13246617192324026" name="left_foot" size="0.05 0.09914811820549191" zaxis="1 0 0" />
          </body>
        </body>
      </body>
    </body>
  </worldbody>

  <sensor>
    <subtreelinvel body="torso" name="torso_subtreelinvel" />
  </sensor>

  <actuator>
    <motor gear="100" joint="right_hip" name="right_hip" />
    <motor gear="50" joint="right_knee" name="right_knee" />
    <motor gear="20" joint="right_ankle" name="right_ankle" />
    <motor gear="100" joint="left_hip" name="left_hip" />
    <motor gear="50" joint="left_knee" name="left_knee" />
    <motor gear="20" joint="left_ankle" name="left_ankle" />
  </actuator>
</mujoco>