<mujoco model="planar walker">
  <include file="./common/visual.xml" />
  <include file="./common/skybox.xml" />
  <include file="./common/materials.xml" />

  <option timestep="0.0025" />

  <statistic center="0 0 1" extent="2" />

  <default>
    <joint armature="0.01" damping=".1" limited="true" solimplimit="0 .99 .01" />
    <geom conaffinity="0" contype="1" friction=".7 .1 .1" />
    <motor ctrllimited="true" ctrlrange="-1 1" />
    <site size="0.01" />
    <default class="walker">
      <geom material="self" type="capsule" />
      <joint axis="0 -1 0" />
    </default>
  </default>

  <worldbody>
    <geom conaffinity="1" material="grid" name="floor" pos="248 0 0" size="250 .8 .2" type="plane" zaxis="0.13449127108626419 0.0 0.9909147783748111" />
    <body childclass="walker" name="torso" pos="2.280033217264105 0.0 34.65201818506848">
      <light mode="trackcom" name="light" pos="0 0 2" />
      <camera euler="60 0 0" mode="trackcom" name="side" pos="0 -2 .7" />
      <camera mode="trackcom" name="back" pos="-2 0 .5" xyaxes="0 -1 0 1 0 3" />
      <joint armature="0" axis="0 0 1" damping="0.05445440470833133" limited="false" name="rootz" type="slide" />
      <joint armature="0" axis="1 0 0" damping="0.04894011466856702" limited="false" name="rootx" type="slide" />
      <joint armature="0" axis="0 1 0" damping="0.1816096231455756" limited="false" name="rooty" type="hinge" />
      <geom density="685.2885745774249" friction="0.35797959367775983 0.18829963824251283 0.1157072822512258" name="torso" size="0.07 0.3" />
      <body name="right_thigh" pos="0 -.05 -0.3">
        <joint damping="0.05238079793324222" name="right_hip" range="-20 100" />
        <geom density="1292.4887943664917" friction="0.33957700476941316 0.10354627178493654 0.16539234305680117" name="right_thigh" pos="0 0 -0.225" size="0.05 0.225" />
        <body name="right_leg" pos="0 0 -0.7">
          <joint damping="0.04734166579526971" name="right_knee" pos="0 0 0.25" range="-150 0" />
          <geom density="688.3113992783741" friction="0.7841562194486117 0.07577570046649439 0.1985957011771434" name="right_leg" size="0.04 0.25" />
          <body name="right_foot" pos="0.06 0 -0.25">
            <joint damping="0.1110491173762077" name="right_ankle" pos="-0.06 0 0" range="-45 45" />
            <geom density="663.9606313769414" friction="1.0688350973944931 0.08358400518206077 0.18868167809382408" name="right_foot" size="0.05 0.07349749734594199" zaxis="1 0 0" />
          </body>
        </body>
      </body>
      <body name="left_thigh" pos="0 .05 -0.3">
        <joint damping="0.05433421125482463" name="left_hip" range="-20 100" />
        <geom density="1116.236479089523" friction="1.4929790313050932 0.07396909247374363 0.18457939452050426" name="left_thigh" pos="0 0 -0.225" size="0.05 0.225" />
        <body name="left_leg" pos="0 0 -0.7">
          <joint damping="0.047623167277299205" name="left_knee" pos="0 0 0.25" range="-150 0" />
          <geom density="1754.9437293527387" friction="0.6784396333500817 0.14893673975938682 0.20243371979178348" name="left_leg" size="0.04 0.25" />
          <body name="left_foot" pos="0.06 0 -0.25">
            <joint damping="0.1689197683863175" name="left_ankle" pos="-0.06 0 0" range="-45 45" />
            <geom density="1471.9951543224156" friction="0.7867727032637878 0.1989782048327742 0.061408465464704146" name="left_foot" size="0.05 0.07117405017032787" zaxis="1 0 0" />
          </body>
        </body>
      </body>
    </body>
  </worldbody>

  <sensor>
    <subtreelinvel body="torso" name="torso_subtreelinvel" />
  </sensor>

  <actuator>
    <motor gear="100" joint="right_hip" name="right_hip" />
    <motor gear="50" joint="right_knee" name="right_knee" />
    <motor gear="20" joint="right_ankle" name="right_ankle" />
    <motor gear="100" joint="left_hip" name="left_hip" />
    <motor gear="50" joint="left_knee" name="left_knee" />
    <motor gear="20" joint="left_ankle" name="left_ankle" />
  </actuator>
</mujoco>