<mujoco model="planar walker">
  <include file="./common/visual.xml" />
  <include file="./common/skybox.xml" />
  <include file="./common/materials.xml" />

  <option timestep="0.0025" />

  <statistic center="0 0 1" extent="2" />

  <default>
    <joint armature="0.01" damping=".1" limited="true" solimplimit="0 .99 .01" />
    <geom conaffinity="0" contype="1" friction=".7 .1 .1" />
    <motor ctrllimited="true" ctrlrange="-1 1" />
    <site size="0.01" />
    <default class="walker">
      <geom material="self" type="capsule" />
      <joint axis="0 -1 0" />
    </default>
  </default>

  <worldbody>
    <geom conaffinity="1" material="grid" name="floor" pos="248 0 0" size="250 .8 .2" type="plane" zaxis="0.158150372670654 0.0 0.9874150391928074" />
    <body childclass="walker" name="torso" pos="3.1527003547178936 0.0 40.51877543016075">
      <light mode="trackcom" name="light" pos="0 0 2" />
      <camera euler="60 0 0" mode="trackcom" name="side" pos="0 -2 .7" />
      <camera mode="trackcom" name="back" pos="-2 0 .5" xyaxes="0 -1 0 1 0 3" />
      <joint armature="0" axis="0 0 1" damping="0.09764007980868276" limited="false" name="rootz" type="slide" />
      <joint armature="0" axis="1 0 0" damping="0.08167981548898323" limited="false" name="rootx" type="slide" />
      <joint armature="0" axis="0 1 0" damping="0.11190210010983107" limited="false" name="rooty" type="hinge" />
      <geom density="1861.2565054656554" friction="1.536125598290269 0.07031458516722941 0.1742305638627839" name="torso" size="0.07 0.3" />
      <body name="right_thigh" pos="0 -.05 -0.3">
        <joint damping="0.1782805994070129" name="right_hip" range="-20 100" />
        <geom density="1815.7795448703741" friction="0.46912262391644866 0.12522707561211618 0.1487422478081408" name="right_thigh" pos="0 0 -0.225" size="0.05 0.225" />
        <body name="right_leg" pos="0 0 -0.7">
          <joint damping="0.11195169540873105" name="right_knee" pos="0 0 0.25" range="-150 0" />
          <geom density="881.5620808731564" friction="1.2923933770445164 0.06636012937966901 0.059030874146692426" name="right_leg" size="0.04 0.25" />
          <body name="right_foot" pos="0.06 0 -0.25">
            <joint damping="0.18341919777964633" name="right_ankle" pos="-0.06 0 0" range="-45 45" />
            <geom density="1648.317502423548" friction="0.8362011130934066 0.048689340309693324 0.21676912329368236" name="right_foot" size="0.05 0.05284028086821122" zaxis="1 0 0" />
          </body>
        </body>
      </body>
      <body name="left_thigh" pos="0 .05 -0.3">
        <joint damping="0.21018093009078953" name="left_hip" range="-20 100" />
        <geom density="847.2953198743805" friction="0.38151597205106497 0.16473005217828499 0.07865581290872313" name="left_thigh" pos="0 0 -0.225" size="0.05 0.225" />
        <body name="left_leg" pos="0 0 -0.7">
          <joint damping="0.052616039369054235" name="left_knee" pos="0 0 0.25" range="-150 0" />
          <geom density="547.4167582740556" friction="1.447516857053496 0.09196828757554555 0.04979482268488085" name="left_leg" size="0.04 0.25" />
          <body name="left_foot" pos="0.06 0 -0.25">
            <joint damping="0.09794309302249646" name="left_ankle" pos="-0.06 0 0" range="-45 45" />
            <geom density="507.22347915131905" friction="1.4276632894200028 0.2130115700265265 0.13364828020735442" name="left_foot" size="0.05 0.09216277345221548" zaxis="1 0 0" />
          </body>
        </body>
      </body>
    </body>
  </worldbody>

  <sensor>
    <subtreelinvel body="torso" name="torso_subtreelinvel" />
  </sensor>

  <actuator>
    <motor gear="100" joint="right_hip" name="right_hip" />
    <motor gear="50" joint="right_knee" name="right_knee" />
    <motor gear="20" joint="right_ankle" name="right_ankle" />
    <motor gear="100" joint="left_hip" name="left_hip" />
    <motor gear="50" joint="left_knee" name="left_knee" />
    <motor gear="20" joint="left_ankle" name="left_ankle" />
  </actuator>
</mujoco>