<mujoco model="planar walker">
  <include file="./common/visual.xml" />
  <include file="./common/skybox.xml" />
  <include file="./common/materials.xml" />

  <option timestep="0.0025" />

  <statistic center="0 0 1" extent="2" />

  <default>
    <joint armature="0.01" damping=".1" limited="true" solimplimit="0 .99 .01" />
    <geom conaffinity="0" contype="1" friction=".7 .1 .1" />
    <motor ctrllimited="true" ctrlrange="-1 1" />
    <site size="0.01" />
    <default class="walker">
      <geom material="self" type="capsule" />
      <joint axis="0 -1 0" />
    </default>
  </default>

  <worldbody>
    <geom conaffinity="1" material="grid" name="floor" pos="248 0 0" size="250 .8 .2" type="plane" zaxis="-0.06694182364819143 0.0 0.9977568803304011" />
    <body childclass="walker" name="torso" pos="0.5429053133308628 0.0 -15.302020888685396">
      <light mode="trackcom" name="light" pos="0 0 2" />
      <camera euler="60 0 0" mode="trackcom" name="side" pos="0 -2 .7" />
      <camera mode="trackcom" name="back" pos="-2 0 .5" xyaxes="0 -1 0 1 0 3" />
      <joint armature="0" axis="0 0 1" damping="0.09059626796556093" limited="false" name="rootz" type="slide" />
      <joint armature="0" axis="1 0 0" damping="0.06551137069624806" limited="false" name="rootx" type="slide" />
      <joint armature="0" axis="0 1 0" damping="0.10003690320644965" limited="false" name="rooty" type="hinge" />
      <geom density="1340.7992849113255" friction="1.0822573984534358 0.16447829748437626 0.12251534163356677" name="torso" size="0.07 0.3" />
      <body name="right_thigh" pos="0 -.05 -0.3">
        <joint damping="0.13962546640331175" name="right_hip" range="-20 100" />
        <geom density="1043.9667779779547" friction="0.4289903786328378 0.06602980072457357 0.07839705356271529" name="right_thigh" pos="0 0 -0.225" size="0.05 0.225" />
        <body name="right_leg" pos="0 0 -0.7">
          <joint damping="0.09731830121266555" name="right_knee" pos="0 0 0.25" range="-150 0" />
          <geom density="1750.8969673888016" friction="1.4972051671934328 0.16330515026027184 0.049341841698043426" name="right_leg" size="0.04 0.25" />
          <body name="right_foot" pos="0.06 0 -0.25">
            <joint damping="0.09392529059573272" name="right_ankle" pos="-0.06 0 0" range="-45 45" />
            <geom density="1156.1082027161885" friction="1.3162529693678422 0.06329919590067831 0.18988375723954165" name="right_foot" size="0.05 0.13344471785408754" zaxis="1 0 0" />
          </body>
        </body>
      </body>
      <body name="left_thigh" pos="0 .05 -0.3">
        <joint damping="0.12561477516960393" name="left_hip" range="-20 100" />
        <geom density="2192.708695927941" friction="0.9778105666535982 0.21091105463612672 0.050575408681044265" name="left_thigh" pos="0 0 -0.225" size="0.05 0.225" />
        <body name="left_leg" pos="0 0 -0.7">
          <joint damping="0.21485816398300772" name="left_knee" pos="0 0 0.25" range="-150 0" />
          <geom density="903.9331485377514" friction="0.6850549260172897 0.1410544864382096 0.1572122903112642" name="left_leg" size="0.04 0.25" />
          <body name="left_foot" pos="0.06 0 -0.25">
            <joint damping="0.13320567222094168" name="left_ankle" pos="-0.06 0 0" range="-45 45" />
            <geom density="588.7115006918926" friction="0.6414377270114495 0.06288044423688624 0.11036343068894115" name="left_foot" size="0.05 0.08424911342476782" zaxis="1 0 0" />
          </body>
        </body>
      </body>
    </body>
  </worldbody>

  <sensor>
    <subtreelinvel body="torso" name="torso_subtreelinvel" />
  </sensor>

  <actuator>
    <motor gear="100" joint="right_hip" name="right_hip" />
    <motor gear="50" joint="right_knee" name="right_knee" />
    <motor gear="20" joint="right_ankle" name="right_ankle" />
    <motor gear="100" joint="left_hip" name="left_hip" />
    <motor gear="50" joint="left_knee" name="left_knee" />
    <motor gear="20" joint="left_ankle" name="left_ankle" />
  </actuator>
</mujoco>