<mujoco model="planar walker">
  <include file="./common/visual.xml" />
  <include file="./common/skybox.xml" />
  <include file="./common/materials.xml" />

  <option timestep="0.0025" />

  <statistic center="0 0 1" extent="2" />

  <default>
    <joint armature="0.01" damping=".1" limited="true" solimplimit="0 .99 .01" />
    <geom conaffinity="0" contype="1" friction=".7 .1 .1" />
    <motor ctrllimited="true" ctrlrange="-1 1" />
    <site size="0.01" />
    <default class="walker">
      <geom material="self" type="capsule" />
      <joint axis="0 -1 0" />
    </default>
  </default>

  <worldbody>
    <geom conaffinity="1" material="grid" name="floor" pos="248 0 0" size="250 .8 .2" type="plane" zaxis="0.10996575885554531 0.0 0.9939353761081875" />
    <body childclass="walker" name="torso" pos="1.5260198769406088 0.0 28.570295271396876">
      <light mode="trackcom" name="light" pos="0 0 2" />
      <camera euler="60 0 0" mode="trackcom" name="side" pos="0 -2 .7" />
      <camera mode="trackcom" name="back" pos="-2 0 .5" xyaxes="0 -1 0 1 0 3" />
      <joint armature="0" axis="0 0 1" damping="0.07138621783219362" limited="false" name="rootz" type="slide" />
      <joint armature="0" axis="1 0 0" damping="0.10844687177860612" limited="false" name="rootx" type="slide" />
      <joint armature="0" axis="0 1 0" damping="0.14510156158413104" limited="false" name="rooty" type="hinge" />
      <geom density="1398.0570414558122" friction="1.1582526582494184 0.17661004075151288 0.07684714379879422" name="torso" size="0.07 0.3" />
      <body name="right_thigh" pos="0 -.05 -0.3">
        <joint damping="0.06310372423978454" name="right_hip" range="-20 100" />
        <geom density="492.7108123612716" friction="0.48939933207743236 0.13924127206301268 0.06568291375555148" name="right_thigh" pos="0 0 -0.225" size="0.05 0.225" />
        <body name="right_leg" pos="0 0 -0.7">
          <joint damping="0.17933189130112115" name="right_knee" pos="0 0 0.25" range="-150 0" />
          <geom density="720.1004686898341" friction="1.2422111196432186 0.12160042340434224 0.06241882310715141" name="right_leg" size="0.04 0.25" />
          <body name="right_foot" pos="0.06 0 -0.25">
            <joint damping="0.2022074359045629" name="right_ankle" pos="-0.06 0 0" range="-45 45" />
            <geom density="1536.373883111725" friction="0.49559810185130493 0.11554676914496607 0.04980875669900232" name="right_foot" size="0.05 0.21865197030115058" zaxis="1 0 0" />
          </body>
        </body>
      </body>
      <body name="left_thigh" pos="0 .05 -0.3">
        <joint damping="0.08293904704460876" name="left_hip" range="-20 100" />
        <geom density="1436.2861785561229" friction="0.5980328525727866 0.21309648054901598 0.14042961744982532" name="left_thigh" pos="0 0 -0.225" size="0.05 0.225" />
        <body name="left_leg" pos="0 0 -0.7">
          <joint damping="0.06756365755496863" name="left_knee" pos="0 0 0.25" range="-150 0" />
          <geom density="931.0967889155874" friction="0.7489543190422974 0.06118320019190581 0.21922150676250063" name="left_leg" size="0.04 0.25" />
          <body name="left_foot" pos="0.06 0 -0.25">
            <joint damping="0.09842948998981368" name="left_ankle" pos="-0.06 0 0" range="-45 45" />
            <geom density="1985.7173866231967" friction="1.5293034316061953 0.052304496659599624 0.20861904132937337" name="left_foot" size="0.05 0.12441248523018925" zaxis="1 0 0" />
          </body>
        </body>
      </body>
    </body>
  </worldbody>

  <sensor>
    <subtreelinvel body="torso" name="torso_subtreelinvel" />
  </sensor>

  <actuator>
    <motor gear="100" joint="right_hip" name="right_hip" />
    <motor gear="50" joint="right_knee" name="right_knee" />
    <motor gear="20" joint="right_ankle" name="right_ankle" />
    <motor gear="100" joint="left_hip" name="left_hip" />
    <motor gear="50" joint="left_knee" name="left_knee" />
    <motor gear="20" joint="left_ankle" name="left_ankle" />
  </actuator>
</mujoco>