<mujoco model="planar walker">
  <include file="./common/visual.xml" />
  <include file="./common/skybox.xml" />
  <include file="./common/materials.xml" />

  <option timestep="0.0025" />

  <statistic center="0 0 1" extent="2" />

  <default>
    <joint armature="0.01" damping=".1" limited="true" solimplimit="0 .99 .01" />
    <geom conaffinity="0" contype="1" friction=".7 .1 .1" />
    <motor ctrllimited="true" ctrlrange="-1 1" />
    <site size="0.01" />
    <default class="walker">
      <geom material="self" type="capsule" />
      <joint axis="0 -1 0" />
    </default>
  </default>

  <worldbody>
    <geom conaffinity="1" material="grid" name="floor" pos="248 0 0" size="250 .8 .2" type="plane" zaxis="0.08829771534001707 0.0 0.9960941288180215" />
    <body childclass="walker" name="torso" pos="0.9863155961986649 0.0 23.197052230087838">
      <light mode="trackcom" name="light" pos="0 0 2" />
      <camera euler="60 0 0" mode="trackcom" name="side" pos="0 -2 .7" />
      <camera mode="trackcom" name="back" pos="-2 0 .5" xyaxes="0 -1 0 1 0 3" />
      <joint armature="0" axis="0 0 1" damping="0.05103832715726572" limited="false" name="rootz" type="slide" />
      <joint armature="0" axis="1 0 0" damping="0.14524821076663183" limited="false" name="rootx" type="slide" />
      <joint armature="0" axis="0 1 0" damping="0.12273852046100482" limited="false" name="rooty" type="hinge" />
      <geom density="1766.8937121440702" friction="1.2167503653684097 0.06473805954617182 0.04562618288231683" name="torso" size="0.07 0.3" />
      <body name="right_thigh" pos="0 -.05 -0.3">
        <joint damping="0.1658765104006788" name="right_hip" range="-20 100" />
        <geom density="682.3445474344443" friction="0.6328423573281657 0.057839464260544274 0.062127645829741555" name="right_thigh" pos="0 0 -0.225" size="0.05 0.225" />
        <body name="right_leg" pos="0 0 -0.7">
          <joint damping="0.06577770042746747" name="right_knee" pos="0 0 0.25" range="-150 0" />
          <geom density="654.3587019322345" friction="1.2032332073805108 0.08425229796334739 0.16219697398012334" name="right_leg" size="0.04 0.25" />
          <body name="right_foot" pos="0.06 0 -0.25">
            <joint damping="0.1938775519106867" name="right_ankle" pos="-0.06 0 0" range="-45 45" />
            <geom density="629.524286460663" friction="1.4195994866551704 0.11398437305443161 0.05698247251072252" name="right_foot" size="0.05 0.11712876900140633" zaxis="1 0 0" />
          </body>
        </body>
      </body>
      <body name="left_thigh" pos="0 .05 -0.3">
        <joint damping="0.1945566640850549" name="left_hip" range="-20 100" />
        <geom density="944.0822637404358" friction="0.4493015254933575 0.09377697209019831 0.047640011574662126" name="left_thigh" pos="0 0 -0.225" size="0.05 0.225" />
        <body name="left_leg" pos="0 0 -0.7">
          <joint damping="0.13542112074376947" name="left_knee" pos="0 0 0.25" range="-150 0" />
          <geom density="2000.756207651302" friction="0.3998546228987402 0.07625410810931896 0.09871996887932288" name="left_leg" size="0.04 0.25" />
          <body name="left_foot" pos="0.06 0 -0.25">
            <joint damping="0.1358036561296508" name="left_ankle" pos="-0.06 0 0" range="-45 45" />
            <geom density="593.4627018608476" friction="1.350336088201467 0.09618806814029539 0.09215526438419874" name="left_foot" size="0.05 0.12334600696908696" zaxis="1 0 0" />
          </body>
        </body>
      </body>
    </body>
  </worldbody>

  <sensor>
    <subtreelinvel body="torso" name="torso_subtreelinvel" />
  </sensor>

  <actuator>
    <motor gear="100" joint="right_hip" name="right_hip" />
    <motor gear="50" joint="right_knee" name="right_knee" />
    <motor gear="20" joint="right_ankle" name="right_ankle" />
    <motor gear="100" joint="left_hip" name="left_hip" />
    <motor gear="50" joint="left_knee" name="left_knee" />
    <motor gear="20" joint="left_ankle" name="left_ankle" />
  </actuator>
</mujoco>