<mujoco model="planar walker">
  <include file="./common/visual.xml" />
  <include file="./common/skybox.xml" />
  <include file="./common/materials.xml" />

  <option timestep="0.0025" />

  <statistic center="0 0 1" extent="2" />

  <default>
    <joint armature="0.01" damping=".1" limited="true" solimplimit="0 .99 .01" />
    <geom conaffinity="0" contype="1" friction=".7 .1 .1" />
    <motor ctrllimited="true" ctrlrange="-1 1" />
    <site size="0.01" />
    <default class="walker">
      <geom material="self" type="capsule" />
      <joint axis="0 -1 0" />
    </default>
  </default>

  <worldbody>
    <geom conaffinity="1" material="grid" name="floor" pos="248 0 0" size="250 .8 .2" type="plane" zaxis="0.08356946449934233 0.0 0.9965019541392245" />
    <body childclass="walker" name="torso" pos="0.8842292663721878 0.0 22.024527586664743">
      <light mode="trackcom" name="light" pos="0 0 2" />
      <camera euler="60 0 0" mode="trackcom" name="side" pos="0 -2 .7" />
      <camera mode="trackcom" name="back" pos="-2 0 .5" xyaxes="0 -1 0 1 0 3" />
      <joint armature="0" axis="0 0 1" damping="0.10719085684646851" limited="false" name="rootz" type="slide" />
      <joint armature="0" axis="1 0 0" damping="0.08484458833408434" limited="false" name="rootx" type="slide" />
      <joint armature="0" axis="0 1 0" damping="0.06676181647309007" limited="false" name="rooty" type="hinge" />
      <geom density="1342.9182645056087" friction="1.0075241468297602 0.067213999950217 0.09169357320206804" name="torso" size="0.07 0.3" />
      <body name="right_thigh" pos="0 -.05 -0.3">
        <joint damping="0.05312894495433573" name="right_hip" range="-20 100" />
        <geom density="1342.134200857783" friction="0.5363384432008208 0.10533992386344289 0.05545986822304016" name="right_thigh" pos="0 0 -0.225" size="0.05 0.225" />
        <body name="right_leg" pos="0 0 -0.7">
          <joint damping="0.06076934600327108" name="right_knee" pos="0 0 0.25" range="-150 0" />
          <geom density="1012.672162574273" friction="0.3887418955444305 0.055071351394172796 0.11941269801480817" name="right_leg" size="0.04 0.25" />
          <body name="right_foot" pos="0.06 0 -0.25">
            <joint damping="0.15371355184521204" name="right_ankle" pos="-0.06 0 0" range="-45 45" />
            <geom density="732.4495999937631" friction="1.2857545005398936 0.10222642566800036 0.07658157383700183" name="right_foot" size="0.05 0.12145050268553559" zaxis="1 0 0" />
          </body>
        </body>
      </body>
      <body name="left_thigh" pos="0 .05 -0.3">
        <joint damping="0.12376649599442194" name="left_hip" range="-20 100" />
        <geom density="609.6044939672263" friction="1.4050302005094935 0.12868300165037516 0.15957421333285907" name="left_thigh" pos="0 0 -0.225" size="0.05 0.225" />
        <body name="left_leg" pos="0 0 -0.7">
          <joint damping="0.0942467012771127" name="left_knee" pos="0 0 0.25" range="-150 0" />
          <geom density="902.6639627080648" friction="0.9312998855301676 0.05356489153934471 0.16447084014615423" name="left_leg" size="0.04 0.25" />
          <body name="left_foot" pos="0.06 0 -0.25">
            <joint damping="0.0530242785000571" name="left_ankle" pos="-0.06 0 0" range="-45 45" />
            <geom density="1108.7122671177106" friction="0.680195373032202 0.150128884407074 0.06913737230846638" name="left_foot" size="0.05 0.04832820094772126" zaxis="1 0 0" />
          </body>
        </body>
      </body>
    </body>
  </worldbody>

  <sensor>
    <subtreelinvel body="torso" name="torso_subtreelinvel" />
  </sensor>

  <actuator>
    <motor gear="100" joint="right_hip" name="right_hip" />
    <motor gear="50" joint="right_knee" name="right_knee" />
    <motor gear="20" joint="right_ankle" name="right_ankle" />
    <motor gear="100" joint="left_hip" name="left_hip" />
    <motor gear="50" joint="left_knee" name="left_knee" />
    <motor gear="20" joint="left_ankle" name="left_ankle" />
  </actuator>
</mujoco>