<mujoco model="planar walker">
  <include file="./common/visual.xml" />
  <include file="./common/skybox.xml" />
  <include file="./common/materials.xml" />

  <option timestep="0.0025" />

  <statistic center="0 0 1" extent="2" />

  <default>
    <joint armature="0.01" damping=".1" limited="true" solimplimit="0 .99 .01" />
    <geom conaffinity="0" contype="1" friction=".7 .1 .1" />
    <motor ctrllimited="true" ctrlrange="-1 1" />
    <site size="0.01" />
    <default class="walker">
      <geom material="self" type="capsule" />
      <joint axis="0 -1 0" />
    </default>
  </default>

  <worldbody>
    <geom conaffinity="1" material="grid" name="floor" pos="248 0 0" size="250 .8 .2" type="plane" zaxis="0.02057004005245624 0.0 0.9997884143418748" />
    <body childclass="walker" name="torso" pos="0.05658725122555097 0.0 6.401327615877522">
      <light mode="trackcom" name="light" pos="0 0 2" />
      <camera euler="60 0 0" mode="trackcom" name="side" pos="0 -2 .7" />
      <camera mode="trackcom" name="back" pos="-2 0 .5" xyaxes="0 -1 0 1 0 3" />
      <joint armature="0" axis="0 0 1" damping="0.10097247146035493" limited="false" name="rootz" type="slide" />
      <joint armature="0" axis="1 0 0" damping="0.15104271262215135" limited="false" name="rootx" type="slide" />
      <joint armature="0" axis="0 1 0" damping="0.12445692414093962" limited="false" name="rooty" type="hinge" />
      <geom density="1084.7895626960776" friction="1.199920217998906 0.1352170050085265 0.12468934131896997" name="torso" size="0.07 0.3" />
      <body name="right_thigh" pos="0 -.05 -0.3">
        <joint damping="0.0502802636214895" name="right_hip" range="-20 100" />
        <geom density="519.9129959978452" friction="0.39820642790227295 0.09590145163863477 0.2171083790311007" name="right_thigh" pos="0 0 -0.225" size="0.05 0.225" />
        <body name="right_leg" pos="0 0 -0.7">
          <joint damping="0.06163219028733811" name="right_knee" pos="0 0 0.25" range="-150 0" />
          <geom density="649.3146598554802" friction="0.32077700963914446 0.06211169940861344 0.07280957914967255" name="right_leg" size="0.04 0.25" />
          <body name="right_foot" pos="0.06 0 -0.25">
            <joint damping="0.08249094546972176" name="right_ankle" pos="-0.06 0 0" range="-45 45" />
            <geom density="1150.7941476166122" friction="0.8399417060348201 0.12551866302840833 0.12451812944863885" name="right_foot" size="0.05 0.05149210198274856" zaxis="1 0 0" />
          </body>
        </body>
      </body>
      <body name="left_thigh" pos="0 .05 -0.3">
        <joint damping="0.15053934714929898" name="left_hip" range="-20 100" />
        <geom density="890.2952326925565" friction="0.38221425421893074 0.05194247681001869 0.11256829174894244" name="left_thigh" pos="0 0 -0.225" size="0.05 0.225" />
        <body name="left_leg" pos="0 0 -0.7">
          <joint damping="0.17078087843226544" name="left_knee" pos="0 0 0.25" range="-150 0" />
          <geom density="821.6095869514575" friction="0.7592304341649492 0.14438072178633696 0.1346874583306523" name="left_leg" size="0.04 0.25" />
          <body name="left_foot" pos="0.06 0 -0.25">
            <joint damping="0.19124683922919716" name="left_ankle" pos="-0.06 0 0" range="-45 45" />
            <geom density="1169.1110981154516" friction="0.4778703268213242 0.16055453052468707 0.1167908905320654" name="left_foot" size="0.05 0.0755422273493053" zaxis="1 0 0" />
          </body>
        </body>
      </body>
    </body>
  </worldbody>

  <sensor>
    <subtreelinvel body="torso" name="torso_subtreelinvel" />
  </sensor>

  <actuator>
    <motor gear="100" joint="right_hip" name="right_hip" />
    <motor gear="50" joint="right_knee" name="right_knee" />
    <motor gear="20" joint="right_ankle" name="right_ankle" />
    <motor gear="100" joint="left_hip" name="left_hip" />
    <motor gear="50" joint="left_knee" name="left_knee" />
    <motor gear="20" joint="left_ankle" name="left_ankle" />
  </actuator>
</mujoco>