<mujoco model="planar walker">
  <include file="./common/visual.xml" />
  <include file="./common/skybox.xml" />
  <include file="./common/materials.xml" />

  <option timestep="0.0025" />

  <statistic center="0 0 1" extent="2" />

  <default>
    <joint armature="0.01" damping=".1" limited="true" solimplimit="0 .99 .01" />
    <geom conaffinity="0" contype="1" friction=".7 .1 .1" />
    <motor ctrllimited="true" ctrlrange="-1 1" />
    <site size="0.01" />
    <default class="walker">
      <geom material="self" type="capsule" />
      <joint axis="0 -1 0" />
    </default>
  </default>

  <worldbody>
    <geom conaffinity="1" material="grid" name="floor" pos="248 0 0" size="250 .8 .2" type="plane" zaxis="0.12778416845643495 0.0 0.9918019995401791" />
    <body childclass="walker" name="torso" pos="2.058660947726878 0.0 32.988834177103904">
      <light mode="trackcom" name="light" pos="0 0 2" />
      <camera euler="60 0 0" mode="trackcom" name="side" pos="0 -2 .7" />
      <camera mode="trackcom" name="back" pos="-2 0 .5" xyaxes="0 -1 0 1 0 3" />
      <joint armature="0" axis="0 0 1" damping="0.1405424727010463" limited="false" name="rootz" type="slide" />
      <joint armature="0" axis="1 0 0" damping="0.19916839285302704" limited="false" name="rootx" type="slide" />
      <joint armature="0" axis="0 1 0" damping="0.1646806603434146" limited="false" name="rooty" type="hinge" />
      <geom density="1329.0020172405675" friction="0.4113841329033725 0.07288336309792569 0.10609559464281688" name="torso" size="0.07 0.3" />
      <body name="right_thigh" pos="0 -.05 -0.3">
        <joint damping="0.05198298302004504" name="right_hip" range="-20 100" />
        <geom density="526.0502177149156" friction="0.3293945180069428 0.05263844596592884 0.050775431452392154" name="right_thigh" pos="0 0 -0.225" size="0.05 0.225" />
        <body name="right_leg" pos="0 0 -0.7">
          <joint damping="0.0891184965118401" name="right_knee" pos="0 0 0.25" range="-150 0" />
          <geom density="468.8934441196101" friction="0.36092036098345937 0.21351142501223375 0.20049119069214372" name="right_leg" size="0.04 0.25" />
          <body name="right_foot" pos="0.06 0 -0.25">
            <joint damping="0.17624863899841844" name="right_ankle" pos="-0.06 0 0" range="-45 45" />
            <geom density="686.8717349584193" friction="0.6059887044974126 0.08042437850565409 0.07004303565787746" name="right_foot" size="0.05 0.0495810013521405" zaxis="1 0 0" />
          </body>
        </body>
      </body>
      <body name="left_thigh" pos="0 .05 -0.3">
        <joint damping="0.059244329969673874" name="left_hip" range="-20 100" />
        <geom density="1631.5519200649255" friction="0.4034080718849605 0.08068179513555507 0.04593367449735495" name="left_thigh" pos="0 0 -0.225" size="0.05 0.225" />
        <body name="left_leg" pos="0 0 -0.7">
          <joint damping="0.18967019961428394" name="left_knee" pos="0 0 0.25" range="-150 0" />
          <geom density="546.6185001790585" friction="0.3824030022128476 0.16081893437274808 0.21261756023596123" name="left_leg" size="0.04 0.25" />
          <body name="left_foot" pos="0.06 0 -0.25">
            <joint damping="0.16303784381783415" name="left_ankle" pos="-0.06 0 0" range="-45 45" />
            <geom density="1407.6347796535651" friction="0.3409902492815775 0.16572911608246038 0.10230014400858314" name="left_foot" size="0.05 0.15042770641040074" zaxis="1 0 0" />
          </body>
        </body>
      </body>
    </body>
  </worldbody>

  <sensor>
    <subtreelinvel body="torso" name="torso_subtreelinvel" />
  </sensor>

  <actuator>
    <motor gear="100" joint="right_hip" name="right_hip" />
    <motor gear="50" joint="right_knee" name="right_knee" />
    <motor gear="20" joint="right_ankle" name="right_ankle" />
    <motor gear="100" joint="left_hip" name="left_hip" />
    <motor gear="50" joint="left_knee" name="left_knee" />
    <motor gear="20" joint="left_ankle" name="left_ankle" />
  </actuator>
</mujoco>