<mujoco model="planar walker">
  <include file="./common/visual.xml" />
  <include file="./common/skybox.xml" />
  <include file="./common/materials.xml" />

  <option timestep="0.0025" />

  <statistic center="0 0 1" extent="2" />

  <default>
    <joint armature="0.01" damping=".1" limited="true" solimplimit="0 .99 .01" />
    <geom conaffinity="0" contype="1" friction=".7 .1 .1" />
    <motor ctrllimited="true" ctrlrange="-1 1" />
    <site size="0.01" />
    <default class="walker">
      <geom material="self" type="capsule" />
      <joint axis="0 -1 0" />
    </default>
  </default>

  <worldbody>
    <geom conaffinity="1" material="grid" name="floor" pos="248 0 0" size="250 .8 .2" type="plane" zaxis="-0.15114452003836973 0.0 0.9885116762397755" />
    <body childclass="walker" name="torso" pos="2.818875388527971 0.0 -36.186138634267735">
      <light mode="trackcom" name="light" pos="0 0 2" />
      <camera euler="60 0 0" mode="trackcom" name="side" pos="0 -2 .7" />
      <camera mode="trackcom" name="back" pos="-2 0 .5" xyaxes="0 -1 0 1 0 3" />
      <joint armature="0" axis="0 0 1" damping="0.11036084376422671" limited="false" name="rootz" type="slide" />
      <joint armature="0" axis="1 0 0" damping="0.15869079541327683" limited="false" name="rootx" type="slide" />
      <joint armature="0" axis="0 1 0" damping="0.10861045571376811" limited="false" name="rooty" type="hinge" />
      <geom density="520.2305471384384" friction="1.1651159904726947 0.060425014398733407 0.053906476679981635" name="torso" size="0.07 0.3" />
      <body name="right_thigh" pos="0 -.05 -0.3">
        <joint damping="0.09938429561603901" name="right_hip" range="-20 100" />
        <geom density="869.4328997302771" friction="0.47953554591811653 0.048694363693837575 0.0784967948541397" name="right_thigh" pos="0 0 -0.225" size="0.05 0.225" />
        <body name="right_leg" pos="0 0 -0.7">
          <joint damping="0.05756959111009753" name="right_knee" pos="0 0 0.25" range="-150 0" />
          <geom density="1094.9053740928189" friction="0.4134984382477377 0.20515031111206078 0.10959247738934293" name="right_leg" size="0.04 0.25" />
          <body name="right_foot" pos="0.06 0 -0.25">
            <joint damping="0.19015104462573906" name="right_ankle" pos="-0.06 0 0" range="-45 45" />
            <geom density="663.5532213250701" friction="1.1541798732155653 0.1364837192302122 0.2040239809163067" name="right_foot" size="0.05 0.061324750215095924" zaxis="1 0 0" />
          </body>
        </body>
      </body>
      <body name="left_thigh" pos="0 .05 -0.3">
        <joint damping="0.13544362183743425" name="left_hip" range="-20 100" />
        <geom density="944.4852883441089" friction="0.4189107377837223 0.067084180276195 0.057348031055946935" name="left_thigh" pos="0 0 -0.225" size="0.05 0.225" />
        <body name="left_leg" pos="0 0 -0.7">
          <joint damping="0.08459740634562728" name="left_knee" pos="0 0 0.25" range="-150 0" />
          <geom density="503.5281865059589" friction="0.4303215218913034 0.08945525842508617 0.06017721486110492" name="left_leg" size="0.04 0.25" />
          <body name="left_foot" pos="0.06 0 -0.25">
            <joint damping="0.08730903195556092" name="left_ankle" pos="-0.06 0 0" range="-45 45" />
            <geom density="1257.5296165915654" friction="0.5782520505316 0.17970568581900648 0.08203480472830926" name="left_foot" size="0.05 0.21618042588738204" zaxis="1 0 0" />
          </body>
        </body>
      </body>
    </body>
  </worldbody>

  <sensor>
    <subtreelinvel body="torso" name="torso_subtreelinvel" />
  </sensor>

  <actuator>
    <motor gear="100" joint="right_hip" name="right_hip" />
    <motor gear="50" joint="right_knee" name="right_knee" />
    <motor gear="20" joint="right_ankle" name="right_ankle" />
    <motor gear="100" joint="left_hip" name="left_hip" />
    <motor gear="50" joint="left_knee" name="left_knee" />
    <motor gear="20" joint="left_ankle" name="left_ankle" />
  </actuator>
</mujoco>