<mujoco model="planar walker">
  <include file="./common/visual.xml" />
  <include file="./common/skybox.xml" />
  <include file="./common/materials.xml" />

  <option timestep="0.0025" />

  <statistic center="0 0 1" extent="2" />

  <default>
    <joint armature="0.01" damping=".1" limited="true" solimplimit="0 .99 .01" />
    <geom conaffinity="0" contype="1" friction=".7 .1 .1" />
    <motor ctrllimited="true" ctrlrange="-1 1" />
    <site size="0.01" />
    <default class="walker">
      <geom material="self" type="capsule" />
      <joint axis="0 -1 0" />
    </default>
  </default>

  <worldbody>
    <geom conaffinity="1" material="grid" name="floor" pos="248 0 0" size="250 .8 .2" type="plane" zaxis="-0.043517311347504896 0.0 0.9990526730924072" />
    <body childclass="walker" name="torso" pos="0.226233610813523 0.0 -9.492482679562732">
      <light mode="trackcom" name="light" pos="0 0 2" />
      <camera euler="60 0 0" mode="trackcom" name="side" pos="0 -2 .7" />
      <camera mode="trackcom" name="back" pos="-2 0 .5" xyaxes="0 -1 0 1 0 3" />
      <joint armature="0" axis="0 0 1" damping="0.195661830849323" limited="false" name="rootz" type="slide" />
      <joint armature="0" axis="1 0 0" damping="0.07617356345631172" limited="false" name="rootx" type="slide" />
      <joint armature="0" axis="0 1 0" damping="0.19741886726835606" limited="false" name="rooty" type="hinge" />
      <geom density="783.3481927855477" friction="1.500576040453649 0.1160071690792322 0.2069050058347599" name="torso" size="0.07 0.3" />
      <body name="right_thigh" pos="0 -.05 -0.3">
        <joint damping="0.05785813450182114" name="right_hip" range="-20 100" />
        <geom density="594.2970085755642" friction="0.8866750113072593 0.11310174003231399 0.07564105262456094" name="right_thigh" pos="0 0 -0.225" size="0.05 0.225" />
        <body name="right_leg" pos="0 0 -0.7">
          <joint damping="0.07591187149889053" name="right_knee" pos="0 0 0.25" range="-150 0" />
          <geom density="2157.213020808035" friction="0.9208232405725015 0.18158541308773357 0.06179605518484713" name="right_leg" size="0.04 0.25" />
          <body name="right_foot" pos="0.06 0 -0.25">
            <joint damping="0.1084054687091145" name="right_ankle" pos="-0.06 0 0" range="-45 45" />
            <geom density="2116.5899599104973" friction="0.4863435495979545 0.04986443601106724 0.08461493174039174" name="right_foot" size="0.05 0.13152066419386285" zaxis="1 0 0" />
          </body>
        </body>
      </body>
      <body name="left_thigh" pos="0 .05 -0.3">
        <joint damping="0.17384801211866174" name="left_hip" range="-20 100" />
        <geom density="499.8180238985445" friction="1.2475428391081869 0.09459529767079289 0.09020846899476281" name="left_thigh" pos="0 0 -0.225" size="0.05 0.225" />
        <body name="left_leg" pos="0 0 -0.7">
          <joint damping="0.0705994809696181" name="left_knee" pos="0 0 0.25" range="-150 0" />
          <geom density="902.2166627822666" friction="0.7360148703494356 0.07894363304249802 0.07239360800084996" name="left_leg" size="0.04 0.25" />
          <body name="left_foot" pos="0.06 0 -0.25">
            <joint damping="0.16719253542482526" name="left_ankle" pos="-0.06 0 0" range="-45 45" />
            <geom density="1029.057662828602" friction="0.534401682321263 0.05455110202542253 0.11193497977253018" name="left_foot" size="0.05 0.09290219786914458" zaxis="1 0 0" />
          </body>
        </body>
      </body>
    </body>
  </worldbody>

  <sensor>
    <subtreelinvel body="torso" name="torso_subtreelinvel" />
  </sensor>

  <actuator>
    <motor gear="100" joint="right_hip" name="right_hip" />
    <motor gear="50" joint="right_knee" name="right_knee" />
    <motor gear="20" joint="right_ankle" name="right_ankle" />
    <motor gear="100" joint="left_hip" name="left_hip" />
    <motor gear="50" joint="left_knee" name="left_knee" />
    <motor gear="20" joint="left_ankle" name="left_ankle" />
  </actuator>
</mujoco>