<mujoco model="planar walker">
  <include file="./common/visual.xml" />
  <include file="./common/skybox.xml" />
  <include file="./common/materials.xml" />

  <option timestep="0.0025" />

  <statistic center="0 0 1" extent="2" />

  <default>
    <joint armature="0.01" damping=".1" limited="true" solimplimit="0 .99 .01" />
    <geom conaffinity="0" contype="1" friction=".7 .1 .1" />
    <motor ctrllimited="true" ctrlrange="-1 1" />
    <site size="0.01" />
    <default class="walker">
      <geom material="self" type="capsule" />
      <joint axis="0 -1 0" />
    </default>
  </default>

  <worldbody>
    <geom conaffinity="1" material="grid" name="floor" pos="248 0 0" size="250 .8 .2" type="plane" zaxis="0.1654138754161651 0.0 0.9862242391159353" />
    <body childclass="walker" name="torso" pos="3.4494714743312898 0.0 42.31988595103213">
      <light mode="trackcom" name="light" pos="0 0 2" />
      <camera euler="60 0 0" mode="trackcom" name="side" pos="0 -2 .7" />
      <camera mode="trackcom" name="back" pos="-2 0 .5" xyaxes="0 -1 0 1 0 3" />
      <joint armature="0" axis="0 0 1" damping="0.07684178524066926" limited="false" name="rootz" type="slide" />
      <joint armature="0" axis="1 0 0" damping="0.12133770788101211" limited="false" name="rootx" type="slide" />
      <joint armature="0" axis="0 1 0" damping="0.05905794025121717" limited="false" name="rooty" type="hinge" />
      <geom density="1866.4835758598322" friction="0.6515669999494809 0.053085839487876554 0.20899443042326987" name="torso" size="0.07 0.3" />
      <body name="right_thigh" pos="0 -.05 -0.3">
        <joint damping="0.06750119597564254" name="right_hip" range="-20 100" />
        <geom density="823.8867726409641" friction="0.6115522636986098 0.0932881310723498 0.047152041561934685" name="right_thigh" pos="0 0 -0.225" size="0.05 0.225" />
        <body name="right_leg" pos="0 0 -0.7">
          <joint damping="0.12495154251476859" name="right_knee" pos="0 0 0.25" range="-150 0" />
          <geom density="985.3628537117368" friction="1.1917115862058585 0.17531088142807458 0.0913025378346925" name="right_leg" size="0.04 0.25" />
          <body name="right_foot" pos="0.06 0 -0.25">
            <joint damping="0.1366732570277266" name="right_ankle" pos="-0.06 0 0" range="-45 45" />
            <geom density="963.0683960042256" friction="0.45889211871822755 0.11986218401436821 0.10995254238180191" name="right_foot" size="0.05 0.08594200835147339" zaxis="1 0 0" />
          </body>
        </body>
      </body>
      <body name="left_thigh" pos="0 .05 -0.3">
        <joint damping="0.08512127786393275" name="left_hip" range="-20 100" />
        <geom density="1332.6097596874615" friction="0.3767323531941801 0.10617713650152072 0.08458040346414286" name="left_thigh" pos="0 0 -0.225" size="0.05 0.225" />
        <body name="left_leg" pos="0 0 -0.7">
          <joint damping="0.10705778882584137" name="left_knee" pos="0 0 0.25" range="-150 0" />
          <geom density="780.7321449123546" friction="0.8323192610363245 0.04859579702519139 0.15381070533154936" name="left_leg" size="0.04 0.25" />
          <body name="left_foot" pos="0.06 0 -0.25">
            <joint damping="0.0682674707721827" name="left_ankle" pos="-0.06 0 0" range="-45 45" />
            <geom density="514.8607716392984" friction="1.1209957861802138 0.12589330138811847 0.05184193006394107" name="left_foot" size="0.05 0.10113857829732256" zaxis="1 0 0" />
          </body>
        </body>
      </body>
    </body>
  </worldbody>

  <sensor>
    <subtreelinvel body="torso" name="torso_subtreelinvel" />
  </sensor>

  <actuator>
    <motor gear="100" joint="right_hip" name="right_hip" />
    <motor gear="50" joint="right_knee" name="right_knee" />
    <motor gear="20" joint="right_ankle" name="right_ankle" />
    <motor gear="100" joint="left_hip" name="left_hip" />
    <motor gear="50" joint="left_knee" name="left_knee" />
    <motor gear="20" joint="left_ankle" name="left_ankle" />
  </actuator>
</mujoco>