<mujoco model="planar walker">
  <include file="./common/visual.xml" />
  <include file="./common/skybox.xml" />
  <include file="./common/materials.xml" />

  <option timestep="0.0025" />

  <statistic center="0 0 1" extent="2" />

  <default>
    <joint armature="0.01" damping=".1" limited="true" solimplimit="0 .99 .01" />
    <geom conaffinity="0" contype="1" friction=".7 .1 .1" />
    <motor ctrllimited="true" ctrlrange="-1 1" />
    <site size="0.01" />
    <default class="walker">
      <geom material="self" type="capsule" />
      <joint axis="0 -1 0" />
    </default>
  </default>

  <worldbody>
    <geom conaffinity="1" material="grid" name="floor" pos="248 0 0" size="250 .8 .2" type="plane" zaxis="-0.16328973024180263 0.0 0.9865781590921012" />
    <body childclass="walker" name="torso" pos="3.29595859911052 0.0 -39.19853746814863">
      <light mode="trackcom" name="light" pos="0 0 2" />
      <camera euler="60 0 0" mode="trackcom" name="side" pos="0 -2 .7" />
      <camera mode="trackcom" name="back" pos="-2 0 .5" xyaxes="0 -1 0 1 0 3" />
      <joint armature="0" axis="0 0 1" damping="0.19121386172096208" limited="false" name="rootz" type="slide" />
      <joint armature="0" axis="1 0 0" damping="0.08341747120668551" limited="false" name="rootx" type="slide" />
      <joint armature="0" axis="0 1 0" damping="0.06494120194788378" limited="false" name="rooty" type="hinge" />
      <geom density="1505.9336438474297" friction="0.36481145735264525 0.11485119763858996 0.1734402270277317" name="torso" size="0.07 0.3" />
      <body name="right_thigh" pos="0 -.05 -0.3">
        <joint damping="0.0714376008711253" name="right_hip" range="-20 100" />
        <geom density="2193.486386813078" friction="0.997883008470207 0.21808707367427177 0.13869981602417386" name="right_thigh" pos="0 0 -0.225" size="0.05 0.225" />
        <body name="right_leg" pos="0 0 -0.7">
          <joint damping="0.2018479381603962" name="right_knee" pos="0 0 0.25" range="-150 0" />
          <geom density="1076.3898909416932" friction="0.7187092694965718 0.06782447209391394 0.05594676551286848" name="right_leg" size="0.04 0.25" />
          <body name="right_foot" pos="0.06 0 -0.25">
            <joint damping="0.11477605121757367" name="right_ankle" pos="-0.06 0 0" range="-45 45" />
            <geom density="889.3085029761152" friction="0.7722773767418872 0.06030010813108231 0.10336686417778157" name="right_foot" size="0.05 0.1058190963147677" zaxis="1 0 0" />
          </body>
        </body>
      </body>
      <body name="left_thigh" pos="0 .05 -0.3">
        <joint damping="0.050353429575191726" name="left_hip" range="-20 100" />
        <geom density="2054.7832118651963" friction="0.9427873660875684 0.06792091134783018 0.16541855744362205" name="left_thigh" pos="0 0 -0.225" size="0.05 0.225" />
        <body name="left_leg" pos="0 0 -0.7">
          <joint damping="0.1984820437372407" name="left_knee" pos="0 0 0.25" range="-150 0" />
          <geom density="645.9332872184576" friction="0.39503110107853767 0.0606069646541791 0.08022162053725099" name="left_leg" size="0.04 0.25" />
          <body name="left_foot" pos="0.06 0 -0.25">
            <joint damping="0.12220179257632119" name="left_ankle" pos="-0.06 0 0" range="-45 45" />
            <geom density="1710.873937951027" friction="0.3227524612818654 0.16919505704404122 0.1513255409037665" name="left_foot" size="0.05 0.0907951506792678" zaxis="1 0 0" />
          </body>
        </body>
      </body>
    </body>
  </worldbody>

  <sensor>
    <subtreelinvel body="torso" name="torso_subtreelinvel" />
  </sensor>

  <actuator>
    <motor gear="100" joint="right_hip" name="right_hip" />
    <motor gear="50" joint="right_knee" name="right_knee" />
    <motor gear="20" joint="right_ankle" name="right_ankle" />
    <motor gear="100" joint="left_hip" name="left_hip" />
    <motor gear="50" joint="left_knee" name="left_knee" />
    <motor gear="20" joint="left_ankle" name="left_ankle" />
  </actuator>
</mujoco>