<mujoco model="planar walker">
  <include file="./common/visual.xml" />
  <include file="./common/skybox.xml" />
  <include file="./common/materials.xml" />

  <option timestep="0.0025" />

  <statistic center="0 0 1" extent="2" />

  <default>
    <joint armature="0.01" damping=".1" limited="true" solimplimit="0 .99 .01" />
    <geom conaffinity="0" contype="1" friction=".7 .1 .1" />
    <motor ctrllimited="true" ctrlrange="-1 1" />
    <site size="0.01" />
    <default class="walker">
      <geom material="self" type="capsule" />
      <joint axis="0 -1 0" />
    </default>
  </default>

  <worldbody>
    <geom conaffinity="1" material="grid" name="floor" pos="248 0 0" size="250 .8 .2" type="plane" zaxis="0.08183376840970268 0.0 0.9966459924907475" />
    <body childclass="walker" name="torso" pos="0.8481606159765818 0.0 21.594103764104414">
      <light mode="trackcom" name="light" pos="0 0 2" />
      <camera euler="60 0 0" mode="trackcom" name="side" pos="0 -2 .7" />
      <camera mode="trackcom" name="back" pos="-2 0 .5" xyaxes="0 -1 0 1 0 3" />
      <joint armature="0" axis="0 0 1" damping="0.18014680685343998" limited="false" name="rootz" type="slide" />
      <joint armature="0" axis="1 0 0" damping="0.08105964853786907" limited="false" name="rootx" type="slide" />
      <joint armature="0" axis="0 1 0" damping="0.09349641295759781" limited="false" name="rooty" type="hinge" />
      <geom density="996.9053418453994" friction="0.56517503388324 0.1136760878523465 0.04659113439039063" name="torso" size="0.07 0.3" />
      <body name="right_thigh" pos="0 -.05 -0.3">
        <joint damping="0.10203122846032589" name="right_hip" range="-20 100" />
        <geom density="1985.9461472663347" friction="0.748441510074045 0.09273146991130088 0.10053073064728038" name="right_thigh" pos="0 0 -0.225" size="0.05 0.225" />
        <body name="right_leg" pos="0 0 -0.7">
          <joint damping="0.09280570903685635" name="right_knee" pos="0 0 0.25" range="-150 0" />
          <geom density="1205.9396512982235" friction="1.1284227276526526 0.055697956629191706 0.10549384428211231" name="right_leg" size="0.04 0.25" />
          <body name="right_foot" pos="0.06 0 -0.25">
            <joint damping="0.055532468167263954" name="right_ankle" pos="-0.06 0 0" range="-45 45" />
            <geom density="872.18661876711" friction="0.990248878001565 0.11787023781642168 0.07266184007674255" name="right_foot" size="0.05 0.05421674050022205" zaxis="1 0 0" />
          </body>
        </body>
      </body>
      <body name="left_thigh" pos="0 .05 -0.3">
        <joint damping="0.10344696547644242" name="left_hip" range="-20 100" />
        <geom density="995.7374768693684" friction="0.3807322432502511 0.1452135406696707 0.051305975234349745" name="left_thigh" pos="0 0 -0.225" size="0.05 0.225" />
        <body name="left_leg" pos="0 0 -0.7">
          <joint damping="0.05122052760352566" name="left_knee" pos="0 0 0.25" range="-150 0" />
          <geom density="1651.2967490101612" friction="1.445227691295978 0.05362181154933572 0.09590014513073003" name="left_leg" size="0.04 0.25" />
          <body name="left_foot" pos="0.06 0 -0.25">
            <joint damping="0.14290872552356912" name="left_ankle" pos="-0.06 0 0" range="-45 45" />
            <geom density="759.0598017632539" friction="0.7032199225019843 0.15297423276088817 0.061316970754167505" name="left_foot" size="0.05 0.05062439016768561" zaxis="1 0 0" />
          </body>
        </body>
      </body>
    </body>
  </worldbody>

  <sensor>
    <subtreelinvel body="torso" name="torso_subtreelinvel" />
  </sensor>

  <actuator>
    <motor gear="100" joint="right_hip" name="right_hip" />
    <motor gear="50" joint="right_knee" name="right_knee" />
    <motor gear="20" joint="right_ankle" name="right_ankle" />
    <motor gear="100" joint="left_hip" name="left_hip" />
    <motor gear="50" joint="left_knee" name="left_knee" />
    <motor gear="20" joint="left_ankle" name="left_ankle" />
  </actuator>
</mujoco>