<mujoco model="planar walker">
  <include file="./common/visual.xml" />
  <include file="./common/skybox.xml" />
  <include file="./common/materials.xml" />

  <option timestep="0.0025" />

  <statistic center="0 0 1" extent="2" />

  <default>
    <joint armature="0.01" damping=".1" limited="true" solimplimit="0 .99 .01" />
    <geom conaffinity="0" contype="1" friction=".7 .1 .1" />
    <motor ctrllimited="true" ctrlrange="-1 1" />
    <site size="0.01" />
    <default class="walker">
      <geom material="self" type="capsule" />
      <joint axis="0 -1 0" />
    </default>
  </default>

  <worldbody>
    <geom conaffinity="1" material="grid" name="floor" pos="248 0 0" size="250 .8 .2" type="plane" zaxis="-0.18106432059212502 0.0 0.9834712562187632" />
    <body childclass="walker" name="torso" pos="4.062915593628304 0.0 -43.607257255603244">
      <light mode="trackcom" name="light" pos="0 0 2" />
      <camera euler="60 0 0" mode="trackcom" name="side" pos="0 -2 .7" />
      <camera mode="trackcom" name="back" pos="-2 0 .5" xyaxes="0 -1 0 1 0 3" />
      <joint armature="0" axis="0 0 1" damping="0.14841352154513093" limited="false" name="rootz" type="slide" />
      <joint armature="0" axis="1 0 0" damping="0.0860116820925581" limited="false" name="rootx" type="slide" />
      <joint armature="0" axis="0 1 0" damping="0.10934407041879657" limited="false" name="rooty" type="hinge" />
      <geom density="621.6992351469761" friction="1.1468650422503097 0.04590703149914261 0.11590423042736597" name="torso" size="0.07 0.3" />
      <body name="right_thigh" pos="0 -.05 -0.3">
        <joint damping="0.13656607479697122" name="right_hip" range="-20 100" />
        <geom density="1085.5302324130867" friction="0.7733935376142852 0.08776584455344816 0.12445065444018699" name="right_thigh" pos="0 0 -0.225" size="0.05 0.225" />
        <body name="right_leg" pos="0 0 -0.7">
          <joint damping="0.07571681745955933" name="right_knee" pos="0 0 0.25" range="-150 0" />
          <geom density="917.8762831479356" friction="0.5202047090761556 0.16501776286691897 0.08707785574554597" name="right_leg" size="0.04 0.25" />
          <body name="right_foot" pos="0.06 0 -0.25">
            <joint damping="0.10150423624875578" name="right_ankle" pos="-0.06 0 0" range="-45 45" />
            <geom density="1025.4988165571124" friction="1.4420471218409883 0.1174670895151626 0.19465150293306802" name="right_foot" size="0.05 0.13185562881125779" zaxis="1 0 0" />
          </body>
        </body>
      </body>
      <body name="left_thigh" pos="0 .05 -0.3">
        <joint damping="0.0873033217225737" name="left_hip" range="-20 100" />
        <geom density="485.6714555606017" friction="0.8286682572262817 0.17088020234731968 0.21048330918807756" name="left_thigh" pos="0 0 -0.225" size="0.05 0.225" />
        <body name="left_leg" pos="0 0 -0.7">
          <joint damping="0.057214708971724385" name="left_knee" pos="0 0 0.25" range="-150 0" />
          <geom density="614.7084915203318" friction="0.7407648113508055 0.05213572183857246 0.08572513494553158" name="left_leg" size="0.04 0.25" />
          <body name="left_foot" pos="0.06 0 -0.25">
            <joint damping="0.10119661552973308" name="left_ankle" pos="-0.06 0 0" range="-45 45" />
            <geom density="949.7618574122438" friction="0.46281278238163526 0.06792577155371583 0.2090126731421952" name="left_foot" size="0.05 0.17168572218405295" zaxis="1 0 0" />
          </body>
        </body>
      </body>
    </body>
  </worldbody>

  <sensor>
    <subtreelinvel body="torso" name="torso_subtreelinvel" />
  </sensor>

  <actuator>
    <motor gear="100" joint="right_hip" name="right_hip" />
    <motor gear="50" joint="right_knee" name="right_knee" />
    <motor gear="20" joint="right_ankle" name="right_ankle" />
    <motor gear="100" joint="left_hip" name="left_hip" />
    <motor gear="50" joint="left_knee" name="left_knee" />
    <motor gear="20" joint="left_ankle" name="left_ankle" />
  </actuator>
</mujoco>