<mujoco model="planar walker">
  <include file="./common/visual.xml" />
  <include file="./common/skybox.xml" />
  <include file="./common/materials.xml" />

  <option timestep="0.0025" />

  <statistic center="0 0 1" extent="2" />

  <default>
    <joint armature="0.01" damping=".1" limited="true" solimplimit="0 .99 .01" />
    <geom conaffinity="0" contype="1" friction=".7 .1 .1" />
    <motor ctrllimited="true" ctrlrange="-1 1" />
    <site size="0.01" />
    <default class="walker">
      <geom material="self" type="capsule" />
      <joint axis="0 -1 0" />
    </default>
  </default>

  <worldbody>
    <geom conaffinity="1" material="grid" name="floor" pos="248 0 0" size="250 .8 .2" type="plane" zaxis="0.0786728205551646 0.0 0.9969004901723616" />
    <body childclass="walker" name="torso" pos="0.7844130013653512 0.0 20.81023959571529">
      <light mode="trackcom" name="light" pos="0 0 2" />
      <camera euler="60 0 0" mode="trackcom" name="side" pos="0 -2 .7" />
      <camera mode="trackcom" name="back" pos="-2 0 .5" xyaxes="0 -1 0 1 0 3" />
      <joint armature="0" axis="0 0 1" damping="0.14092004559994564" limited="false" name="rootz" type="slide" />
      <joint armature="0" axis="1 0 0" damping="0.06286192174402892" limited="false" name="rootx" type="slide" />
      <joint armature="0" axis="0 1 0" damping="0.17839714317143845" limited="false" name="rooty" type="hinge" />
      <geom density="1115.6264568281993" friction="0.35088376827486956 0.12765443205980528 0.08397848261196462" name="torso" size="0.07 0.3" />
      <body name="right_thigh" pos="0 -.05 -0.3">
        <joint damping="0.1065403129991665" name="right_hip" range="-20 100" />
        <geom density="1354.8440020795115" friction="1.51990134096187 0.11866068902128753 0.21149085281469102" name="right_thigh" pos="0 0 -0.225" size="0.05 0.225" />
        <body name="right_leg" pos="0 0 -0.7">
          <joint damping="0.05681216568374208" name="right_knee" pos="0 0 0.25" range="-150 0" />
          <geom density="675.3710988922295" friction="0.5874092517826994 0.06857396178122066 0.14667825753853558" name="right_leg" size="0.04 0.25" />
          <body name="right_foot" pos="0.06 0 -0.25">
            <joint damping="0.19490367507956088" name="right_ankle" pos="-0.06 0 0" range="-45 45" />
            <geom density="828.5796797556912" friction="1.0077911155224115 0.19212849127479037 0.09711381061870966" name="right_foot" size="0.05 0.13437076848368623" zaxis="1 0 0" />
          </body>
        </body>
      </body>
      <body name="left_thigh" pos="0 .05 -0.3">
        <joint damping="0.1086187076335648" name="left_hip" range="-20 100" />
        <geom density="806.9373544673068" friction="1.2262274871508367 0.09872717623671418 0.17901897653615959" name="left_thigh" pos="0 0 -0.225" size="0.05 0.225" />
        <body name="left_leg" pos="0 0 -0.7">
          <joint damping="0.20642692813076371" name="left_knee" pos="0 0 0.25" range="-150 0" />
          <geom density="696.9666204510027" friction="0.9687787019226454 0.0635649264885579 0.10307135684009266" name="left_leg" size="0.04 0.25" />
          <body name="left_foot" pos="0.06 0 -0.25">
            <joint damping="0.09449522473867515" name="left_ankle" pos="-0.06 0 0" range="-45 45" />
            <geom density="781.0591442098928" friction="1.4326173026684297 0.05106346508203085 0.12513776237089555" name="left_foot" size="0.05 0.06088101537482199" zaxis="1 0 0" />
          </body>
        </body>
      </body>
    </body>
  </worldbody>

  <sensor>
    <subtreelinvel body="torso" name="torso_subtreelinvel" />
  </sensor>

  <actuator>
    <motor gear="100" joint="right_hip" name="right_hip" />
    <motor gear="50" joint="right_knee" name="right_knee" />
    <motor gear="20" joint="right_ankle" name="right_ankle" />
    <motor gear="100" joint="left_hip" name="left_hip" />
    <motor gear="50" joint="left_knee" name="left_knee" />
    <motor gear="20" joint="left_ankle" name="left_ankle" />
  </actuator>
</mujoco>