<mujoco model="planar walker">
  <include file="./common/visual.xml" />
  <include file="./common/skybox.xml" />
  <include file="./common/materials.xml" />

  <option timestep="0.0025" />

  <statistic center="0 0 1" extent="2" />

  <default>
    <joint armature="0.01" damping=".1" limited="true" solimplimit="0 .99 .01" />
    <geom conaffinity="0" contype="1" friction=".7 .1 .1" />
    <motor ctrllimited="true" ctrlrange="-1 1" />
    <site size="0.01" />
    <default class="walker">
      <geom material="self" type="capsule" />
      <joint axis="0 -1 0" />
    </default>
  </default>

  <worldbody>
    <geom conaffinity="1" material="grid" name="floor" pos="248 0 0" size="250 .8 .2" type="plane" zaxis="0.15539171040970895 0.0 0.9878529325440832" />
    <body childclass="walker" name="torso" pos="3.0435510711492952 0.0 39.83471476811664">
      <light mode="trackcom" name="light" pos="0 0 2" />
      <camera euler="60 0 0" mode="trackcom" name="side" pos="0 -2 .7" />
      <camera mode="trackcom" name="back" pos="-2 0 .5" xyaxes="0 -1 0 1 0 3" />
      <joint armature="0" axis="0 0 1" damping="0.19934710159640465" limited="false" name="rootz" type="slide" />
      <joint armature="0" axis="1 0 0" damping="0.10342604029777765" limited="false" name="rootx" type="slide" />
      <joint armature="0" axis="0 1 0" damping="0.13232408554342054" limited="false" name="rooty" type="hinge" />
      <geom density="1386.1596891492075" friction="0.5973787448049062 0.07647651343742193 0.05245664310891493" name="torso" size="0.07 0.3" />
      <body name="right_thigh" pos="0 -.05 -0.3">
        <joint damping="0.05018524162768916" name="right_hip" range="-20 100" />
        <geom density="1457.3973881484885" friction="0.822656018806777 0.1828273592911601 0.1263130678306289" name="right_thigh" pos="0 0 -0.225" size="0.05 0.225" />
        <body name="right_leg" pos="0 0 -0.7">
          <joint damping="0.07949107865992096" name="right_knee" pos="0 0 0.25" range="-150 0" />
          <geom density="987.7977537819058" friction="1.1560729438723663 0.0946646254326799 0.17524748622191902" name="right_leg" size="0.04 0.25" />
          <body name="right_foot" pos="0.06 0 -0.25">
            <joint damping="0.17774621265585094" name="right_ankle" pos="-0.06 0 0" range="-45 45" />
            <geom density="1072.22737031765" friction="0.7323881126770001 0.19233367330477794 0.051630920704728835" name="right_foot" size="0.05 0.05727542945444957" zaxis="1 0 0" />
          </body>
        </body>
      </body>
      <body name="left_thigh" pos="0 .05 -0.3">
        <joint damping="0.0875393498388121" name="left_hip" range="-20 100" />
        <geom density="787.1613093782031" friction="1.2437679154445274 0.1259191844900658 0.05048761263159765" name="left_thigh" pos="0 0 -0.225" size="0.05 0.225" />
        <body name="left_leg" pos="0 0 -0.7">
          <joint damping="0.04750299810638994" name="left_knee" pos="0 0 0.25" range="-150 0" />
          <geom density="1135.01952360639" friction="1.1373643699584437 0.047944469630821086 0.1340525738517744" name="left_leg" size="0.04 0.25" />
          <body name="left_foot" pos="0.06 0 -0.25">
            <joint damping="0.201320684016279" name="left_ankle" pos="-0.06 0 0" range="-45 45" />
            <geom density="1671.9172815163824" friction="0.5534861028649325 0.12436373750945018 0.13808562488023143" name="left_foot" size="0.05 0.11702683827934979" zaxis="1 0 0" />
          </body>
        </body>
      </body>
    </body>
  </worldbody>

  <sensor>
    <subtreelinvel body="torso" name="torso_subtreelinvel" />
  </sensor>

  <actuator>
    <motor gear="100" joint="right_hip" name="right_hip" />
    <motor gear="50" joint="right_knee" name="right_knee" />
    <motor gear="20" joint="right_ankle" name="right_ankle" />
    <motor gear="100" joint="left_hip" name="left_hip" />
    <motor gear="50" joint="left_knee" name="left_knee" />
    <motor gear="20" joint="left_ankle" name="left_ankle" />
  </actuator>
</mujoco>