<mujoco model="planar walker">
  <include file="./common/visual.xml" />
  <include file="./common/skybox.xml" />
  <include file="./common/materials.xml" />

  <option timestep="0.0025" />

  <statistic center="0 0 1" extent="2" />

  <default>
    <joint armature="0.01" damping=".1" limited="true" solimplimit="0 .99 .01" />
    <geom conaffinity="0" contype="1" friction=".7 .1 .1" />
    <motor ctrllimited="true" ctrlrange="-1 1" />
    <site size="0.01" />
    <default class="walker">
      <geom material="self" type="capsule" />
      <joint axis="0 -1 0" />
    </default>
  </default>

  <worldbody>
    <geom conaffinity="1" material="grid" name="floor" pos="248 0 0" size="250 .8 .2" type="plane" zaxis="-0.03181371036139342 0.0 0.9994938158053012" />
    <body childclass="walker" name="torso" pos="0.11917093821304547 0.0 -6.589901406464508">
      <light mode="trackcom" name="light" pos="0 0 2" />
      <camera euler="60 0 0" mode="trackcom" name="side" pos="0 -2 .7" />
      <camera mode="trackcom" name="back" pos="-2 0 .5" xyaxes="0 -1 0 1 0 3" />
      <joint armature="0" axis="0 0 1" damping="0.19541582274838054" limited="false" name="rootz" type="slide" />
      <joint armature="0" axis="1 0 0" damping="0.06909939020840221" limited="false" name="rootx" type="slide" />
      <joint armature="0" axis="0 1 0" damping="0.1156135527903721" limited="false" name="rooty" type="hinge" />
      <geom density="1883.2366982532121" friction="1.3287879728078482 0.08493457744477602 0.05827489767619093" name="torso" size="0.07 0.3" />
      <body name="right_thigh" pos="0 -.05 -0.3">
        <joint damping="0.1896783687183523" name="right_hip" range="-20 100" />
        <geom density="567.4221007233165" friction="0.5717452895366497 0.10735387019339399 0.10547406358684104" name="right_thigh" pos="0 0 -0.225" size="0.05 0.225" />
        <body name="right_leg" pos="0 0 -0.7">
          <joint damping="0.05448454311907867" name="right_knee" pos="0 0 0.25" range="-150 0" />
          <geom density="1656.1548774909627" friction="0.6898635640884655 0.1263677123187403 0.08011979368730297" name="right_leg" size="0.04 0.25" />
          <body name="right_foot" pos="0.06 0 -0.25">
            <joint damping="0.11298615239513446" name="right_ankle" pos="-0.06 0 0" range="-45 45" />
            <geom density="1466.4035426265405" friction="0.3759797308620208 0.15109361160324755 0.07985411890868382" name="right_foot" size="0.05 0.10827032266700953" zaxis="1 0 0" />
          </body>
        </body>
      </body>
      <body name="left_thigh" pos="0 .05 -0.3">
        <joint damping="0.158790069996984" name="left_hip" range="-20 100" />
        <geom density="976.6853766441567" friction="0.5073494145015843 0.19235320904626318 0.07509949251484593" name="left_thigh" pos="0 0 -0.225" size="0.05 0.225" />
        <body name="left_leg" pos="0 0 -0.7">
          <joint damping="0.16189361033454364" name="left_knee" pos="0 0 0.25" range="-150 0" />
          <geom density="583.4900351302279" friction="0.6394252562858589 0.08745666648055986 0.07831014669214709" name="left_leg" size="0.04 0.25" />
          <body name="left_foot" pos="0.06 0 -0.25">
            <joint damping="0.054201282421497146" name="left_ankle" pos="-0.06 0 0" range="-45 45" />
            <geom density="1438.908851167373" friction="0.33397212032528634 0.16134257320404172 0.15085406524779832" name="left_foot" size="0.05 0.11181818783002209" zaxis="1 0 0" />
          </body>
        </body>
      </body>
    </body>
  </worldbody>

  <sensor>
    <subtreelinvel body="torso" name="torso_subtreelinvel" />
  </sensor>

  <actuator>
    <motor gear="100" joint="right_hip" name="right_hip" />
    <motor gear="50" joint="right_knee" name="right_knee" />
    <motor gear="20" joint="right_ankle" name="right_ankle" />
    <motor gear="100" joint="left_hip" name="left_hip" />
    <motor gear="50" joint="left_knee" name="left_knee" />
    <motor gear="20" joint="left_ankle" name="left_ankle" />
  </actuator>
</mujoco>