<mujoco model="planar walker">
  <include file="./common/visual.xml" />
  <include file="./common/skybox.xml" />
  <include file="./common/materials.xml" />

  <option timestep="0.0025" />

  <statistic center="0 0 1" extent="2" />

  <default>
    <joint armature="0.01" damping=".1" limited="true" solimplimit="0 .99 .01" />
    <geom conaffinity="0" contype="1" friction=".7 .1 .1" />
    <motor ctrllimited="true" ctrlrange="-1 1" />
    <site size="0.01" />
    <default class="walker">
      <geom material="self" type="capsule" />
      <joint axis="0 -1 0" />
    </default>
  </default>

  <worldbody>
    <geom conaffinity="1" material="grid" name="floor" pos="248 0 0" size="250 .8 .2" type="plane" zaxis="-0.1023041121702244 0.0 0.9947531697024454" />
    <body childclass="walker" name="torso" pos="1.280753091359486 0.0 -24.072469184275164">
      <light mode="trackcom" name="light" pos="0 0 2" />
      <camera euler="60 0 0" mode="trackcom" name="side" pos="0 -2 .7" />
      <camera mode="trackcom" name="back" pos="-2 0 .5" xyaxes="0 -1 0 1 0 3" />
      <joint armature="0" axis="0 0 1" damping="0.21409448286362395" limited="false" name="rootz" type="slide" />
      <joint armature="0" axis="1 0 0" damping="0.09933709999998558" limited="false" name="rootx" type="slide" />
      <joint armature="0" axis="0 1 0" damping="0.16587018064620374" limited="false" name="rooty" type="hinge" />
      <geom density="1419.8776221393762" friction="0.757673016495004 0.10847507422757048 0.06857607124323022" name="torso" size="0.07 0.3" />
      <body name="right_thigh" pos="0 -.05 -0.3">
        <joint damping="0.05748690127404528" name="right_hip" range="-20 100" />
        <geom density="724.644275433269" friction="1.2294240496566797 0.06602141854805647 0.10775638036597146" name="right_thigh" pos="0 0 -0.225" size="0.05 0.225" />
        <body name="right_leg" pos="0 0 -0.7">
          <joint damping="0.1749930311445029" name="right_knee" pos="0 0 0.25" range="-150 0" />
          <geom density="502.4307082466207" friction="0.36489702861243545 0.08543555212849104 0.12196196634248785" name="right_leg" size="0.04 0.25" />
          <body name="right_foot" pos="0.06 0 -0.25">
            <joint damping="0.10652251916867084" name="right_ankle" pos="-0.06 0 0" range="-45 45" />
            <geom density="872.9564948454898" friction="0.48123929059921877 0.14999419241102033 0.18869729474302901" name="right_foot" size="0.05 0.20102697106264983" zaxis="1 0 0" />
          </body>
        </body>
      </body>
      <body name="left_thigh" pos="0 .05 -0.3">
        <joint damping="0.12229176946041818" name="left_hip" range="-20 100" />
        <geom density="581.4385216049205" friction="0.6551307783806328 0.16072555416812193 0.11020928038130949" name="left_thigh" pos="0 0 -0.225" size="0.05 0.225" />
        <body name="left_leg" pos="0 0 -0.7">
          <joint damping="0.08305918907918321" name="left_knee" pos="0 0 0.25" range="-150 0" />
          <geom density="828.0490435919406" friction="0.3271354904981617 0.04880787984662728 0.09721096163150861" name="left_leg" size="0.04 0.25" />
          <body name="left_foot" pos="0.06 0 -0.25">
            <joint damping="0.16096852328903255" name="left_ankle" pos="-0.06 0 0" range="-45 45" />
            <geom density="1783.6329822407392" friction="0.748136686771134 0.1114443429857047 0.07440342553489561" name="left_foot" size="0.05 0.09328891730658957" zaxis="1 0 0" />
          </body>
        </body>
      </body>
    </body>
  </worldbody>

  <sensor>
    <subtreelinvel body="torso" name="torso_subtreelinvel" />
  </sensor>

  <actuator>
    <motor gear="100" joint="right_hip" name="right_hip" />
    <motor gear="50" joint="right_knee" name="right_knee" />
    <motor gear="20" joint="right_ankle" name="right_ankle" />
    <motor gear="100" joint="left_hip" name="left_hip" />
    <motor gear="50" joint="left_knee" name="left_knee" />
    <motor gear="20" joint="left_ankle" name="left_ankle" />
  </actuator>
</mujoco>