<mujoco model="planar walker">
  <include file="./common/visual.xml" />
  <include file="./common/skybox.xml" />
  <include file="./common/materials.xml" />

  <option timestep="0.0025" />

  <statistic center="0 0 1" extent="2" />

  <default>
    <joint armature="0.01" damping=".1" limited="true" solimplimit="0 .99 .01" />
    <geom conaffinity="0" contype="1" friction=".7 .1 .1" />
    <motor ctrllimited="true" ctrlrange="-1 1" />
    <site size="0.01" />
    <default class="walker">
      <geom material="self" type="capsule" />
      <joint axis="0 -1 0" />
    </default>
  </default>

  <worldbody>
    <geom conaffinity="1" material="grid" name="floor" pos="248 0 0" size="250 .8 .2" type="plane" zaxis="0.025330473891645628 0.0 0.9996791320680974" />
    <body childclass="walker" name="torso" pos="0.08464134189017614 0.0 7.581893351541735">
      <light mode="trackcom" name="light" pos="0 0 2" />
      <camera euler="60 0 0" mode="trackcom" name="side" pos="0 -2 .7" />
      <camera mode="trackcom" name="back" pos="-2 0 .5" xyaxes="0 -1 0 1 0 3" />
      <joint armature="0" axis="0 0 1" damping="0.12291632613728026" limited="false" name="rootz" type="slide" />
      <joint armature="0" axis="1 0 0" damping="0.06636516510627594" limited="false" name="rootx" type="slide" />
      <joint armature="0" axis="0 1 0" damping="0.1706401301275926" limited="false" name="rooty" type="hinge" />
      <geom density="1233.0542329670911" friction="1.260878821456935 0.13222681301711606 0.08024573902759434" name="torso" size="0.07 0.3" />
      <body name="right_thigh" pos="0 -.05 -0.3">
        <joint damping="0.07834828970924355" name="right_hip" range="-20 100" />
        <geom density="1158.769310038172" friction="1.0619924416190678 0.07390117938617738 0.08423576705343909" name="right_thigh" pos="0 0 -0.225" size="0.05 0.225" />
        <body name="right_leg" pos="0 0 -0.7">
          <joint damping="0.09387493178962134" name="right_knee" pos="0 0 0.25" range="-150 0" />
          <geom density="491.3072374401007" friction="0.6039531939670775 0.07841105097094804 0.08002710385288025" name="right_leg" size="0.04 0.25" />
          <body name="right_foot" pos="0.06 0 -0.25">
            <joint damping="0.17077970224856862" name="right_ankle" pos="-0.06 0 0" range="-45 45" />
            <geom density="698.4119839235218" friction="0.3313912388662992 0.1865633563935501 0.17108269574441118" name="right_foot" size="0.05 0.0717031632005921" zaxis="1 0 0" />
          </body>
        </body>
      </body>
      <body name="left_thigh" pos="0 .05 -0.3">
        <joint damping="0.08808389412454273" name="left_hip" range="-20 100" />
        <geom density="597.6183441275158" friction="1.1985184590212892 0.052382779431064244 0.1427017967108194" name="left_thigh" pos="0 0 -0.225" size="0.05 0.225" />
        <body name="left_leg" pos="0 0 -0.7">
          <joint damping="0.12223564704052775" name="left_knee" pos="0 0 0.25" range="-150 0" />
          <geom density="1202.6290350200416" friction="0.7107603832110049 0.1509181781969604 0.1385754618240663" name="left_leg" size="0.04 0.25" />
          <body name="left_foot" pos="0.06 0 -0.25">
            <joint damping="0.05306335971602172" name="left_ankle" pos="-0.06 0 0" range="-45 45" />
            <geom density="486.08360333980454" friction="0.6673219942472189 0.12377526117142319 0.06065289622773589" name="left_foot" size="0.05 0.09652325344598076" zaxis="1 0 0" />
          </body>
        </body>
      </body>
    </body>
  </worldbody>

  <sensor>
    <subtreelinvel body="torso" name="torso_subtreelinvel" />
  </sensor>

  <actuator>
    <motor gear="100" joint="right_hip" name="right_hip" />
    <motor gear="50" joint="right_knee" name="right_knee" />
    <motor gear="20" joint="right_ankle" name="right_ankle" />
    <motor gear="100" joint="left_hip" name="left_hip" />
    <motor gear="50" joint="left_knee" name="left_knee" />
    <motor gear="20" joint="left_ankle" name="left_ankle" />
  </actuator>
</mujoco>