<mujoco model="planar walker">
  <include file="./common/visual.xml" />
  <include file="./common/skybox.xml" />
  <include file="./common/materials.xml" />

  <option timestep="0.0025" />

  <statistic center="0 0 1" extent="2" />

  <default>
    <joint armature="0.01" damping=".1" limited="true" solimplimit="0 .99 .01" />
    <geom conaffinity="0" contype="1" friction=".7 .1 .1" />
    <motor ctrllimited="true" ctrlrange="-1 1" />
    <site size="0.01" />
    <default class="walker">
      <geom material="self" type="capsule" />
      <joint axis="0 -1 0" />
    </default>
  </default>

  <worldbody>
    <geom conaffinity="1" material="grid" name="floor" pos="248 0 0" size="250 .8 .2" type="plane" zaxis="0.07618986200514416 0.0 0.9970933280930312" />
    <body childclass="walker" name="torso" pos="0.7360926053292758 0.0 20.19450444289436">
      <light mode="trackcom" name="light" pos="0 0 2" />
      <camera euler="60 0 0" mode="trackcom" name="side" pos="0 -2 .7" />
      <camera mode="trackcom" name="back" pos="-2 0 .5" xyaxes="0 -1 0 1 0 3" />
      <joint armature="0" axis="0 0 1" damping="0.18335362790191959" limited="false" name="rootz" type="slide" />
      <joint armature="0" axis="1 0 0" damping="0.06070651431676508" limited="false" name="rootx" type="slide" />
      <joint armature="0" axis="0 1 0" damping="0.11199028961208567" limited="false" name="rooty" type="hinge" />
      <geom density="460.01821202594283" friction="1.1143870192833696 0.06270588424911148 0.06050652076828015" name="torso" size="0.07 0.3" />
      <body name="right_thigh" pos="0 -.05 -0.3">
        <joint damping="0.09577389458396432" name="right_hip" range="-20 100" />
        <geom density="1792.66379197281" friction="0.5553442649303693 0.046155256269570545 0.062286829843642824" name="right_thigh" pos="0 0 -0.225" size="0.05 0.225" />
        <body name="right_leg" pos="0 0 -0.7">
          <joint damping="0.14364772006585005" name="right_knee" pos="0 0 0.25" range="-150 0" />
          <geom density="961.6849391993173" friction="1.1764172380358524 0.08708311721475308 0.09797501685211783" name="right_leg" size="0.04 0.25" />
          <body name="right_foot" pos="0.06 0 -0.25">
            <joint damping="0.11437384012577263" name="right_ankle" pos="-0.06 0 0" range="-45 45" />
            <geom density="456.3755476279566" friction="0.5053370886676244 0.08531085918691729 0.055812959193523394" name="right_foot" size="0.05 0.20678629147692265" zaxis="1 0 0" />
          </body>
        </body>
      </body>
      <body name="left_thigh" pos="0 .05 -0.3">
        <joint damping="0.0939060038461992" name="left_hip" range="-20 100" />
        <geom density="486.21525616812704" friction="1.5252203836619225 0.20685061557303452 0.18399190217416156" name="left_thigh" pos="0 0 -0.225" size="0.05 0.225" />
        <body name="left_leg" pos="0 0 -0.7">
          <joint damping="0.19710383068744547" name="left_knee" pos="0 0 0.25" range="-150 0" />
          <geom density="770.308851125218" friction="1.2416928198591732 0.13167276363135777 0.19546747586301377" name="left_leg" size="0.04 0.25" />
          <body name="left_foot" pos="0.06 0 -0.25">
            <joint damping="0.07481414566076544" name="left_ankle" pos="-0.06 0 0" range="-45 45" />
            <geom density="1914.7783462077937" friction="0.6827411787910875 0.09593399316982083 0.20099176181462833" name="left_foot" size="0.05 0.05409080154361783" zaxis="1 0 0" />
          </body>
        </body>
      </body>
    </body>
  </worldbody>

  <sensor>
    <subtreelinvel body="torso" name="torso_subtreelinvel" />
  </sensor>

  <actuator>
    <motor gear="100" joint="right_hip" name="right_hip" />
    <motor gear="50" joint="right_knee" name="right_knee" />
    <motor gear="20" joint="right_ankle" name="right_ankle" />
    <motor gear="100" joint="left_hip" name="left_hip" />
    <motor gear="50" joint="left_knee" name="left_knee" />
    <motor gear="20" joint="left_ankle" name="left_ankle" />
  </actuator>
</mujoco>