<mujoco model="planar walker">
  <include file="./common/visual.xml" />
  <include file="./common/skybox.xml" />
  <include file="./common/materials.xml" />

  <option timestep="0.0025" />

  <statistic center="0 0 1" extent="2" />

  <default>
    <joint armature="0.01" damping=".1" limited="true" solimplimit="0 .99 .01" />
    <geom conaffinity="0" contype="1" friction=".7 .1 .1" />
    <motor ctrllimited="true" ctrlrange="-1 1" />
    <site size="0.01" />
    <default class="walker">
      <geom material="self" type="capsule" />
      <joint axis="0 -1 0" />
    </default>
  </default>

  <worldbody>
    <geom conaffinity="1" material="grid" name="floor" pos="248 0 0" size="250 .8 .2" type="plane" zaxis="0.10134993023569 0.0 0.9948508388905448" />
    <body childclass="walker" name="torso" pos="1.2972619411920334 0.0 26.43375286622923">
      <light mode="trackcom" name="light" pos="0 0 2" />
      <camera euler="60 0 0" mode="trackcom" name="side" pos="0 -2 .7" />
      <camera mode="trackcom" name="back" pos="-2 0 .5" xyaxes="0 -1 0 1 0 3" />
      <joint armature="0" axis="0 0 1" damping="0.154487373424735" limited="false" name="rootz" type="slide" />
      <joint armature="0" axis="1 0 0" damping="0.08194231290555885" limited="false" name="rootx" type="slide" />
      <joint armature="0" axis="0 1 0" damping="0.1408859159539738" limited="false" name="rooty" type="hinge" />
      <geom density="1645.5912716663543" friction="0.8811416527206675 0.11072168496318145 0.127736032814665" name="torso" size="0.07 0.3" />
      <body name="right_thigh" pos="0 -.05 -0.3">
        <joint damping="0.05781237835993221" name="right_hip" range="-20 100" />
        <geom density="1560.9746715205576" friction="0.5612146720083208 0.1457297983065931 0.09528791453576163" name="right_thigh" pos="0 0 -0.225" size="0.05 0.225" />
        <body name="right_leg" pos="0 0 -0.7">
          <joint damping="0.11070597509354851" name="right_knee" pos="0 0 0.25" range="-150 0" />
          <geom density="1489.8450991558616" friction="0.9814644178847506 0.09968195292542913 0.13617373269298813" name="right_leg" size="0.04 0.25" />
          <body name="right_foot" pos="0.06 0 -0.25">
            <joint damping="0.0662645396087375" name="right_ankle" pos="-0.06 0 0" range="-45 45" />
            <geom density="1091.9154955039385" friction="0.6389436705539738 0.046354620971732055 0.16775729876475354" name="right_foot" size="0.05 0.1729853484678227" zaxis="1 0 0" />
          </body>
        </body>
      </body>
      <body name="left_thigh" pos="0 .05 -0.3">
        <joint damping="0.14582184122990066" name="left_hip" range="-20 100" />
        <geom density="779.4063477078633" friction="0.9218282027385029 0.0568650478661652 0.06189736524176087" name="left_thigh" pos="0 0 -0.225" size="0.05 0.225" />
        <body name="left_leg" pos="0 0 -0.7">
          <joint damping="0.17430016534112427" name="left_knee" pos="0 0 0.25" range="-150 0" />
          <geom density="518.5467653102107" friction="0.7303348303124461 0.2075869958154887 0.21503393388509637" name="left_leg" size="0.04 0.25" />
          <body name="left_foot" pos="0.06 0 -0.25">
            <joint damping="0.056270418540637336" name="left_ankle" pos="-0.06 0 0" range="-45 45" />
            <geom density="1589.7533677477809" friction="0.47430242270933803 0.07691600911949598 0.17620942795593764" name="left_foot" size="0.05 0.08725088335680026" zaxis="1 0 0" />
          </body>
        </body>
      </body>
    </body>
  </worldbody>

  <sensor>
    <subtreelinvel body="torso" name="torso_subtreelinvel" />
  </sensor>

  <actuator>
    <motor gear="100" joint="right_hip" name="right_hip" />
    <motor gear="50" joint="right_knee" name="right_knee" />
    <motor gear="20" joint="right_ankle" name="right_ankle" />
    <motor gear="100" joint="left_hip" name="left_hip" />
    <motor gear="50" joint="left_knee" name="left_knee" />
    <motor gear="20" joint="left_ankle" name="left_ankle" />
  </actuator>
</mujoco>