<mujoco model="planar walker">
  <include file="./common/visual.xml" />
  <include file="./common/skybox.xml" />
  <include file="./common/materials.xml" />

  <option timestep="0.0025" />

  <statistic center="0 0 1" extent="2" />

  <default>
    <joint armature="0.01" damping=".1" limited="true" solimplimit="0 .99 .01" />
    <geom conaffinity="0" contype="1" friction=".7 .1 .1" />
    <motor ctrllimited="true" ctrlrange="-1 1" />
    <site size="0.01" />
    <default class="walker">
      <geom material="self" type="capsule" />
      <joint axis="0 -1 0" />
    </default>
  </default>

  <worldbody>
    <geom conaffinity="1" material="grid" name="floor" pos="248 0 0" size="250 .8 .2" type="plane" zaxis="-0.0884191417711722 0.0 0.9960833576405387" />
    <body childclass="walker" name="torso" pos="0.9536434767921946 0.0 -20.628730487722596">
      <light mode="trackcom" name="light" pos="0 0 2" />
      <camera euler="60 0 0" mode="trackcom" name="side" pos="0 -2 .7" />
      <camera mode="trackcom" name="back" pos="-2 0 .5" xyaxes="0 -1 0 1 0 3" />
      <joint armature="0" axis="0 0 1" damping="0.17239923904310744" limited="false" name="rootz" type="slide" />
      <joint armature="0" axis="1 0 0" damping="0.07578496828131984" limited="false" name="rootx" type="slide" />
      <joint armature="0" axis="0 1 0" damping="0.12498390710121213" limited="false" name="rooty" type="hinge" />
      <geom density="639.523320888975" friction="0.4794093539705482 0.05088620134035987 0.12734188447061476" name="torso" size="0.07 0.3" />
      <body name="right_thigh" pos="0 -.05 -0.3">
        <joint damping="0.19670609792063073" name="right_hip" range="-20 100" />
        <geom density="836.2657706910082" friction="1.0173052013004358 0.07351763170845566 0.21314830093419138" name="right_thigh" pos="0 0 -0.225" size="0.05 0.225" />
        <body name="right_leg" pos="0 0 -0.7">
          <joint damping="0.10502246784375885" name="right_knee" pos="0 0 0.25" range="-150 0" />
          <geom density="823.7503811020284" friction="0.544371100921816 0.09618945788112732 0.07191313271781405" name="right_leg" size="0.04 0.25" />
          <body name="right_foot" pos="0.06 0 -0.25">
            <joint damping="0.09513300674801606" name="right_ankle" pos="-0.06 0 0" range="-45 45" />
            <geom density="861.6507403053497" friction="0.9819370789820392 0.12836702891256588 0.051504519029260065" name="right_foot" size="0.05 0.06291053131130633" zaxis="1 0 0" />
          </body>
        </body>
      </body>
      <body name="left_thigh" pos="0 .05 -0.3">
        <joint damping="0.12854380484883327" name="left_hip" range="-20 100" />
        <geom density="632.7345052017943" friction="1.4074751470918598 0.06535236758248643 0.04704389402133957" name="left_thigh" pos="0 0 -0.225" size="0.05 0.225" />
        <body name="left_leg" pos="0 0 -0.7">
          <joint damping="0.09590024819783526" name="left_knee" pos="0 0 0.25" range="-150 0" />
          <geom density="1308.3838791593685" friction="1.1031845124226216 0.20940870855485116 0.14455180177283874" name="left_leg" size="0.04 0.25" />
          <body name="left_foot" pos="0.06 0 -0.25">
            <joint damping="0.06749567136942612" name="left_ankle" pos="-0.06 0 0" range="-45 45" />
            <geom density="2119.917947477342" friction="0.9514311130326318 0.10791057108765263 0.1475541073431946" name="left_foot" size="0.05 0.1957767145576512" zaxis="1 0 0" />
          </body>
        </body>
      </body>
    </body>
  </worldbody>

  <sensor>
    <subtreelinvel body="torso" name="torso_subtreelinvel" />
  </sensor>

  <actuator>
    <motor gear="100" joint="right_hip" name="right_hip" />
    <motor gear="50" joint="right_knee" name="right_knee" />
    <motor gear="20" joint="right_ankle" name="right_ankle" />
    <motor gear="100" joint="left_hip" name="left_hip" />
    <motor gear="50" joint="left_knee" name="left_knee" />
    <motor gear="20" joint="left_ankle" name="left_ankle" />
  </actuator>
</mujoco>