<mujoco model="planar walker">
  <include file="./common/visual.xml" />
  <include file="./common/skybox.xml" />
  <include file="./common/materials.xml" />

  <option timestep="0.0025" />

  <statistic center="0 0 1" extent="2" />

  <default>
    <joint armature="0.01" damping=".1" limited="true" solimplimit="0 .99 .01" />
    <geom conaffinity="0" contype="1" friction=".7 .1 .1" />
    <motor ctrllimited="true" ctrlrange="-1 1" />
    <site size="0.01" />
    <default class="walker">
      <geom material="self" type="capsule" />
      <joint axis="0 -1 0" />
    </default>
  </default>

  <worldbody>
    <geom conaffinity="1" material="grid" name="floor" pos="248 0 0" size="250 .8 .2" type="plane" zaxis="0.04048069070939844 0.0 0.999180320902934" />
    <body childclass="walker" name="torso" pos="0.2113765542142403 0.0 11.339047360111401">
      <light mode="trackcom" name="light" pos="0 0 2" />
      <camera euler="60 0 0" mode="trackcom" name="side" pos="0 -2 .7" />
      <camera mode="trackcom" name="back" pos="-2 0 .5" xyaxes="0 -1 0 1 0 3" />
      <joint armature="0" axis="0 0 1" damping="0.16201145458933064" limited="false" name="rootz" type="slide" />
      <joint armature="0" axis="1 0 0" damping="0.07703137815023423" limited="false" name="rootx" type="slide" />
      <joint armature="0" axis="0 1 0" damping="0.21170780564316374" limited="false" name="rooty" type="hinge" />
      <geom density="1325.7915198973094" friction="0.6654560115595428 0.05476823957180388 0.05087336911725272" name="torso" size="0.07 0.3" />
      <body name="right_thigh" pos="0 -.05 -0.3">
        <joint damping="0.1222211551216652" name="right_hip" range="-20 100" />
        <geom density="1344.9641480058747" friction="1.0458714784129293 0.09686893661063554 0.14236877093671899" name="right_thigh" pos="0 0 -0.225" size="0.05 0.225" />
        <body name="right_leg" pos="0 0 -0.7">
          <joint damping="0.17912092468950092" name="right_knee" pos="0 0 0.25" range="-150 0" />
          <geom density="488.9596875732663" friction="0.9342160830288176 0.14036728083654618 0.12783886196960367" name="right_leg" size="0.04 0.25" />
          <body name="right_foot" pos="0.06 0 -0.25">
            <joint damping="0.15419366787261982" name="right_ankle" pos="-0.06 0 0" range="-45 45" />
            <geom density="566.5030222098418" friction="0.738908808407066 0.08535272980420955 0.054505667831639786" name="right_foot" size="0.05 0.21806920843972055" zaxis="1 0 0" />
          </body>
        </body>
      </body>
      <body name="left_thigh" pos="0 .05 -0.3">
        <joint damping="0.13098281317256683" name="left_hip" range="-20 100" />
        <geom density="501.37405083148633" friction="0.8274152013717065 0.0811139693429705 0.08287161028479864" name="left_thigh" pos="0 0 -0.225" size="0.05 0.225" />
        <body name="left_leg" pos="0 0 -0.7">
          <joint damping="0.2076277882751706" name="left_knee" pos="0 0 0.25" range="-150 0" />
          <geom density="1485.9454831228027" friction="0.642236316514003 0.20409749099682256 0.1677935227046619" name="left_leg" size="0.04 0.25" />
          <body name="left_foot" pos="0.06 0 -0.25">
            <joint damping="0.046176414635113884" name="left_ankle" pos="-0.06 0 0" range="-45 45" />
            <geom density="1127.174370041896" friction="0.6016072141862412 0.1467587057788293 0.1989520412038525" name="left_foot" size="0.05 0.07746131921434077" zaxis="1 0 0" />
          </body>
        </body>
      </body>
    </body>
  </worldbody>

  <sensor>
    <subtreelinvel body="torso" name="torso_subtreelinvel" />
  </sensor>

  <actuator>
    <motor gear="100" joint="right_hip" name="right_hip" />
    <motor gear="50" joint="right_knee" name="right_knee" />
    <motor gear="20" joint="right_ankle" name="right_ankle" />
    <motor gear="100" joint="left_hip" name="left_hip" />
    <motor gear="50" joint="left_knee" name="left_knee" />
    <motor gear="20" joint="left_ankle" name="left_ankle" />
  </actuator>
</mujoco>