<mujoco model="planar walker">
  <include file="./common/visual.xml" />
  <include file="./common/skybox.xml" />
  <include file="./common/materials.xml" />

  <option timestep="0.0025" />

  <statistic center="0 0 1" extent="2" />

  <default>
    <joint armature="0.01" damping=".1" limited="true" solimplimit="0 .99 .01" />
    <geom conaffinity="0" contype="1" friction=".7 .1 .1" />
    <motor ctrllimited="true" ctrlrange="-1 1" />
    <site size="0.01" />
    <default class="walker">
      <geom material="self" type="capsule" />
      <joint axis="0 -1 0" />
    </default>
  </default>

  <worldbody>
    <geom conaffinity="1" material="grid" name="floor" pos="248 0 0" size="250 .8 .2" type="plane" zaxis="0.14755703018262267 0.0 0.9890535490273945" />
    <body childclass="walker" name="torso" pos="2.744231247242709 0.0 37.891954195095906">
      <light mode="trackcom" name="light" pos="0 0 2" />
      <camera euler="60 0 0" mode="trackcom" name="side" pos="0 -2 .7" />
      <camera mode="trackcom" name="back" pos="-2 0 .5" xyaxes="0 -1 0 1 0 3" />
      <joint armature="0" axis="0 0 1" damping="0.07639044029961564" limited="false" name="rootz" type="slide" />
      <joint armature="0" axis="1 0 0" damping="0.12939212177772924" limited="false" name="rootx" type="slide" />
      <joint armature="0" axis="0 1 0" damping="0.05802058436166363" limited="false" name="rooty" type="hinge" />
      <geom density="1773.8231805924984" friction="0.39847989505108833 0.06560298129572555 0.052133632100131735" name="torso" size="0.07 0.3" />
      <body name="right_thigh" pos="0 -.05 -0.3">
        <joint damping="0.08407377055269906" name="right_hip" range="-20 100" />
        <geom density="1114.2535678465977" friction="1.4930577614382061 0.08118767030479307 0.09566794229032839" name="right_thigh" pos="0 0 -0.225" size="0.05 0.225" />
        <body name="right_leg" pos="0 0 -0.7">
          <joint damping="0.09329059510290162" name="right_knee" pos="0 0 0.25" range="-150 0" />
          <geom density="887.0093551952347" friction="0.32055186902215743 0.11332737659048359 0.15161637257328842" name="right_leg" size="0.04 0.25" />
          <body name="right_foot" pos="0.06 0 -0.25">
            <joint damping="0.17532160732209756" name="right_ankle" pos="-0.06 0 0" range="-45 45" />
            <geom density="1220.946605920259" friction="0.40551148265262915 0.11238883511117992 0.06909496259057947" name="right_foot" size="0.05 0.06487937849452145" zaxis="1 0 0" />
          </body>
        </body>
      </body>
      <body name="left_thigh" pos="0 .05 -0.3">
        <joint damping="0.0616098669307045" name="left_hip" range="-20 100" />
        <geom density="685.9041645630998" friction="1.1746576864473408 0.11146423732055835 0.06687541687921249" name="left_thigh" pos="0 0 -0.225" size="0.05 0.225" />
        <body name="left_leg" pos="0 0 -0.7">
          <joint damping="0.10100966901083203" name="left_knee" pos="0 0 0.25" range="-150 0" />
          <geom density="1477.383345023198" friction="1.3244483019100293 0.05431881858222496 0.15642615052481512" name="left_leg" size="0.04 0.25" />
          <body name="left_foot" pos="0.06 0 -0.25">
            <joint damping="0.06745374059423555" name="left_ankle" pos="-0.06 0 0" range="-45 45" />
            <geom density="1232.1137667642297" friction="0.7225165527082591 0.1377036912537226 0.08146018725474415" name="left_foot" size="0.05 0.05431154410246635" zaxis="1 0 0" />
          </body>
        </body>
      </body>
    </body>
  </worldbody>

  <sensor>
    <subtreelinvel body="torso" name="torso_subtreelinvel" />
  </sensor>

  <actuator>
    <motor gear="100" joint="right_hip" name="right_hip" />
    <motor gear="50" joint="right_knee" name="right_knee" />
    <motor gear="20" joint="right_ankle" name="right_ankle" />
    <motor gear="100" joint="left_hip" name="left_hip" />
    <motor gear="50" joint="left_knee" name="left_knee" />
    <motor gear="20" joint="left_ankle" name="left_ankle" />
  </actuator>
</mujoco>