<mujoco model="planar walker">
  <include file="./common/visual.xml" />
  <include file="./common/skybox.xml" />
  <include file="./common/materials.xml" />

  <option timestep="0.0025" />

  <statistic center="0 0 1" extent="2" />

  <default>
    <joint armature="0.01" damping=".1" limited="true" solimplimit="0 .99 .01" />
    <geom conaffinity="0" contype="1" friction=".7 .1 .1" />
    <motor ctrllimited="true" ctrlrange="-1 1" />
    <site size="0.01" />
    <default class="walker">
      <geom material="self" type="capsule" />
      <joint axis="0 -1 0" />
    </default>
  </default>

  <worldbody>
    <geom conaffinity="1" material="grid" name="floor" pos="248 0 0" size="250 .8 .2" type="plane" zaxis="0.034408913923678966 0.0 0.9994078379933754" />
    <body childclass="walker" name="torso" pos="0.15373796042763388 0.0 9.833292220671058">
      <light mode="trackcom" name="light" pos="0 0 2" />
      <camera euler="60 0 0" mode="trackcom" name="side" pos="0 -2 .7" />
      <camera mode="trackcom" name="back" pos="-2 0 .5" xyaxes="0 -1 0 1 0 3" />
      <joint armature="0" axis="0 0 1" damping="0.072061832380751" limited="false" name="rootz" type="slide" />
      <joint armature="0" axis="1 0 0" damping="0.1078124453890981" limited="false" name="rootx" type="slide" />
      <joint armature="0" axis="0 1 0" damping="0.05895107056786349" limited="false" name="rooty" type="hinge" />
      <geom density="1768.343868541177" friction="0.4542846423498627 0.09143752684185574 0.1041897949794267" name="torso" size="0.07 0.3" />
      <body name="right_thigh" pos="0 -.05 -0.3">
        <joint damping="0.2193065973623253" name="right_hip" range="-20 100" />
        <geom density="1880.5716250477676" friction="0.8213769247070148 0.20858865069234214 0.04598922353669723" name="right_thigh" pos="0 0 -0.225" size="0.05 0.225" />
        <body name="right_leg" pos="0 0 -0.7">
          <joint damping="0.184646338565661" name="right_knee" pos="0 0 0.25" range="-150 0" />
          <geom density="2103.000008988509" friction="0.3480133060085646 0.07544771490265173 0.18533002678804888" name="right_leg" size="0.04 0.25" />
          <body name="right_foot" pos="0.06 0 -0.25">
            <joint damping="0.14293642189044284" name="right_ankle" pos="-0.06 0 0" range="-45 45" />
            <geom density="558.2482887553359" friction="0.46830769027040126 0.10170861201046928 0.12046716428820654" name="right_foot" size="0.05 0.10963762906651403" zaxis="1 0 0" />
          </body>
        </body>
      </body>
      <body name="left_thigh" pos="0 .05 -0.3">
        <joint damping="0.08167217956641626" name="left_hip" range="-20 100" />
        <geom density="1496.3789161799184" friction="0.3554956875536802 0.0876655533745175 0.08239539087847236" name="left_thigh" pos="0 0 -0.225" size="0.05 0.225" />
        <body name="left_leg" pos="0 0 -0.7">
          <joint damping="0.0638285087385747" name="left_knee" pos="0 0 0.25" range="-150 0" />
          <geom density="481.38333443358346" friction="0.9856041222634183 0.04817332621459665 0.05892292148331311" name="left_leg" size="0.04 0.25" />
          <body name="left_foot" pos="0.06 0 -0.25">
            <joint damping="0.07409449523648687" name="left_ankle" pos="-0.06 0 0" range="-45 45" />
            <geom density="459.16507732766524" friction="1.1178757224056166 0.08544728671551967 0.18479583370785888" name="left_foot" size="0.05 0.05820991319851063" zaxis="1 0 0" />
          </body>
        </body>
      </body>
    </body>
  </worldbody>

  <sensor>
    <subtreelinvel body="torso" name="torso_subtreelinvel" />
  </sensor>

  <actuator>
    <motor gear="100" joint="right_hip" name="right_hip" />
    <motor gear="50" joint="right_knee" name="right_knee" />
    <motor gear="20" joint="right_ankle" name="right_ankle" />
    <motor gear="100" joint="left_hip" name="left_hip" />
    <motor gear="50" joint="left_knee" name="left_knee" />
    <motor gear="20" joint="left_ankle" name="left_ankle" />
  </actuator>
</mujoco>