<mujoco model="planar walker">
  <include file="./common/visual.xml" />
  <include file="./common/skybox.xml" />
  <include file="./common/materials.xml" />

  <option timestep="0.0025" />

  <statistic center="0 0 1" extent="2" />

  <default>
    <joint armature="0.01" damping=".1" limited="true" solimplimit="0 .99 .01" />
    <geom conaffinity="0" contype="1" friction=".7 .1 .1" />
    <motor ctrllimited="true" ctrlrange="-1 1" />
    <site size="0.01" />
    <default class="walker">
      <geom material="self" type="capsule" />
      <joint axis="0 -1 0" />
    </default>
  </default>

  <worldbody>
    <geom conaffinity="1" material="grid" name="floor" pos="248 0 0" size="250 .8 .2" type="plane" zaxis="-0.16218056970468492 0.0 0.9867610971305384" />
    <body childclass="walker" name="torso" pos="3.250811797685543 0.0 -38.92342906733575">
      <light mode="trackcom" name="light" pos="0 0 2" />
      <camera euler="60 0 0" mode="trackcom" name="side" pos="0 -2 .7" />
      <camera mode="trackcom" name="back" pos="-2 0 .5" xyaxes="0 -1 0 1 0 3" />
      <joint armature="0" axis="0 0 1" damping="0.047502104910936864" limited="false" name="rootz" type="slide" />
      <joint armature="0" axis="1 0 0" damping="0.16395717392728995" limited="false" name="rootx" type="slide" />
      <joint armature="0" axis="0 1 0" damping="0.18591297348599375" limited="false" name="rooty" type="hinge" />
      <geom density="1584.0967640932618" friction="0.7351263277448515 0.06588181175265355 0.06977131714700863" name="torso" size="0.07 0.3" />
      <body name="right_thigh" pos="0 -.05 -0.3">
        <joint damping="0.06460325461143808" name="right_hip" range="-20 100" />
        <geom density="1139.922860701254" friction="0.3346753750310437 0.1715535276570418 0.08008102259346474" name="right_thigh" pos="0 0 -0.225" size="0.05 0.225" />
        <body name="right_leg" pos="0 0 -0.7">
          <joint damping="0.08741372811968731" name="right_knee" pos="0 0 0.25" range="-150 0" />
          <geom density="1482.008693061942" friction="1.0652398825440956 0.06974653071808457 0.0801694537092334" name="right_leg" size="0.04 0.25" />
          <body name="right_foot" pos="0.06 0 -0.25">
            <joint damping="0.09434904918020248" name="right_ankle" pos="-0.06 0 0" range="-45 45" />
            <geom density="1453.9081070974914" friction="0.36713029192237445 0.131468609475571 0.04868490334883571" name="right_foot" size="0.05 0.06222354830544485" zaxis="1 0 0" />
          </body>
        </body>
      </body>
      <body name="left_thigh" pos="0 .05 -0.3">
        <joint damping="0.2052679774224497" name="left_hip" range="-20 100" />
        <geom density="1231.8039100350195" friction="0.4590154516967741 0.06685677212411421 0.15218059577129817" name="left_thigh" pos="0 0 -0.225" size="0.05 0.225" />
        <body name="left_leg" pos="0 0 -0.7">
          <joint damping="0.17991299088424478" name="left_knee" pos="0 0 0.25" range="-150 0" />
          <geom density="585.4332437754612" friction="0.866923513315091 0.07170332807973288 0.16918470418387058" name="left_leg" size="0.04 0.25" />
          <body name="left_foot" pos="0.06 0 -0.25">
            <joint damping="0.1932473238312948" name="left_ankle" pos="-0.06 0 0" range="-45 45" />
            <geom density="627.0348565069727" friction="0.494819896307923 0.14143571693945847 0.11073019120537644" name="left_foot" size="0.05 0.06580195589046155" zaxis="1 0 0" />
          </body>
        </body>
      </body>
    </body>
  </worldbody>

  <sensor>
    <subtreelinvel body="torso" name="torso_subtreelinvel" />
  </sensor>

  <actuator>
    <motor gear="100" joint="right_hip" name="right_hip" />
    <motor gear="50" joint="right_knee" name="right_knee" />
    <motor gear="20" joint="right_ankle" name="right_ankle" />
    <motor gear="100" joint="left_hip" name="left_hip" />
    <motor gear="50" joint="left_knee" name="left_knee" />
    <motor gear="20" joint="left_ankle" name="left_ankle" />
  </actuator>
</mujoco>