<mujoco model="planar walker">
  <include file="./common/visual.xml" />
  <include file="./common/skybox.xml" />
  <include file="./common/materials.xml" />

  <option timestep="0.0025" />

  <statistic center="0 0 1" extent="2" />

  <default>
    <joint armature="0.01" damping=".1" limited="true" solimplimit="0 .99 .01" />
    <geom conaffinity="0" contype="1" friction=".7 .1 .1" />
    <motor ctrllimited="true" ctrlrange="-1 1" />
    <site size="0.01" />
    <default class="walker">
      <geom material="self" type="capsule" />
      <joint axis="0 -1 0" />
    </default>
  </default>

  <worldbody>
    <geom conaffinity="1" material="grid" name="floor" pos="248 0 0" size="250 .8 .2" type="plane" zaxis="0.10836688004768263 0.0 0.9941109693131502" />
    <body childclass="walker" name="torso" pos="1.4821529863482965 0.0 28.173808445687925">
      <light mode="trackcom" name="light" pos="0 0 2" />
      <camera euler="60 0 0" mode="trackcom" name="side" pos="0 -2 .7" />
      <camera mode="trackcom" name="back" pos="-2 0 .5" xyaxes="0 -1 0 1 0 3" />
      <joint armature="0" axis="0 0 1" damping="0.050259213269696304" limited="false" name="rootz" type="slide" />
      <joint armature="0" axis="1 0 0" damping="0.10488888055228257" limited="false" name="rootx" type="slide" />
      <joint armature="0" axis="0 1 0" damping="0.1620364170826859" limited="false" name="rooty" type="hinge" />
      <geom density="731.7323241741556" friction="0.6707512493682143 0.055508093996463906 0.17373612282998685" name="torso" size="0.07 0.3" />
      <body name="right_thigh" pos="0 -.05 -0.3">
        <joint damping="0.09939913731518767" name="right_hip" range="-20 100" />
        <geom density="630.2127154364696" friction="1.2315651352638182 0.09545005970872261 0.051756312269774875" name="right_thigh" pos="0 0 -0.225" size="0.05 0.225" />
        <body name="right_leg" pos="0 0 -0.7">
          <joint damping="0.09355656634118609" name="right_knee" pos="0 0 0.25" range="-150 0" />
          <geom density="473.1968932700734" friction="0.9006473045240491 0.0794426008092958 0.07532414714814269" name="right_leg" size="0.04 0.25" />
          <body name="right_foot" pos="0.06 0 -0.25">
            <joint damping="0.18435148771281887" name="right_ankle" pos="-0.06 0 0" range="-45 45" />
            <geom density="1217.2107096462726" friction="0.8877909883491898 0.19765052087515034 0.0646945002153642" name="right_foot" size="0.05 0.06455879564637404" zaxis="1 0 0" />
          </body>
        </body>
      </body>
      <body name="left_thigh" pos="0 .05 -0.3">
        <joint damping="0.059266325384177365" name="left_hip" range="-20 100" />
        <geom density="924.3885789187023" friction="0.9956637087814576 0.09688070600620917 0.04737108431171198" name="left_thigh" pos="0 0 -0.225" size="0.05 0.225" />
        <body name="left_leg" pos="0 0 -0.7">
          <joint damping="0.14666815679093742" name="left_knee" pos="0 0 0.25" range="-150 0" />
          <geom density="698.2065020927477" friction="0.6602959085972397 0.19314933348605487 0.05325509244785858" name="left_leg" size="0.04 0.25" />
          <body name="left_foot" pos="0.06 0 -0.25">
            <joint damping="0.21488457281766113" name="left_ankle" pos="-0.06 0 0" range="-45 45" />
            <geom density="748.0067468788939" friction="1.3966905667997538 0.07962900891900364 0.06983580330672218" name="left_foot" size="0.05 0.1974120708562374" zaxis="1 0 0" />
          </body>
        </body>
      </body>
    </body>
  </worldbody>

  <sensor>
    <subtreelinvel body="torso" name="torso_subtreelinvel" />
  </sensor>

  <actuator>
    <motor gear="100" joint="right_hip" name="right_hip" />
    <motor gear="50" joint="right_knee" name="right_knee" />
    <motor gear="20" joint="right_ankle" name="right_ankle" />
    <motor gear="100" joint="left_hip" name="left_hip" />
    <motor gear="50" joint="left_knee" name="left_knee" />
    <motor gear="20" joint="left_ankle" name="left_ankle" />
  </actuator>
</mujoco>