<mujoco model="planar walker">
  <include file="./common/visual.xml" />
  <include file="./common/skybox.xml" />
  <include file="./common/materials.xml" />

  <option timestep="0.0025" />

  <statistic center="0 0 1" extent="2" />

  <default>
    <joint armature="0.01" damping=".1" limited="true" solimplimit="0 .99 .01" />
    <geom conaffinity="0" contype="1" friction=".7 .1 .1" />
    <motor ctrllimited="true" ctrlrange="-1 1" />
    <site size="0.01" />
    <default class="walker">
      <geom material="self" type="capsule" />
      <joint axis="0 -1 0" />
    </default>
  </default>

  <worldbody>
    <geom conaffinity="1" material="grid" name="floor" pos="248 0 0" size="250 .8 .2" type="plane" zaxis="0.19794135622240838 0.0 0.9802138641627314" />
    <body childclass="walker" name="torso" pos="4.94654995888709 0.0 50.38549911598983">
      <light mode="trackcom" name="light" pos="0 0 2" />
      <camera euler="60 0 0" mode="trackcom" name="side" pos="0 -2 .7" />
      <camera mode="trackcom" name="back" pos="-2 0 .5" xyaxes="0 -1 0 1 0 3" />
      <joint armature="0" axis="0 0 1" damping="0.05605492648977947" limited="false" name="rootz" type="slide" />
      <joint armature="0" axis="1 0 0" damping="0.14079017866195384" limited="false" name="rootx" type="slide" />
      <joint armature="0" axis="0 1 0" damping="0.1420262040253992" limited="false" name="rooty" type="hinge" />
      <geom density="1487.3004724049256" friction="1.2967218801007636 0.13073586130044088 0.1363387108564695" name="torso" size="0.07 0.3" />
      <body name="right_thigh" pos="0 -.05 -0.3">
        <joint damping="0.05784710134026018" name="right_hip" range="-20 100" />
        <geom density="1130.309457419673" friction="0.4608352161767756 0.08443487325311243 0.05226836595400367" name="right_thigh" pos="0 0 -0.225" size="0.05 0.225" />
        <body name="right_leg" pos="0 0 -0.7">
          <joint damping="0.19659013203752645" name="right_knee" pos="0 0 0.25" range="-150 0" />
          <geom density="980.2180754734113" friction="0.6017018642626742 0.18739669308807402 0.07193481782122554" name="right_leg" size="0.04 0.25" />
          <body name="right_foot" pos="0.06 0 -0.25">
            <joint damping="0.09185733620096698" name="right_ankle" pos="-0.06 0 0" range="-45 45" />
            <geom density="494.17370970197044" friction="1.3225368230677952 0.15013814224546945 0.11248833042376333" name="right_foot" size="0.05 0.09019381013268378" zaxis="1 0 0" />
          </body>
        </body>
      </body>
      <body name="left_thigh" pos="0 .05 -0.3">
        <joint damping="0.08051726622421962" name="left_hip" range="-20 100" />
        <geom density="1044.1414227102905" friction="1.5288853643063929 0.1621514130650968 0.09524071052254206" name="left_thigh" pos="0 0 -0.225" size="0.05 0.225" />
        <body name="left_leg" pos="0 0 -0.7">
          <joint damping="0.05328639436446826" name="left_knee" pos="0 0 0.25" range="-150 0" />
          <geom density="1351.7878751816224" friction="1.126125728132258 0.11354239052167894 0.20806594619426547" name="left_leg" size="0.04 0.25" />
          <body name="left_foot" pos="0.06 0 -0.25">
            <joint damping="0.04955200157531647" name="left_ankle" pos="-0.06 0 0" range="-45 45" />
            <geom density="1197.353653999828" friction="0.4905901606138046 0.05667641226513978 0.08399643275989815" name="left_foot" size="0.05 0.07695611498263427" zaxis="1 0 0" />
          </body>
        </body>
      </body>
    </body>
  </worldbody>

  <sensor>
    <subtreelinvel body="torso" name="torso_subtreelinvel" />
  </sensor>

  <actuator>
    <motor gear="100" joint="right_hip" name="right_hip" />
    <motor gear="50" joint="right_knee" name="right_knee" />
    <motor gear="20" joint="right_ankle" name="right_ankle" />
    <motor gear="100" joint="left_hip" name="left_hip" />
    <motor gear="50" joint="left_knee" name="left_knee" />
    <motor gear="20" joint="left_ankle" name="left_ankle" />
  </actuator>
</mujoco>