<mujoco model="planar walker">
  <include file="./common/visual.xml" />
  <include file="./common/skybox.xml" />
  <include file="./common/materials.xml" />

  <option timestep="0.0025" />

  <statistic center="0 0 1" extent="2" />

  <default>
    <joint armature="0.01" damping=".1" limited="true" solimplimit="0 .99 .01" />
    <geom conaffinity="0" contype="1" friction=".7 .1 .1" />
    <motor ctrllimited="true" ctrlrange="-1 1" />
    <site size="0.01" />
    <default class="walker">
      <geom material="self" type="capsule" />
      <joint axis="0 -1 0" />
    </default>
  </default>

  <worldbody>
    <geom conaffinity="1" material="grid" name="floor" pos="248 0 0" size="250 .8 .2" type="plane" zaxis="0.043560069558188766 0.0 0.9990508096889196" />
    <body childclass="walker" name="torso" pos="0.24411121105958955 0.0 12.102707412368597">
      <light mode="trackcom" name="light" pos="0 0 2" />
      <camera euler="60 0 0" mode="trackcom" name="side" pos="0 -2 .7" />
      <camera mode="trackcom" name="back" pos="-2 0 .5" xyaxes="0 -1 0 1 0 3" />
      <joint armature="0" axis="0 0 1" damping="0.16858236852256184" limited="false" name="rootz" type="slide" />
      <joint armature="0" axis="1 0 0" damping="0.05087346311027328" limited="false" name="rootx" type="slide" />
      <joint armature="0" axis="0 1 0" damping="0.09177924311377315" limited="false" name="rooty" type="hinge" />
      <geom density="557.3096677878219" friction="1.4205842327569767 0.11177436503753005 0.16412231588600668" name="torso" size="0.07 0.3" />
      <body name="right_thigh" pos="0 -.05 -0.3">
        <joint damping="0.11940391546143017" name="right_hip" range="-20 100" />
        <geom density="544.3911880593714" friction="0.7028688587360326 0.09088452902442398 0.050828251069820474" name="right_thigh" pos="0 0 -0.225" size="0.05 0.225" />
        <body name="right_leg" pos="0 0 -0.7">
          <joint damping="0.14467337778834474" name="right_knee" pos="0 0 0.25" range="-150 0" />
          <geom density="1911.7360333370243" friction="0.5818929939312564 0.056954301316093275 0.096716405729847" name="right_leg" size="0.04 0.25" />
          <body name="right_foot" pos="0.06 0 -0.25">
            <joint damping="0.13958350819050133" name="right_ankle" pos="-0.06 0 0" range="-45 45" />
            <geom density="761.8234899226784" friction="0.957517012324278 0.059608183387021355 0.20169658206230423" name="right_foot" size="0.05 0.06993046332891759" zaxis="1 0 0" />
          </body>
        </body>
      </body>
      <body name="left_thigh" pos="0 .05 -0.3">
        <joint damping="0.0756518674765039" name="left_hip" range="-20 100" />
        <geom density="521.0167696438234" friction="0.41047999593412576 0.17329548319004662 0.052260263685196956" name="left_thigh" pos="0 0 -0.225" size="0.05 0.225" />
        <body name="left_leg" pos="0 0 -0.7">
          <joint damping="0.14432094483185856" name="left_knee" pos="0 0 0.25" range="-150 0" />
          <geom density="1263.7845032233606" friction="0.6029718699141325 0.05572652603171757 0.051875335494927594" name="left_leg" size="0.04 0.25" />
          <body name="left_foot" pos="0.06 0 -0.25">
            <joint damping="0.06414096525835486" name="left_ankle" pos="-0.06 0 0" range="-45 45" />
            <geom density="1150.50757666507" friction="1.154533231855452 0.18826934319747526 0.17988254812728433" name="left_foot" size="0.05 0.11815455854212231" zaxis="1 0 0" />
          </body>
        </body>
      </body>
    </body>
  </worldbody>

  <sensor>
    <subtreelinvel body="torso" name="torso_subtreelinvel" />
  </sensor>

  <actuator>
    <motor gear="100" joint="right_hip" name="right_hip" />
    <motor gear="50" joint="right_knee" name="right_knee" />
    <motor gear="20" joint="right_ankle" name="right_ankle" />
    <motor gear="100" joint="left_hip" name="left_hip" />
    <motor gear="50" joint="left_knee" name="left_knee" />
    <motor gear="20" joint="left_ankle" name="left_ankle" />
  </actuator>
</mujoco>