<mujoco model="planar walker">
  <include file="./common/visual.xml" />
  <include file="./common/skybox.xml" />
  <include file="./common/materials.xml" />

  <option timestep="0.0025" />

  <statistic center="0 0 1" extent="2" />

  <default>
    <joint armature="0.01" damping=".1" limited="true" solimplimit="0 .99 .01" />
    <geom conaffinity="0" contype="1" friction=".7 .1 .1" />
    <motor ctrllimited="true" ctrlrange="-1 1" />
    <site size="0.01" />
    <default class="walker">
      <geom material="self" type="capsule" />
      <joint axis="0 -1 0" />
    </default>
  </default>

  <worldbody>
    <geom conaffinity="1" material="grid" name="floor" pos="248 0 0" size="250 .8 .2" type="plane" zaxis="0.09666373931947465 0.0 0.9953170959552421" />
    <body childclass="walker" name="torso" pos="1.1806929509638735 0.0 25.271670770420766">
      <light mode="trackcom" name="light" pos="0 0 2" />
      <camera euler="60 0 0" mode="trackcom" name="side" pos="0 -2 .7" />
      <camera mode="trackcom" name="back" pos="-2 0 .5" xyaxes="0 -1 0 1 0 3" />
      <joint armature="0" axis="0 0 1" damping="0.13945554023992415" limited="false" name="rootz" type="slide" />
      <joint armature="0" axis="1 0 0" damping="0.1359511549132573" limited="false" name="rootx" type="slide" />
      <joint armature="0" axis="0 1 0" damping="0.19164069803517958" limited="false" name="rooty" type="hinge" />
      <geom density="1477.4916866454237" friction="1.5190287295865585 0.05455886844610918 0.11347408943516742" name="torso" size="0.07 0.3" />
      <body name="right_thigh" pos="0 -.05 -0.3">
        <joint damping="0.21910608816450214" name="right_hip" range="-20 100" />
        <geom density="1400.3149575324458" friction="0.5197512510991417 0.04923404829548965 0.06639959894071486" name="right_thigh" pos="0 0 -0.225" size="0.05 0.225" />
        <body name="right_leg" pos="0 0 -0.7">
          <joint damping="0.19582507830673518" name="right_knee" pos="0 0 0.25" range="-150 0" />
          <geom density="664.4565600864411" friction="1.365477817249842 0.13238987514423423 0.14361690370200797" name="right_leg" size="0.04 0.25" />
          <body name="right_foot" pos="0.06 0 -0.25">
            <joint damping="0.16384049277332624" name="right_ankle" pos="-0.06 0 0" range="-45 45" />
            <geom density="1871.134007264171" friction="1.1899664015777547 0.08118973416954713 0.06950378614371994" name="right_foot" size="0.05 0.11677341306152973" zaxis="1 0 0" />
          </body>
        </body>
      </body>
      <body name="left_thigh" pos="0 .05 -0.3">
        <joint damping="0.0955545426941841" name="left_hip" range="-20 100" />
        <geom density="464.7156186795495" friction="0.45336722527930207 0.07067128655084294 0.0703056037763879" name="left_thigh" pos="0 0 -0.225" size="0.05 0.225" />
        <body name="left_leg" pos="0 0 -0.7">
          <joint damping="0.1914713851403455" name="left_knee" pos="0 0 0.25" range="-150 0" />
          <geom density="1153.762559364" friction="0.751759275363367 0.05276123127288238 0.0502069155041225" name="left_leg" size="0.04 0.25" />
          <body name="left_foot" pos="0.06 0 -0.25">
            <joint damping="0.06648379005005703" name="left_ankle" pos="-0.06 0 0" range="-45 45" />
            <geom density="1648.1925580352304" friction="0.3235163231402518 0.06916315241395489 0.1272590247513974" name="left_foot" size="0.05 0.11629010976283548" zaxis="1 0 0" />
          </body>
        </body>
      </body>
    </body>
  </worldbody>

  <sensor>
    <subtreelinvel body="torso" name="torso_subtreelinvel" />
  </sensor>

  <actuator>
    <motor gear="100" joint="right_hip" name="right_hip" />
    <motor gear="50" joint="right_knee" name="right_knee" />
    <motor gear="20" joint="right_ankle" name="right_ankle" />
    <motor gear="100" joint="left_hip" name="left_hip" />
    <motor gear="50" joint="left_knee" name="left_knee" />
    <motor gear="20" joint="left_ankle" name="left_ankle" />
  </actuator>
</mujoco>