<mujoco model="planar walker">
  <include file="./common/visual.xml" />
  <include file="./common/skybox.xml" />
  <include file="./common/materials.xml" />

  <option timestep="0.0025" />

  <statistic center="0 0 1" extent="2" />

  <default>
    <joint armature="0.01" damping=".1" limited="true" solimplimit="0 .99 .01" />
    <geom conaffinity="0" contype="1" friction=".7 .1 .1" />
    <motor ctrllimited="true" ctrlrange="-1 1" />
    <site size="0.01" />
    <default class="walker">
      <geom material="self" type="capsule" />
      <joint axis="0 -1 0" />
    </default>
  </default>

  <worldbody>
    <geom conaffinity="1" material="grid" name="floor" pos="248 0 0" size="250 .8 .2" type="plane" zaxis="-0.18149953746974756 0.0 0.98339103000702" />
    <body childclass="walker" name="torso" pos="4.082724650765101 0.0 -43.715207086495994">
      <light mode="trackcom" name="light" pos="0 0 2" />
      <camera euler="60 0 0" mode="trackcom" name="side" pos="0 -2 .7" />
      <camera mode="trackcom" name="back" pos="-2 0 .5" xyaxes="0 -1 0 1 0 3" />
      <joint armature="0" axis="0 0 1" damping="0.06108575481041933" limited="false" name="rootz" type="slide" />
      <joint armature="0" axis="1 0 0" damping="0.06571089699038117" limited="false" name="rootx" type="slide" />
      <joint armature="0" axis="0 1 0" damping="0.05127453174836575" limited="false" name="rooty" type="hinge" />
      <geom density="529.7128462764387" friction="0.6103619786961175 0.05362064955668377 0.045570493578065786" name="torso" size="0.07 0.3" />
      <body name="right_thigh" pos="0 -.05 -0.3">
        <joint damping="0.1185766690522697" name="right_hip" range="-20 100" />
        <geom density="2139.721630531313" friction="0.615610411056692 0.046188803840064095 0.07200006785706613" name="right_thigh" pos="0 0 -0.225" size="0.05 0.225" />
        <body name="right_leg" pos="0 0 -0.7">
          <joint damping="0.07238978654475574" name="right_knee" pos="0 0 0.25" range="-150 0" />
          <geom density="1044.3431806010922" friction="0.6695632766469823 0.06789461001227715 0.06892592937924748" name="right_leg" size="0.04 0.25" />
          <body name="right_foot" pos="0.06 0 -0.25">
            <joint damping="0.17435666647241438" name="right_ankle" pos="-0.06 0 0" range="-45 45" />
            <geom density="1497.1280356833065" friction="0.8405603078791889 0.06327990057088266 0.17357294131096365" name="right_foot" size="0.05 0.054884078405252196" zaxis="1 0 0" />
          </body>
        </body>
      </body>
      <body name="left_thigh" pos="0 .05 -0.3">
        <joint damping="0.07222261170224996" name="left_hip" range="-20 100" />
        <geom density="1508.0801004847917" friction="0.7132962228317558 0.0460300110801114 0.0663229019350224" name="left_thigh" pos="0 0 -0.225" size="0.05 0.225" />
        <body name="left_leg" pos="0 0 -0.7">
          <joint damping="0.1073718661918673" name="left_knee" pos="0 0 0.25" range="-150 0" />
          <geom density="1097.267997281407" friction="0.4663109912992763 0.10189036477110268 0.07239152070911678" name="left_leg" size="0.04 0.25" />
          <body name="left_foot" pos="0.06 0 -0.25">
            <joint damping="0.08017115506524512" name="left_ankle" pos="-0.06 0 0" range="-45 45" />
            <geom density="2172.5908163117883" friction="0.4207801950614178 0.2039008675837359 0.07412109094542828" name="left_foot" size="0.05 0.08621439459716455" zaxis="1 0 0" />
          </body>
        </body>
      </body>
    </body>
  </worldbody>

  <sensor>
    <subtreelinvel body="torso" name="torso_subtreelinvel" />
  </sensor>

  <actuator>
    <motor gear="100" joint="right_hip" name="right_hip" />
    <motor gear="50" joint="right_knee" name="right_knee" />
    <motor gear="20" joint="right_ankle" name="right_ankle" />
    <motor gear="100" joint="left_hip" name="left_hip" />
    <motor gear="50" joint="left_knee" name="left_knee" />
    <motor gear="20" joint="left_ankle" name="left_ankle" />
  </actuator>
</mujoco>