<mujoco model="planar walker">
  <include file="./common/visual.xml" />
  <include file="./common/skybox.xml" />
  <include file="./common/materials.xml" />

  <option timestep="0.0025" />

  <statistic center="0 0 1" extent="2" />

  <default>
    <joint armature="0.01" damping=".1" limited="true" solimplimit="0 .99 .01" />
    <geom conaffinity="0" contype="1" friction=".7 .1 .1" />
    <motor ctrllimited="true" ctrlrange="-1 1" />
    <site size="0.01" />
    <default class="walker">
      <geom material="self" type="capsule" />
      <joint axis="0 -1 0" />
    </default>
  </default>

  <worldbody>
    <geom conaffinity="1" material="grid" name="floor" pos="248 0 0" size="250 .8 .2" type="plane" zaxis="-0.19150325103895646 0.0 0.9814919790000887" />
    <body childclass="walker" name="torso" pos="4.551688557770234 0.0 -46.19650786186118">
      <light mode="trackcom" name="light" pos="0 0 2" />
      <camera euler="60 0 0" mode="trackcom" name="side" pos="0 -2 .7" />
      <camera mode="trackcom" name="back" pos="-2 0 .5" xyaxes="0 -1 0 1 0 3" />
      <joint armature="0" axis="0 0 1" damping="0.07787226090226183" limited="false" name="rootz" type="slide" />
      <joint armature="0" axis="1 0 0" damping="0.13151607667276868" limited="false" name="rootx" type="slide" />
      <joint armature="0" axis="0 1 0" damping="0.10406461201018735" limited="false" name="rooty" type="hinge" />
      <geom density="983.8510634661985" friction="1.2273213982186966 0.10846008177404431 0.06312788054583612" name="torso" size="0.07 0.3" />
      <body name="right_thigh" pos="0 -.05 -0.3">
        <joint damping="0.05005229928269082" name="right_hip" range="-20 100" />
        <geom density="857.9427643857501" friction="0.3407834603017141 0.1541734075349718 0.19717862246750176" name="right_thigh" pos="0 0 -0.225" size="0.05 0.225" />
        <body name="right_leg" pos="0 0 -0.7">
          <joint damping="0.10867459287033464" name="right_knee" pos="0 0 0.25" range="-150 0" />
          <geom density="704.0522270335574" friction="0.5005295686693954 0.049207384140672855 0.10709658976568351" name="right_leg" size="0.04 0.25" />
          <body name="right_foot" pos="0.06 0 -0.25">
            <joint damping="0.1370240575177734" name="right_ankle" pos="-0.06 0 0" range="-45 45" />
            <geom density="1135.4030618842057" friction="1.2339746034542933 0.055351522101746035 0.09336187619032933" name="right_foot" size="0.05 0.09880205257186203" zaxis="1 0 0" />
          </body>
        </body>
      </body>
      <body name="left_thigh" pos="0 .05 -0.3">
        <joint damping="0.09915109387784965" name="left_hip" range="-20 100" />
        <geom density="591.4897423919641" friction="0.8474289424632171 0.04903021462999929 0.06774679730393833" name="left_thigh" pos="0 0 -0.225" size="0.05 0.225" />
        <body name="left_leg" pos="0 0 -0.7">
          <joint damping="0.08808308352640298" name="left_knee" pos="0 0 0.25" range="-150 0" />
          <geom density="2186.1593833587663" friction="1.443740893850599 0.07212908512780601 0.1749837436616497" name="left_leg" size="0.04 0.25" />
          <body name="left_foot" pos="0.06 0 -0.25">
            <joint damping="0.05299552959624502" name="left_ankle" pos="-0.06 0 0" range="-45 45" />
            <geom density="2090.7246591684616" friction="0.549591420977842 0.1851952267483191 0.1882416512499707" name="left_foot" size="0.05 0.04900587207621466" zaxis="1 0 0" />
          </body>
        </body>
      </body>
    </body>
  </worldbody>

  <sensor>
    <subtreelinvel body="torso" name="torso_subtreelinvel" />
  </sensor>

  <actuator>
    <motor gear="100" joint="right_hip" name="right_hip" />
    <motor gear="50" joint="right_knee" name="right_knee" />
    <motor gear="20" joint="right_ankle" name="right_ankle" />
    <motor gear="100" joint="left_hip" name="left_hip" />
    <motor gear="50" joint="left_knee" name="left_knee" />
    <motor gear="20" joint="left_ankle" name="left_ankle" />
  </actuator>
</mujoco>