<mujoco model="planar walker">
  <include file="./common/visual.xml" />
  <include file="./common/skybox.xml" />
  <include file="./common/materials.xml" />

  <option timestep="0.0025" />

  <statistic center="0 0 1" extent="2" />

  <default>
    <joint armature="0.01" damping=".1" limited="true" solimplimit="0 .99 .01" />
    <geom conaffinity="0" contype="1" friction=".7 .1 .1" />
    <motor ctrllimited="true" ctrlrange="-1 1" />
    <site size="0.01" />
    <default class="walker">
      <geom material="self" type="capsule" />
      <joint axis="0 -1 0" />
    </default>
  </default>

  <worldbody>
    <geom conaffinity="1" material="grid" name="floor" pos="248 0 0" size="250 .8 .2" type="plane" zaxis="-0.00823550733688642 0.0 0.9999660876344277" />
    <body childclass="walker" name="torso" pos="0.006763165194541898 0.0 -0.7424126020209463">
      <light mode="trackcom" name="light" pos="0 0 2" />
      <camera euler="60 0 0" mode="trackcom" name="side" pos="0 -2 .7" />
      <camera mode="trackcom" name="back" pos="-2 0 .5" xyaxes="0 -1 0 1 0 3" />
      <joint armature="0" axis="0 0 1" damping="0.08259514877619308" limited="false" name="rootz" type="slide" />
      <joint armature="0" axis="1 0 0" damping="0.07894347405720688" limited="false" name="rootx" type="slide" />
      <joint armature="0" axis="0 1 0" damping="0.18494577701898185" limited="false" name="rooty" type="hinge" />
      <geom density="628.0081379064899" friction="1.3302377510850687 0.05101747786714981 0.12183178764405916" name="torso" size="0.07 0.3" />
      <body name="right_thigh" pos="0 -.05 -0.3">
        <joint damping="0.1580841261552631" name="right_hip" range="-20 100" />
        <geom density="930.5445079087968" friction="0.38745637169094815 0.07745867649090703 0.1688235154301262" name="right_thigh" pos="0 0 -0.225" size="0.05 0.225" />
        <body name="right_leg" pos="0 0 -0.7">
          <joint damping="0.06804778150614396" name="right_knee" pos="0 0 0.25" range="-150 0" />
          <geom density="527.3637822421244" friction="1.2056295549480622 0.1480817920819817 0.09345775591508" name="right_leg" size="0.04 0.25" />
          <body name="right_foot" pos="0.06 0 -0.25">
            <joint damping="0.1275233458030262" name="right_ankle" pos="-0.06 0 0" range="-45 45" />
            <geom density="1372.1352113804219" friction="0.8056984900159169 0.06281320232446008 0.18677682311958407" name="right_foot" size="0.05 0.08912210351691857" zaxis="1 0 0" />
          </body>
        </body>
      </body>
      <body name="left_thigh" pos="0 .05 -0.3">
        <joint damping="0.04934959447875445" name="left_hip" range="-20 100" />
        <geom density="878.8546559616432" friction="0.6654347062484971 0.050009668429382564 0.13943177391719683" name="left_thigh" pos="0 0 -0.225" size="0.05 0.225" />
        <body name="left_leg" pos="0 0 -0.7">
          <joint damping="0.11752677026694025" name="left_knee" pos="0 0 0.25" range="-150 0" />
          <geom density="823.8476068576302" friction="1.0713828215766574 0.13161882664732197 0.05741658578138906" name="left_leg" size="0.04 0.25" />
          <body name="left_foot" pos="0.06 0 -0.25">
            <joint damping="0.05556241095854156" name="left_ankle" pos="-0.06 0 0" range="-45 45" />
            <geom density="501.83303029266193" friction="1.1384646218389691 0.07831338516724572 0.07919950162949335" name="left_foot" size="0.05 0.11418424872276622" zaxis="1 0 0" />
          </body>
        </body>
      </body>
    </body>
  </worldbody>

  <sensor>
    <subtreelinvel body="torso" name="torso_subtreelinvel" />
  </sensor>

  <actuator>
    <motor gear="100" joint="right_hip" name="right_hip" />
    <motor gear="50" joint="right_knee" name="right_knee" />
    <motor gear="20" joint="right_ankle" name="right_ankle" />
    <motor gear="100" joint="left_hip" name="left_hip" />
    <motor gear="50" joint="left_knee" name="left_knee" />
    <motor gear="20" joint="left_ankle" name="left_ankle" />
  </actuator>
</mujoco>