<mujoco model="planar walker">
  <include file="./common/visual.xml" />
  <include file="./common/skybox.xml" />
  <include file="./common/materials.xml" />

  <option timestep="0.0025" />

  <statistic center="0 0 1" extent="2" />

  <default>
    <joint armature="0.01" damping=".1" limited="true" solimplimit="0 .99 .01" />
    <geom conaffinity="0" contype="1" friction=".7 .1 .1" />
    <motor ctrllimited="true" ctrlrange="-1 1" />
    <site size="0.01" />
    <default class="walker">
      <geom material="self" type="capsule" />
      <joint axis="0 -1 0" />
    </default>
  </default>

  <worldbody>
    <geom conaffinity="1" material="grid" name="floor" pos="248 0 0" size="250 .8 .2" type="plane" zaxis="-0.10813713821567325 0.0 0.9941359863411667" />
    <body childclass="walker" name="torso" pos="1.432647959747527 0.0 -25.51918308021873">
      <light mode="trackcom" name="light" pos="0 0 2" />
      <camera euler="60 0 0" mode="trackcom" name="side" pos="0 -2 .7" />
      <camera mode="trackcom" name="back" pos="-2 0 .5" xyaxes="0 -1 0 1 0 3" />
      <joint armature="0" axis="0 0 1" damping="0.174649564943173" limited="false" name="rootz" type="slide" />
      <joint armature="0" axis="1 0 0" damping="0.09415582233725936" limited="false" name="rootx" type="slide" />
      <joint armature="0" axis="0 1 0" damping="0.06794504691805378" limited="false" name="rooty" type="hinge" />
      <geom density="684.9763579308778" friction="1.1891018906323751 0.14723969977230852 0.07833627719324353" name="torso" size="0.07 0.3" />
      <body name="right_thigh" pos="0 -.05 -0.3">
        <joint damping="0.17097571434997255" name="right_hip" range="-20 100" />
        <geom density="1747.9967711909185" friction="0.8579791150157945 0.0675605949972161 0.20262164183896647" name="right_thigh" pos="0 0 -0.225" size="0.05 0.225" />
        <body name="right_leg" pos="0 0 -0.7">
          <joint damping="0.07769790900419715" name="right_knee" pos="0 0 0.25" range="-150 0" />
          <geom density="493.9872449279393" friction="0.72128978633803 0.193332842267079 0.09936424165809116" name="right_leg" size="0.04 0.25" />
          <body name="right_foot" pos="0.06 0 -0.25">
            <joint damping="0.11787252642725324" name="right_ankle" pos="-0.06 0 0" range="-45 45" />
            <geom density="942.0348595376192" friction="0.4681680917221452 0.0978344452452099 0.131754790332766" name="right_foot" size="0.05 0.19093605823267565" zaxis="1 0 0" />
          </body>
        </body>
      </body>
      <body name="left_thigh" pos="0 .05 -0.3">
        <joint damping="0.0512390815561726" name="left_hip" range="-20 100" />
        <geom density="1211.8734301154325" friction="0.8224349778364993 0.04673087837357309 0.09228763172981955" name="left_thigh" pos="0 0 -0.225" size="0.05 0.225" />
        <body name="left_leg" pos="0 0 -0.7">
          <joint damping="0.07498764313185816" name="left_knee" pos="0 0 0.25" range="-150 0" />
          <geom density="484.4011339078631" friction="0.7556623542620371 0.12010389082861372 0.1677794540869794" name="left_leg" size="0.04 0.25" />
          <body name="left_foot" pos="0.06 0 -0.25">
            <joint damping="0.0590224260586592" name="left_ankle" pos="-0.06 0 0" range="-45 45" />
            <geom density="761.8553037454154" friction="0.6986558051683894 0.04722893846607819 0.12246258882459123" name="left_foot" size="0.05 0.15960310228041674" zaxis="1 0 0" />
          </body>
        </body>
      </body>
    </body>
  </worldbody>

  <sensor>
    <subtreelinvel body="torso" name="torso_subtreelinvel" />
  </sensor>

  <actuator>
    <motor gear="100" joint="right_hip" name="right_hip" />
    <motor gear="50" joint="right_knee" name="right_knee" />
    <motor gear="20" joint="right_ankle" name="right_ankle" />
    <motor gear="100" joint="left_hip" name="left_hip" />
    <motor gear="50" joint="left_knee" name="left_knee" />
    <motor gear="20" joint="left_ankle" name="left_ankle" />
  </actuator>
</mujoco>